Workbook

Sheet Verification - Summary
B2: Details | C2: Stories Tested | D2: Test Cases | G2: Result | K2: INJI Web Testing | Q2: Browser Versions Used For Testing | S2: Tested with Components
C3: Total | D3: Total | E3: With Stories | F3: w/o Stories | G3: Pass | H3: Fail | I3: Not tested | K3: Story | L3: Test Results | Q3: Chrome: Version 142.0.7444.176 | S3: Injistackqa/ui-test:0.16.x
B4: INJI Web | C4: =IFERROR(__xludf.DUMMYFUNCTION("COUNTUNIQUE('Inji - Web - Test Cases'!A2:A2335)"),123.0) -> 123 | D4: =COUNTA('Inji - Web - Test Cases'!C2:C2300) -> 1125 | E4: =SUM(L4:L50) -> 601 | F4: =D4-E4 -> 524 | G4: =COUNTIF('Inji - Web - Test Cases'!J2:J3152, "Pass") -> 1036 | H4: =COUNTIF('Inji - Web - Test Cases'!J2:J3152, "Fail") -> 89 | I4: =D4-(G4+H4) -> 0 | K4: =IFERROR(__xludf.DUMMYFUNCTION("UNIQUE(FILTER('Inji - Web - Test Cases'!A2:A1887, 'Inji - Web - Test Cases'!A2:A1887<>""""))"),"INJIWEB-36") -> INJIWEB-36 | L4: =COUNTIFS('Inji - Web - Test Cases'!A1:A1700,K4,'Inji - Web - Test Cases'!C1:C1700,"<>"&"") -> 13 | M4: =COUNTIFS('Inji - Web - Test Cases'!A2:A1697,K4,'Inji - Web - Test Cases'!C2:C1697,"<>"&"",'Inji - Web - Test Cases'!J2:J1697,"Pass") -> 13 | N4: =COUNTIFS('Inji - Web - Test Cases'!A2:A1697,K4,'Inji - Web - Test Cases'!C2:C1697,"<>"&"",'Inji - Web - Test Cases'!J2:J1697,"Fail") -> 0 | O4: =COUNTIFS('Inji - Web - Test Cases'!A2:A1697,K4,'Inji - Web - Test Cases'!C2:C1697,"<>"&"",'Inji - Web - Test Cases'!J2:J1697,"NA") -> 0 | Q4: Firefox: Version 145.0.2 | S4: Injistackqa/inji-web:0.16.x
K5: =IFERROR(__xludf.DUMMYFUNCTION("""COMPUTED_VALUE"""),"INJIWEB-37") -> INJIWEB-37 | L5: =COUNTIFS('Inji - Web - Test Cases'!A2:A1701,K5,'Inji - Web - Test Cases'!C2:C1701,"<>"&"") -> 7 | M5: =COUNTIFS('Inji - Web - Test Cases'!A3:A1698,K5,'Inji - Web - Test Cases'!C3:C1698,"<>"&"",'Inji - Web - Test Cases'!J3:J1698,"Pass") -> 7 | N5: =COUNTIFS('Inji - Web - Test Cases'!A3:A1698,K5,'Inji - Web - Test Cases'!C3:C1698,"<>"&"",'Inji - Web - Test Cases'!J3:J1698,"Fail") -> 0 | O5: =COUNTIFS('Inji - Web - Test Cases'!A3:A1698,K5,'Inji - Web - Test Cases'!C3:C1698,"<>"&"",'Inji - Web - Test Cases'!J3:J1698,"NA") -> 0 | Q5: Edge: Version 142.0.3595.94 | S5: Injistackqa/apitest-mimoto:0.21.x
B6: Total | C6: =SUM(C3:C5) -> 123 | D6: =SUM(D3:D5) -> 1125 | E6: =SUM(E3:E5) -> 601 | F6: =SUM(F3:F5) -> 524 | G6: =SUM(G3:G5) -> 1036 | H6: =SUM(H3:H5) -> 89 | I6: =SUM(I3:I5) -> 0 | K6: =IFERROR(__xludf.DUMMYFUNCTION("""COMPUTED_VALUE"""),"INJIWEB-44") -> INJIWEB-44 | L6: =COUNTIFS('Inji - Web - Test Cases'!A3:A1702,K6,'Inji - Web - Test Cases'!C3:C1702,"<>"&"") -> 11 | M6: =COUNTIFS('Inji - Web - Test Cases'!A4:A1699,K6,'Inji - Web - Test Cases'!C4:C1699,"<>"&"",'Inji - Web - Test Cases'!J4:J1699,"Pass") -> 11 | N6: =COUNTIFS('Inji - Web - Test Cases'!A4:A1699,K6,'Inji - Web - Test Cases'!C4:C1699,"<>"&"",'Inji - Web - Test Cases'!J4:J1699,"Fail") -> 0 | O6: =COUNTIFS('Inji - Web - Test Cases'!A4:A1699,K6,'Inji - Web - Test Cases'!C4:C1699,"<>"&"",'Inji - Web - Test Cases'!J4:J1699,"NA") -> 0 | Q6: Safari : Version 16.6 | S6: Injistackqa/mimoto:0.21.x
K7: =IFERROR(__xludf.DUMMYFUNCTION("""COMPUTED_VALUE"""),"INJIWEB-45") -> INJIWEB-45 | L7: =COUNTIFS('Inji - Web - Test Cases'!A4:A1703,K7,'Inji - Web - Test Cases'!C4:C1703,"<>"&"") -> 19 | M7: =COUNTIFS('Inji - Web - Test Cases'!A4:A1700,K7,'Inji - Web - Test Cases'!C4:C1700,"<>"&"",'Inji - Web - Test Cases'!J4:J1700,"Pass") -> 19 | N7: =COUNTIFS('Inji - Web - Test Cases'!A4:A1700,K7,'Inji - Web - Test Cases'!C4:C1700,"<>"&"",'Inji - Web - Test Cases'!J4:J1700,"Fail") -> 0 | O7: =COUNTIFS('Inji - Web - Test Cases'!A4:A1700,K7,'Inji - Web - Test Cases'!C4:C1700,"<>"&"",'Inji - Web - Test Cases'!J4:J1700,"NA") -> 0
K8: =IFERROR(__xludf.DUMMYFUNCTION("""COMPUTED_VALUE"""),"INJIWEB-47") -> INJIWEB-47 | L8: =COUNTIFS('Inji - Web - Test Cases'!A4:A1704,K8,'Inji - Web - Test Cases'!C4:C1704,"<>"&"") -> 6 | M8: =COUNTIFS('Inji - Web - Test Cases'!A4:A1701,K8,'Inji - Web - Test Cases'!C4:C1701,"<>"&"",'Inji - Web - Test Cases'!J4:J1701,"Pass") -> 6 | N8: =COUNTIFS('Inji - Web - Test Cases'!A4:A1701,K8,'Inji - Web - Test Cases'!C4:C1701,"<>"&"",'Inji - Web - Test Cases'!J4:J1701,"Fail") -> 0 | O8: =COUNTIFS('Inji - Web - Test Cases'!A4:A1701,K8,'Inji - Web - Test Cases'!C4:C1701,"<>"&"",'Inji - Web - Test Cases'!J4:J1701,"NA") -> 0
K9: =IFERROR(__xludf.DUMMYFUNCTION("""COMPUTED_VALUE"""),"INJIWEB-48") -> INJIWEB-48 | L9: =COUNTIFS('Inji - Web - Test Cases'!A4:A1705,K9,'Inji - Web - Test Cases'!C4:C1705,"<>"&"") -> 4 | M9: =COUNTIFS('Inji - Web - Test Cases'!A4:A1702,K9,'Inji - Web - Test Cases'!C4:C1702,"<>"&"",'Inji - Web - Test Cases'!J4:J1702,"Pass") -> 4 | N9: =COUNTIFS('Inji - Web - Test Cases'!A4:A1702,K9,'Inji - Web - Test Cases'!C4:C1702,"<>"&"",'Inji - Web - Test Cases'!J4:J1702,"Fail") -> 0 | O9: =COUNTIFS('Inji - Web - Test Cases'!A4:A1702,K9,'Inji - Web - Test Cases'!C4:C1702,"<>"&"",'Inji - Web - Test Cases'!J4:J1702,"NA") -> 0
B10: ="Functional Testing - Stories Verified : " & C6 -> Functional Testing - Stories Verified : 123 | K10: =IFERROR(__xludf.DUMMYFUNCTION("""COMPUTED_VALUE"""),"INJIWEB-49") -> INJIWEB-49 | L10: =COUNTIFS('Inji - Web - Test Cases'!A4:A1706,K10,'Inji - Web - Test Cases'!C4:C1706,"<>"&"") -> 6 | M10: =COUNTIFS('Inji - Web - Test Cases'!A5:A1703,K10,'Inji - Web - Test Cases'!C5:C1703,"<>"&"",'Inji - Web - Test Cases'!J5:J1703,"Pass") -> 6 | N10: =COUNTIFS('Inji - Web - Test Cases'!A5:A1703,K10,'Inji - Web - Test Cases'!C5:C1703,"<>"&"",'Inji - Web - Test Cases'!J5:J1703,"Fail") -> 0 | O10: =COUNTIFS('Inji - Web - Test Cases'!A5:A1703,K10,'Inji - Web - Test Cases'!C5:C1703,"<>"&"",'Inji - Web - Test Cases'!J5:J1703,"NA") -> 0
B11: ="Test cases : " & D6 & " Passed : "& G6 & " Failed : " & H6 & " Skipped : " & I6 -> Test cases : 1125 Passed : 1036 Failed : 89 Skipped : 0 | K11: =IFERROR(__xludf.DUMMYFUNCTION("""COMPUTED_VALUE"""),"INJIWEB-50") -> INJIWEB-50 | L11: =COUNTIFS('Inji - Web - Test Cases'!A5:A1707,K11,'Inji - Web - Test Cases'!C5:C1707,"<>"&"") -> 8 | M11: =COUNTIFS('Inji - Web - Test Cases'!A6:A1704,K11,'Inji - Web - Test Cases'!C6:C1704,"<>"&"",'Inji - Web - Test Cases'!J6:J1704,"Pass") -> 8 | N11: =COUNTIFS('Inji - Web - Test Cases'!A6:A1704,K11,'Inji - Web - Test Cases'!C6:C1704,"<>"&"",'Inji - Web - Test Cases'!J6:J1704,"Fail") -> 0 | O11: =COUNTIFS('Inji - Web - Test Cases'!A6:A1704,K11,'Inji - Web - Test Cases'!C6:C1704,"<>"&"",'Inji - Web - Test Cases'!J6:J1704,"NA") -> 0
B12: ="Test Rate : " & INT((((G6+H6)/D6)*100)) & "% With Pass Rate : " & INT((G6/(G6+H6))*100) & "%" -> Test Rate : 100% With Pass Rate : 92% | K12: =IFERROR(__xludf.DUMMYFUNCTION("""COMPUTED_VALUE"""),"INJIWEB-51") -> INJIWEB-51 | L12: =COUNTIFS('Inji - Web - Test Cases'!A6:A1708,K12,'Inji - Web - Test Cases'!C6:C1708,"<>"&"") -> 5 | M12: =COUNTIFS('Inji - Web - Test Cases'!A7:A1705,K12,'Inji - Web - Test Cases'!C7:C1705,"<>"&"",'Inji - Web - Test Cases'!J7:J1705,"Pass") -> 5 | N12: =COUNTIFS('Inji - Web - Test Cases'!A7:A1705,K12,'Inji - Web - Test Cases'!C7:C1705,"<>"&"",'Inji - Web - Test Cases'!J7:J1705,"Fail") -> 0 | O12: =COUNTIFS('Inji - Web - Test Cases'!A7:A1705,K12,'Inji - Web - Test Cases'!C7:C1705,"<>"&"",'Inji - Web - Test Cases'!J7:J1705,"NA") -> 0
K13: =IFERROR(__xludf.DUMMYFUNCTION("""COMPUTED_VALUE"""),"INJIWEB-247") -> INJIWEB-247 | L13: =COUNTIFS('Inji - Web - Test Cases'!A7:A1709,K13,'Inji - Web - Test Cases'!C7:C1709,"<>"&"") -> 15 | M13: =COUNTIFS('Inji - Web - Test Cases'!A8:A1706,K13,'Inji - Web - Test Cases'!C8:C1706,"<>"&"",'Inji - Web - Test Cases'!J8:J1706,"Pass") -> 15 | N13: =COUNTIFS('Inji - Web - Test Cases'!A8:A1706,K13,'Inji - Web - Test Cases'!C8:C1706,"<>"&"",'Inji - Web - Test Cases'!J8:J1706,"Fail") -> 0 | O13: =COUNTIFS('Inji - Web - Test Cases'!A8:A1706,K13,'Inji - Web - Test Cases'!C8:C1706,"<>"&"",'Inji - Web - Test Cases'!J8:J1706,"NA") -> 0
K14: =IFERROR(__xludf.DUMMYFUNCTION("""COMPUTED_VALUE"""),"INJIWEB-257") -> INJIWEB-257 | L14: =COUNTIFS('Inji - Web - Test Cases'!A8:A1710,K14,'Inji - Web - Test Cases'!C8:C1710,"<>"&"") -> 3 | M14: =COUNTIFS('Inji - Web - Test Cases'!A9:A1707,K14,'Inji - Web - Test Cases'!C9:C1707,"<>"&"",'Inji - Web - Test Cases'!J9:J1707,"Pass") -> 3 | N14: =COUNTIFS('Inji - Web - Test Cases'!A9:A1707,K14,'Inji - Web - Test Cases'!C9:C1707,"<>"&"",'Inji - Web - Test Cases'!J9:J1707,"Fail") -> 0 | O14: =COUNTIFS('Inji - Web - Test Cases'!A9:A1707,K14,'Inji - Web - Test Cases'!C9:C1707,"<>"&"",'Inji - Web - Test Cases'!J9:J1707,"NA") -> 0
K15: =IFERROR(__xludf.DUMMYFUNCTION("""COMPUTED_VALUE"""),"INJIWEB-278") -> INJIWEB-278 | L15: =COUNTIFS('Inji - Web - Test Cases'!A9:A1711,K15,'Inji - Web - Test Cases'!C9:C1711,"<>"&"") -> 7 | M15: =COUNTIFS('Inji - Web - Test Cases'!A10:A1708,K15,'Inji - Web - Test Cases'!C10:C1708,"<>"&"",'Inji - Web - Test Cases'!J10:J1708,"Pass") -> 7 | N15: =COUNTIFS('Inji - Web - Test Cases'!A10:A1708,K15,'Inji - Web - Test Cases'!C10:C1708,"<>"&"",'Inji - Web - Test Cases'!J10:J1708,"Fail") -> 0 | O15: =COUNTIFS('Inji - Web - Test Cases'!A10:A1708,K15,'Inji - Web - Test Cases'!C10:C1708,"<>"&"",'Inji - Web - Test Cases'!J10:J1708,"NA") -> 0
K16: =IFERROR(__xludf.DUMMYFUNCTION("""COMPUTED_VALUE"""),"INJIWEB-232") -> INJIWEB-232 | L16: =COUNTIFS('Inji - Web - Test Cases'!A10:A1712,K16,'Inji - Web - Test Cases'!C10:C1712,"<>"&"") -> 9 | M16: =COUNTIFS('Inji - Web - Test Cases'!A11:A1709,K16,'Inji - Web - Test Cases'!C11:C1709,"<>"&"",'Inji - Web - Test Cases'!J11:J1709,"Pass") -> 9 | N16: =COUNTIFS('Inji - Web - Test Cases'!A11:A1709,K16,'Inji - Web - Test Cases'!C11:C1709,"<>"&"",'Inji - Web - Test Cases'!J11:J1709,"Fail") -> 0 | O16: =COUNTIFS('Inji - Web - Test Cases'!A11:A1709,K16,'Inji - Web - Test Cases'!C11:C1709,"<>"&"",'Inji - Web - Test Cases'!J11:J1709,"NA") -> 0
K17: =IFERROR(__xludf.DUMMYFUNCTION("""COMPUTED_VALUE"""),"INJIWEB-479") -> INJIWEB-479 | L17: =COUNTIFS('Inji - Web - Test Cases'!A11:A1713,K17,'Inji - Web - Test Cases'!C11:C1713,"<>"&"") -> 6 | M17: =COUNTIFS('Inji - Web - Test Cases'!A12:A1710,K17,'Inji - Web - Test Cases'!C12:C1710,"<>"&"",'Inji - Web - Test Cases'!J12:J1710,"Pass") -> 6 | N17: =COUNTIFS('Inji - Web - Test Cases'!A12:A1710,K17,'Inji - Web - Test Cases'!C12:C1710,"<>"&"",'Inji - Web - Test Cases'!J12:J1710,"Fail") -> 0 | O17: =COUNTIFS('Inji - Web - Test Cases'!A12:A1710,K17,'Inji - Web - Test Cases'!C12:C1710,"<>"&"",'Inji - Web - Test Cases'!J12:J1710,"NA") -> 0
K18: =IFERROR(__xludf.DUMMYFUNCTION("""COMPUTED_VALUE"""),"INJIWEB-192") -> INJIWEB-192 | L18: =COUNTIFS('Inji - Web - Test Cases'!A12:A1714,K18,'Inji - Web - Test Cases'!C12:C1714,"<>"&"") -> 18 | M18: =COUNTIFS('Inji - Web - Test Cases'!A13:A1711,K18,'Inji - Web - Test Cases'!C13:C1711,"<>"&"",'Inji - Web - Test Cases'!J13:J1711,"Pass") -> 18 | N18: =COUNTIFS('Inji - Web - Test Cases'!A13:A1711,K18,'Inji - Web - Test Cases'!C13:C1711,"<>"&"",'Inji - Web - Test Cases'!J13:J1711,"Fail") -> 0 | O18: =COUNTIFS('Inji - Web - Test Cases'!A13:A1711,K18,'Inji - Web - Test Cases'!C13:C1711,"<>"&"",'Inji - Web - Test Cases'!J13:J1711,"NA") -> 0
K19: =IFERROR(__xludf.DUMMYFUNCTION("""COMPUTED_VALUE"""),"INJIWEB-597") -> INJIWEB-597 | L19: =COUNTIFS('Inji - Web - Test Cases'!A13:A1715,K19,'Inji - Web - Test Cases'!C13:C1715,"<>"&"") -> 8 | M19: =COUNTIFS('Inji - Web - Test Cases'!A14:A1712,K19,'Inji - Web - Test Cases'!C14:C1712,"<>"&"",'Inji - Web - Test Cases'!J14:J1712,"Pass") -> 8 | N19: =COUNTIFS('Inji - Web - Test Cases'!A14:A1712,K19,'Inji - Web - Test Cases'!C14:C1712,"<>"&"",'Inji - Web - Test Cases'!J14:J1712,"Fail") -> 0 | O19: =COUNTIFS('Inji - Web - Test Cases'!A14:A1712,K19,'Inji - Web - Test Cases'!C14:C1712,"<>"&"",'Inji - Web - Test Cases'!J14:J1712,"NA") -> 0
K20: =IFERROR(__xludf.DUMMYFUNCTION("""COMPUTED_VALUE"""),"INJIWEB-639") -> INJIWEB-639 | L20: =COUNTIFS('Inji - Web - Test Cases'!A14:A1716,K20,'Inji - Web - Test Cases'!C14:C1716,"<>"&"") -> 17 | M20: =COUNTIFS('Inji - Web - Test Cases'!A15:A1713,K20,'Inji - Web - Test Cases'!C15:C1713,"<>"&"",'Inji - Web - Test Cases'!J15:J1713,"Pass") -> 17 | N20: =COUNTIFS('Inji - Web - Test Cases'!A15:A1713,K20,'Inji - Web - Test Cases'!C15:C1713,"<>"&"",'Inji - Web - Test Cases'!J15:J1713,"Fail") -> 0 | O20: =COUNTIFS('Inji - Web - Test Cases'!A15:A1713,K20,'Inji - Web - Test Cases'!C15:C1713,"<>"&"",'Inji - Web - Test Cases'!J15:J1713,"NA") -> 0
K21: =IFERROR(__xludf.DUMMYFUNCTION("""COMPUTED_VALUE"""),"INJIWEB-649") -> INJIWEB-649 | L21: =COUNTIFS('Inji - Web - Test Cases'!A15:A1717,K21,'Inji - Web - Test Cases'!C15:C1717,"<>"&"") -> 20 | M21: =COUNTIFS('Inji - Web - Test Cases'!A16:A1714,K21,'Inji - Web - Test Cases'!C16:C1714,"<>"&"",'Inji - Web - Test Cases'!J16:J1714,"Pass") -> 20 | N21: =COUNTIFS('Inji - Web - Test Cases'!A16:A1714,K21,'Inji - Web - Test Cases'!C16:C1714,"<>"&"",'Inji - Web - Test Cases'!J16:J1714,"Fail") -> 0 | O21: =COUNTIFS('Inji - Web - Test Cases'!A16:A1714,K21,'Inji - Web - Test Cases'!C16:C1714,"<>"&"",'Inji - Web - Test Cases'!J16:J1714,"NA") -> 0
K22: =IFERROR(__xludf.DUMMYFUNCTION("""COMPUTED_VALUE"""),"INJIWEB-665") -> INJIWEB-665 | L22: =COUNTIFS('Inji - Web - Test Cases'!A16:A1718,K22,'Inji - Web - Test Cases'!C16:C1718,"<>"&"") -> 10 | M22: =COUNTIFS('Inji - Web - Test Cases'!A17:A1715,K22,'Inji - Web - Test Cases'!C17:C1715,"<>"&"",'Inji - Web - Test Cases'!J17:J1715,"Pass") -> 10 | N22: =COUNTIFS('Inji - Web - Test Cases'!A17:A1715,K22,'Inji - Web - Test Cases'!C17:C1715,"<>"&"",'Inji - Web - Test Cases'!J17:J1715,"Fail") -> 0 | O22: =COUNTIFS('Inji - Web - Test Cases'!A17:A1715,K22,'Inji - Web - Test Cases'!C17:C1715,"<>"&"",'Inji - Web - Test Cases'!J17:J1715,"NA") -> 0
K23: =IFERROR(__xludf.DUMMYFUNCTION("""COMPUTED_VALUE"""),"INJIWEB-679") -> INJIWEB-679 | L23: =COUNTIFS('Inji - Web - Test Cases'!A17:A1719,K23,'Inji - Web - Test Cases'!C17:C1719,"<>"&"") -> 22 | M23: =COUNTIFS('Inji - Web - Test Cases'!A18:A1716,K23,'Inji - Web - Test Cases'!C18:C1716,"<>"&"",'Inji - Web - Test Cases'!J18:J1716,"Pass") -> 22 | N23: =COUNTIFS('Inji - Web - Test Cases'!A18:A1716,K23,'Inji - Web - Test Cases'!C18:C1716,"<>"&"",'Inji - Web - Test Cases'!J18:J1716,"Fail") -> 0 | O23: =COUNTIFS('Inji - Web - Test Cases'!A18:A1716,K23,'Inji - Web - Test Cases'!C18:C1716,"<>"&"",'Inji - Web - Test Cases'!J18:J1716,"NA") -> 0
K24: =IFERROR(__xludf.DUMMYFUNCTION("""COMPUTED_VALUE"""),"INJIWEB-880") -> INJIWEB-880 | L24: =COUNTIFS('Inji - Web - Test Cases'!A18:A1720,K24,'Inji - Web - Test Cases'!C18:C1720,"<>"&"") -> 4 | M24: =COUNTIFS('Inji - Web - Test Cases'!A19:A1717,K24,'Inji - Web - Test Cases'!C19:C1717,"<>"&"",'Inji - Web - Test Cases'!J19:J1717,"Pass") -> 4 | N24: =COUNTIFS('Inji - Web - Test Cases'!A19:A1717,K24,'Inji - Web - Test Cases'!C19:C1717,"<>"&"",'Inji - Web - Test Cases'!J19:J1717,"Fail") -> 0 | O24: =COUNTIFS('Inji - Web - Test Cases'!A19:A1717,K24,'Inji - Web - Test Cases'!C19:C1717,"<>"&"",'Inji - Web - Test Cases'!J19:J1717,"NA") -> 0
K25: =IFERROR(__xludf.DUMMYFUNCTION("""COMPUTED_VALUE"""),"INJIWEB-268") -> INJIWEB-268 | L25: =COUNTIFS('Inji - Web - Test Cases'!A19:A1721,K25,'Inji - Web - Test Cases'!C19:C1721,"<>"&"") -> 14 | M25: =COUNTIFS('Inji - Web - Test Cases'!A20:A1718,K25,'Inji - Web - Test Cases'!C20:C1718,"<>"&"",'Inji - Web - Test Cases'!J20:J1718,"Pass") -> 14 | N25: =COUNTIFS('Inji - Web - Test Cases'!A20:A1718,K25,'Inji - Web - Test Cases'!C20:C1718,"<>"&"",'Inji - Web - Test Cases'!J20:J1718,"Fail") -> 0 | O25: =COUNTIFS('Inji - Web - Test Cases'!A20:A1718,K25,'Inji - Web - Test Cases'!C20:C1718,"<>"&"",'Inji - Web - Test Cases'!J20:J1718,"NA") -> 0
K26: =IFERROR(__xludf.DUMMYFUNCTION("""COMPUTED_VALUE"""),"INJIWEB-424") -> INJIWEB-424 | L26: =COUNTIFS('Inji - Web - Test Cases'!A20:A1722,K26,'Inji - Web - Test Cases'!C20:C1722,"<>"&"") -> 13 | M26: =COUNTIFS('Inji - Web - Test Cases'!A21:A1719,K26,'Inji - Web - Test Cases'!C21:C1719,"<>"&"",'Inji - Web - Test Cases'!J21:J1719,"Pass") -> 13 | N26: =COUNTIFS('Inji - Web - Test Cases'!A21:A1719,K26,'Inji - Web - Test Cases'!C21:C1719,"<>"&"",'Inji - Web - Test Cases'!J21:J1719,"Fail") -> 0 | O26: =COUNTIFS('Inji - Web - Test Cases'!A21:A1719,K26,'Inji - Web - Test Cases'!C21:C1719,"<>"&"",'Inji - Web - Test Cases'!J21:J1719,"NA") -> 0
K27: =IFERROR(__xludf.DUMMYFUNCTION("""COMPUTED_VALUE"""),"INJIWEB-511") -> INJIWEB-511 | L27: =COUNTIFS('Inji - Web - Test Cases'!A21:A1723,K27,'Inji - Web - Test Cases'!C21:C1723,"<>"&"") -> 54 | M27: =COUNTIFS('Inji - Web - Test Cases'!A22:A1720,K27,'Inji - Web - Test Cases'!C22:C1720,"<>"&"",'Inji - Web - Test Cases'!J22:J1720,"Pass") -> 54 | N27: =COUNTIFS('Inji - Web - Test Cases'!A22:A1720,K27,'Inji - Web - Test Cases'!C22:C1720,"<>"&"",'Inji - Web - Test Cases'!J22:J1720,"Fail") -> 0 | O27: =COUNTIFS('Inji - Web - Test Cases'!A22:A1720,K27,'Inji - Web - Test Cases'!C22:C1720,"<>"&"",'Inji - Web - Test Cases'!J22:J1720,"NA") -> 0
K28: =IFERROR(__xludf.DUMMYFUNCTION("""COMPUTED_VALUE"""),"INJIWEB-758") -> INJIWEB-758 | L28: =COUNTIFS('Inji - Web - Test Cases'!A22:A1724,K28,'Inji - Web - Test Cases'!C22:C1724,"<>"&"") -> 4 | M28: =COUNTIFS('Inji - Web - Test Cases'!A23:A1721,K28,'Inji - Web - Test Cases'!C23:C1721,"<>"&"",'Inji - Web - Test Cases'!J23:J1721,"Pass") -> 4 | N28: =COUNTIFS('Inji - Web - Test Cases'!A23:A1721,K28,'Inji - Web - Test Cases'!C23:C1721,"<>"&"",'Inji - Web - Test Cases'!J23:J1721,"Fail") -> 0 | O28: =COUNTIFS('Inji - Web - Test Cases'!A23:A1721,K28,'Inji - Web - Test Cases'!C23:C1721,"<>"&"",'Inji - Web - Test Cases'!J23:J1721,"NA") -> 0
K29: =IFERROR(__xludf.DUMMYFUNCTION("""COMPUTED_VALUE"""),"INJIWEB-700") -> INJIWEB-700 | L29: =COUNTIFS('Inji - Web - Test Cases'!A23:A1725,K29,'Inji - Web - Test Cases'!C23:C1725,"<>"&"") -> 26 | M29: =COUNTIFS('Inji - Web - Test Cases'!A24:A1722,K29,'Inji - Web - Test Cases'!C24:C1722,"<>"&"",'Inji - Web - Test Cases'!J24:J1722,"Pass") -> 26 | N29: =COUNTIFS('Inji - Web - Test Cases'!A24:A1722,K29,'Inji - Web - Test Cases'!C24:C1722,"<>"&"",'Inji - Web - Test Cases'!J24:J1722,"Fail") -> 0 | O29: =COUNTIFS('Inji - Web - Test Cases'!A24:A1722,K29,'Inji - Web - Test Cases'!C24:C1722,"<>"&"",'Inji - Web - Test Cases'!J24:J1722,"NA") -> 0
K30: =IFERROR(__xludf.DUMMYFUNCTION("""COMPUTED_VALUE"""),"INJIWEB-980") -> INJIWEB-980 | L30: =COUNTIFS('Inji - Web - Test Cases'!A24:A1726,K30,'Inji - Web - Test Cases'!C24:C1726,"<>"&"") -> 27 | M30: =COUNTIFS('Inji - Web - Test Cases'!A25:A1723,K30,'Inji - Web - Test Cases'!C25:C1723,"<>"&"",'Inji - Web - Test Cases'!J25:J1723,"Pass") -> 27 | N30: =COUNTIFS('Inji - Web - Test Cases'!A25:A1723,K30,'Inji - Web - Test Cases'!C25:C1723,"<>"&"",'Inji - Web - Test Cases'!J25:J1723,"Fail") -> 0 | O30: =COUNTIFS('Inji - Web - Test Cases'!A25:A1723,K30,'Inji - Web - Test Cases'!C25:C1723,"<>"&"",'Inji - Web - Test Cases'!J25:J1723,"NA") -> 0
K31: =IFERROR(__xludf.DUMMYFUNCTION("""COMPUTED_VALUE"""),"INJIWEB-910") -> INJIWEB-910 | L31: =COUNTIFS('Inji - Web - Test Cases'!A25:A1727,K31,'Inji - Web - Test Cases'!C25:C1727,"<>"&"") -> 19 | M31: =COUNTIFS('Inji - Web - Test Cases'!A26:A1724,K31,'Inji - Web - Test Cases'!C26:C1724,"<>"&"",'Inji - Web - Test Cases'!J26:J1724,"Pass") -> 19 | N31: =COUNTIFS('Inji - Web - Test Cases'!A26:A1724,K31,'Inji - Web - Test Cases'!C26:C1724,"<>"&"",'Inji - Web - Test Cases'!J26:J1724,"Fail") -> 0 | O31: =COUNTIFS('Inji - Web - Test Cases'!A26:A1724,K31,'Inji - Web - Test Cases'!C26:C1724,"<>"&"",'Inji - Web - Test Cases'!J26:J1724,"NA") -> 0
K32: =IFERROR(__xludf.DUMMYFUNCTION("""COMPUTED_VALUE"""),"INJIWEB-920") -> INJIWEB-920 | L32: =COUNTIFS('Inji - Web - Test Cases'!A26:A1728,K32,'Inji - Web - Test Cases'!C26:C1728,"<>"&"") -> 11 | M32: =COUNTIFS('Inji - Web - Test Cases'!A26:A1725,K32,'Inji - Web - Test Cases'!C26:C1725,"<>"&"",'Inji - Web - Test Cases'!J26:J1725,"Pass") -> 11 | N32: =COUNTIFS('Inji - Web - Test Cases'!A26:A1725,K32,'Inji - Web - Test Cases'!C26:C1725,"<>"&"",'Inji - Web - Test Cases'!J26:J1725,"Fail") -> 0 | O32: =COUNTIFS('Inji - Web - Test Cases'!A26:A1725,K32,'Inji - Web - Test Cases'!C26:C1725,"<>"&"",'Inji - Web - Test Cases'!J26:J1725,"NA") -> 0
K33: =IFERROR(__xludf.DUMMYFUNCTION("""COMPUTED_VALUE"""),"INJIWEB-1036") -> INJIWEB-1036 | L33: =COUNTIFS('Inji - Web - Test Cases'!A26:A1729,K33,'Inji - Web - Test Cases'!C26:C1729,"<>"&"") -> 12 | M33: =COUNTIFS('Inji - Web - Test Cases'!A27:A1726,K33,'Inji - Web - Test Cases'!C27:C1726,"<>"&"",'Inji - Web - Test Cases'!J27:J1726,"Pass") -> 12 | N33: =COUNTIFS('Inji - Web - Test Cases'!A27:A1726,K33,'Inji - Web - Test Cases'!C27:C1726,"<>"&"",'Inji - Web - Test Cases'!J27:J1726,"Fail") -> 0 | O33: =COUNTIFS('Inji - Web - Test Cases'!A27:A1726,K33,'Inji - Web - Test Cases'!C27:C1726,"<>"&"",'Inji - Web - Test Cases'!J27:J1726,"NA") -> 0
K34: =IFERROR(__xludf.DUMMYFUNCTION("""COMPUTED_VALUE"""),"INJIWEB-1203") -> INJIWEB-1203 | L34: =COUNTIFS('Inji - Web - Test Cases'!A27:A1730,K34,'Inji - Web - Test Cases'!C27:C1730,"<>"&"") -> 12 | M34: =COUNTIFS('Inji - Web - Test Cases'!A27:A1727,K34,'Inji - Web - Test Cases'!C27:C1727,"<>"&"",'Inji - Web - Test Cases'!J27:J1727,"Pass") -> 12 | N34: =COUNTIFS('Inji - Web - Test Cases'!A27:A1727,K34,'Inji - Web - Test Cases'!C27:C1727,"<>"&"",'Inji - Web - Test Cases'!J27:J1727,"Fail") -> 0 | O34: =COUNTIFS('Inji - Web - Test Cases'!A27:A1727,K34,'Inji - Web - Test Cases'!C27:C1727,"<>"&"",'Inji - Web - Test Cases'!J27:J1727,"NA") -> 0
K35: =IFERROR(__xludf.DUMMYFUNCTION("""COMPUTED_VALUE"""),"INJIWEB-1167") -> INJIWEB-1167 | L35: =COUNTIFS('Inji - Web - Test Cases'!A27:A1731,K35,'Inji - Web - Test Cases'!C27:C1731,"<>"&"") -> 10 | M35: =COUNTIFS('Inji - Web - Test Cases'!A28:A1728,K35,'Inji - Web - Test Cases'!C28:C1728,"<>"&"",'Inji - Web - Test Cases'!J28:J1728,"Pass") -> 9 | N35: =COUNTIFS('Inji - Web - Test Cases'!A28:A1728,K35,'Inji - Web - Test Cases'!C28:C1728,"<>"&"",'Inji - Web - Test Cases'!J28:J1728,"Fail") -> 1 | O35: =COUNTIFS('Inji - Web - Test Cases'!A28:A1728,K35,'Inji - Web - Test Cases'!C28:C1728,"<>"&"",'Inji - Web - Test Cases'!J28:J1728,"NA") -> 0
K36: =IFERROR(__xludf.DUMMYFUNCTION("""COMPUTED_VALUE"""),"INJIWEB-1246") -> INJIWEB-1246 | L36: =COUNTIFS('Inji - Web - Test Cases'!A28:A1732,K36,'Inji - Web - Test Cases'!C28:C1732,"<>"&"") -> 21 | M36: =COUNTIFS('Inji - Web - Test Cases'!A28:A1729,K36,'Inji - Web - Test Cases'!C28:C1729,"<>"&"",'Inji - Web - Test Cases'!J28:J1729,"Pass") -> 21 | N36: =COUNTIFS('Inji - Web - Test Cases'!A28:A1729,K36,'Inji - Web - Test Cases'!C28:C1729,"<>"&"",'Inji - Web - Test Cases'!J28:J1729,"Fail") -> 0 | O36: =COUNTIFS('Inji - Web - Test Cases'!A28:A1729,K36,'Inji - Web - Test Cases'!C28:C1729,"<>"&"",'Inji - Web - Test Cases'!J28:J1729,"NA") -> 0
K37: =IFERROR(__xludf.DUMMYFUNCTION("""COMPUTED_VALUE"""),"INJIWEB-1117") -> INJIWEB-1117 | L37: =COUNTIFS('Inji - Web - Test Cases'!A28:A1733,K37,'Inji - Web - Test Cases'!C28:C1733,"<>"&"") -> 29 | M37: =COUNTIFS('Inji - Web - Test Cases'!A29:A1730,K37,'Inji - Web - Test Cases'!C29:C1730,"<>"&"",'Inji - Web - Test Cases'!J29:J1730,"Pass") -> 28 | N37: =COUNTIFS('Inji - Web - Test Cases'!A29:A1730,K37,'Inji - Web - Test Cases'!C29:C1730,"<>"&"",'Inji - Web - Test Cases'!J29:J1730,"Fail") -> 1 | O37: =COUNTIFS('Inji - Web - Test Cases'!A29:A1730,K37,'Inji - Web - Test Cases'!C29:C1730,"<>"&"",'Inji - Web - Test Cases'!J29:J1730,"NA") -> 0
K38: =IFERROR(__xludf.DUMMYFUNCTION("""COMPUTED_VALUE"""),"INJIWEB-1513") -> INJIWEB-1513 | L38: =COUNTIFS('Inji - Web - Test Cases'!A29:A1734,K38,'Inji - Web - Test Cases'!C29:C1734,"<>"&"") -> 12 | M38: =COUNTIFS('Inji - Web - Test Cases'!A30:A1731,K38,'Inji - Web - Test Cases'!C30:C1731,"<>"&"",'Inji - Web - Test Cases'!J30:J1731,"Pass") -> 12 | N38: =COUNTIFS('Inji - Web - Test Cases'!A30:A1731,K38,'Inji - Web - Test Cases'!C30:C1731,"<>"&"",'Inji - Web - Test Cases'!J30:J1731,"Fail") -> 0 | O38: =COUNTIFS('Inji - Web - Test Cases'!A30:A1731,K38,'Inji - Web - Test Cases'!C30:C1731,"<>"&"",'Inji - Web - Test Cases'!J30:J1731,"NA") -> 0
K39: =IFERROR(__xludf.DUMMYFUNCTION("""COMPUTED_VALUE"""),"INJIWEB-1522") -> INJIWEB-1522 | L39: =COUNTIFS('Inji - Web - Test Cases'!A30:A1735,K39,'Inji - Web - Test Cases'!C30:C1735,"<>"&"") -> 22 | M39: =COUNTIFS('Inji - Web - Test Cases'!A31:A1732,K39,'Inji - Web - Test Cases'!C31:C1732,"<>"&"",'Inji - Web - Test Cases'!J31:J1732,"Pass") -> 21 | N39: =COUNTIFS('Inji - Web - Test Cases'!A31:A1732,K39,'Inji - Web - Test Cases'!C31:C1732,"<>"&"",'Inji - Web - Test Cases'!J31:J1732,"Fail") -> 1 | O39: =COUNTIFS('Inji - Web - Test Cases'!A31:A1732,K39,'Inji - Web - Test Cases'!C31:C1732,"<>"&"",'Inji - Web - Test Cases'!J31:J1732,"NA") -> 0
K40: =IFERROR(__xludf.DUMMYFUNCTION("""COMPUTED_VALUE"""),"INJIWEB-1533") -> INJIWEB-1533 | L40: =COUNTIFS('Inji - Web - Test Cases'!A31:A1736,K40,'Inji - Web - Test Cases'!C31:C1736,"<>"&"") -> 14 | M40: =COUNTIFS('Inji - Web - Test Cases'!A32:A1733,K40,'Inji - Web - Test Cases'!C32:C1733,"<>"&"",'Inji - Web - Test Cases'!J32:J1733,"Pass") -> 11 | N40: =COUNTIFS('Inji - Web - Test Cases'!A32:A1733,K40,'Inji - Web - Test Cases'!C32:C1733,"<>"&"",'Inji - Web - Test Cases'!J32:J1733,"Fail") -> 3 | O40: =COUNTIFS('Inji - Web - Test Cases'!A32:A1733,K40,'Inji - Web - Test Cases'!C32:C1733,"<>"&"",'Inji - Web - Test Cases'!J32:J1733,"NA") -> 0
K41: =IFERROR(__xludf.DUMMYFUNCTION("""COMPUTED_VALUE"""),"INJIWEB-1520") -> INJIWEB-1520 | L41: =COUNTIFS('Inji - Web - Test Cases'!A32:A1737,K41,'Inji - Web - Test Cases'!C32:C1737,"<>"&"") -> 13 | M41: =COUNTIFS('Inji - Web - Test Cases'!A33:A1734,K41,'Inji - Web - Test Cases'!C33:C1734,"<>"&"",'Inji - Web - Test Cases'!J33:J1734,"Pass") -> 13 | N41: =COUNTIFS('Inji - Web - Test Cases'!A33:A1734,K41,'Inji - Web - Test Cases'!C33:C1734,"<>"&"",'Inji - Web - Test Cases'!J33:J1734,"Fail") -> 0 | O41: =COUNTIFS('Inji - Web - Test Cases'!A33:A1734,K41,'Inji - Web - Test Cases'!C33:C1734,"<>"&"",'Inji - Web - Test Cases'!J33:J1734,"NA") -> 0
...

Sheet API_UI-Automation
B2: INJI WEB UI Automation
B3: Details | C3: Total | G3: Pass | H3: Fail | I3: NA
B4: INJI Web UI | C4: 28 | G4: 28 | H4: 0 | I4: 0
B6: Total | C6: =SUM(C4:F5) -> 28 | G6: =SUM(G3:G5) -> 28 | H6: =SUM(H3:H5) -> 0 | I6: =SUM(I3:I5) -> 0
B8: ="Functional Testing - Stories Verified : " & C6 -> Functional Testing - Stories Verified : 28
B9: ="Test cases : " & C6 & " Passed : "& G6 & " Failed : " & H6 & " Skipped : " & I6 -> Test cases : 28 Passed : 28 Failed : 0 Skipped : 0
B10: ="Test Rate : " & INT((((G6+H6)/C6)*100)) & "% With Pass Rate : " & INT((G6/(G6+H6))*100) & "%" -> Test Rate : 100% With Pass Rate : 100%
B12: INJI WEB API - Mimoto
B13: Details | C13: Total | G13: Pass | H13: Fail | I13: NA | J13: KI
B14: INJI Web API | C14: 349 | G14: 312 | H14: 0 | I14: 33 | J14: 4
B16: Total | C16: =SUM(C14:F15) -> 349 | G16: =SUM(G13:G15) -> 312 | H16: =SUM(H13:H15) -> 0 | I16: =SUM(I13:I15) -> 33 | J16: =SUM(J13:J15) -> 4
B18: ="Functional Testing - Stories Verified : " & C16 -> Functional Testing - Stories Verified : 349
B19: ="Test cases : " & C16 & " Passed : "& G16 & " Failed : " & H16 & " Skipped : " & I16 &" Known Issues : "& J16 -> Test cases : 349 Passed : 312 Failed : 0 Skipped : 33 Known Issues : 4
B20: ="Test Rate : " & INT((((G16+H16)/C16)*100)) & "% With Pass Rate : " & INT((G16/(G16+H16))*100) & "%" -> Test Rate : 89% With Pass Rate : 100%

Sheet Feature Health
A1: Feature list | B1: INJI Web | C1: Total | D1: Pass | E1: Fail
A2: Inji Home page and User wallet | B2: Pass | C2: 177 | D2: 160 | E2: 17
A3: Credential type | B3: Pass | C3: 54 | D3: 48 | E3: 6
A4: Authenticate user credentials | B4: Pass | C4: 28 | D4: 28 | E4: 0
A5: PDF Generation download and View | B5: Pass | C5: 54 | D5: 52 | E5: 2
A6: Issuers and credentials support | B6: Pass | C6: 41 | D6: 40 | E6: 1
A7: Multi languages support | B7: Pass | C7: 29 | D7: 27 | E7: 2
A8: Responsive view of the web | B8: Pass | C8: 19 | D8: 19 | E8: 0
A9: Access violations | B9: Pass | C9: 3 | D9: 3 | E9: 0
A10: datashare | B10: Pass | C10: 86 | D10: 85 | E10: 1
A11: OpenID4VP Implementation | B11: Pass | C11: 66 | D11: 62 | E11: 4
A12: QR code | B12: Pass | C12: 41 | D12: 39 | E12: 2
A13: Login flow and Setup passcode | B13: Pass | C13: 125 | D13: 98 | E13: 27
... A21: Claim 169 | B21: Pass | C21: 20 | D21: 20 | E21: 0

Sheet Inji - Web - Test Cases
A1: Story id | B1: Story Title | C1: TestCase_No | D1: Functional | E1: Feature | F1: Prerequisite | G1: Scenario | H1: Steps | I1: Expected Result | J1: Pass/Fail | K1: Automated | L1: Automated In | M1: Automation Comments | N1: Bug ID | O1: Remarks | P1: Environments
A2: INJIWEB-36 | B2: [UI] Inji Web - Launch Inji Web Home Page | C2: INJIWEB-36_TC_01 | E2: Inji Home page and User wallet | F2: 1. The Inji Web Home Page should be available in the appropriate URL in the environment specified. 2. Inji Web should have configured Header (logo) similar to Inji mobile, Footer (copyright information) 3. Non-functional links of About MOSIP, Playstore and Appstore icons on the header. | G2: Open Inji web in diff browsers | H2: 1. Open browser 2. Browse Inji Web Home Page in all the supported browsers Ex: Chrome, Firefox, Edge,Safari etc. | I2: Inji web page should be opened in all the supported browsers without any errors | J2: PASS | K2: Yes | L2: UI | M2: edge browser is not supporting now need to do more resarch on it
A3: INJIWEB-36 | C3: INJIWEB-36_TC_02 | E3: Inji Home page and User wallet | G3: Verify Header(Logo), footer(Copy right) info | H3: 1. Open Inji Web Home Page 2. Verify Header and footer information on home page in all the supported browsers Ex: Chrome, Firefox, Edge,Safari etc. | I3: Proper header and footer inforamtion similar to Inji mobile app | J3: PASS | K3: Yes | L3: UI
A4: INJIWEB-36 | C4: INJIWEB-36_TC_04 | E4: Inji Home page and User wallet | G4: Open inji home page in multiple winodws | H4: 1. Open inji web page 2. Browse home page 3. Open another browser window 4. Browse inji home page | I4: Inji home page should be opened in all the windows with all the configured content | J4: PASS | K4: Yes | L4: UI
A5: INJIWEB-36 | C5: INJIWEB-36_TC_05 | E5: Inji Home page and User wallet | G5: Open inji home page in multiple tabs | H5: 1. Open browser 2. Browse inji home page 3. Open another browser tab 4. Browse inji home page | I5: Inji home page should be opened in all the tabs with all the configured content | J5: PASS | K5: Yes | L5: UI
A6: INJIWEB-36 | C6: INJIWEB-36_TC_06 | E6: Inji Home page and User wallet | G6: Open inji home page in multiple winodws of diff browsers | H6: 1. Open browser 2. Browse inji home page 3. Open another browser window in diff browser 4. Browse inji home page | I6: Inji home page should be opened in all the windows with all the configured content | J6: PASS | K6: NA | L6: NA | M6: Diff browsers at the same time. so NA
A7: INJIWEB-36 | C7: INJIWEB-36_TC_07 | E7: Inji Home page and User wallet | G7: Open inji home page in incognito window | H7: 1. Open browser 2. Browse inji home page 3. Open another window in incognito mode 4. Browse inji home page | I7: Inji home page should be opened incognito mode with all the configured content | J7: PASS | K7: Yes | L7: UI
A8: INJIWEB-36 | C8: INJIWEB-36_TC_08 | E8: Inji Home page and User wallet | G8: Verify List of issuers on home page | H8: 1. Open browser 2. Browse inji home page 3. Verify all the issuers as per configuration | I8: Home page should be displayed with all the configured issuers details | J8: PASS | K8: Yes | L8: UI
A9: INJIWEB-36 | C9: INJIWEB-36_TC_09 | E9: Inji Home page and User wallet | G9: Serach issuer with complete name | H9: 1. Open browser 2. Browse inji home page 3. Search for an issuer with complete name | I9: Home page should be displayed with all the configured issuers details | J9: PASS | K9: Yes | L9: UI
A10: INJIWEB-36 | C10: INJIWEB-36_TC_10 | E10: Inji Home page and User wallet | G10: Search Issuer with partial string | H10: 1. Open browser 2. Browse inji home page 3. Search for an issuer with partial string | I10: Home page should be displayed with all the configured issuers details as per search string | J10: PASS | K10: Yes | L10: UI
A11: INJIWEB-36 | C11: INJIWEB-36_TC_11 | E11: Inji Home page and User wallet | G11: Serach issuer with non-existing value | H11: 1. Open browser 2. Browse inji home page 3. Search for an issuer with non-existing value | I11: Home page should not display any issuers | J11: PASS | K11: Yes | L11: UI
A12: INJIWEB-36 | C12: INJIWEB-36_TC_12 | E12: Inji Home page and User wallet | G12: Verify click functionality on selected issuer | H12: 1. Open browser 2. Browse inji home page 3. Click on Issuer | I12: Click button should be functional and should navigate to "Credential Type selection" screen | J12: PASS | K12: Yes | L12: UI
A13: INJIWEB-36 | C13: INJIWEB-36_TC_13 | E13: Inji Home page and User wallet | G13: Verify error message when the server is not reachable | H13: 1. Open browser 2. Browse inji home page 3. Make sure the site is down | I13: A red colour toaster should apper for 5 mins about the server is down and “The service is currently unavailable now. Please try again later.” at the footer | J13: PASS | K13: NA | L13: NA | M13: Service stop required
A14: INJIWEB-36 | C14: INJIWEB-36_TC_14 | E14: Inji Home page and User wallet | G14: Verify the error message when the list of issuers cannot be retrieved. | H14: 1. Open browser 2. Browse inji home page 3. Click on Issuer | I14: “No issuers found. Please try again later.” should apper at the Issuers list section | J14: PASS | K14: NA | L14: NA | M14: Service stop required
A15: INJIWEB-37 | B15: [UI ]Inji Web- Issuer selection in the “Home Page” | C15: INJIWEB-37_TC_01 | E15: Inji Home page and User wallet | F15: 1. The “Issuer Selection” in the Home page should be updated with the list of issuers in a clickable tile. 2. While loading the web page, an API call to issuers list should happen. 3. The list of issuers should be taken from the mimoto issuers config. | G15: Verify that the issuer can be selected. | H15: 1. Open browser 2. Browse inji home page 3. Click on Issuer | I15: Issuer can be selected and page navigated to "Credential Type selection" screen in the same tab | J15: PASS | K15: Yes | L15: UI
A16: INJIWEB-37 | C16: INJIWEB-37_TC_02 | E16: Inji Home page and User wallet | G16: Verify that the issuer can be selected in diff browser windows | H16: 1. Open browser 2. Browse inji home page 3. Open another browser window 4. Browse inji home page 5. Click on the issuer in both pages | I16: Issuer can be selected and page navigated to "Credential Type selection" screen in the same tab | J16: PASS | K16: NA | L16: NA | M16: Diff browsers at the same time. so NA
A17: INJIWEB-37 | C17: INJIWEB-37_TC_03 | E17: Inji Home page and User wallet | G17: Verify that the issuer can be selected in diff browser tabs | H17: 1. Open browser 2. Browse inji home page 3. Open another browser tab 4. Browse inji home page 5. Click on Issuer in both tabs | I17: Issuer can be selected and page navigated to "Credential Type selection" screen in the same tab | J17: PASS | K17: NA | L17: NA | M17: Diff browsers at the same time. so NA
A18: INJIWEB-37 | C18: INJIWEB-37_TC_04 | E18: Inji Home page and User wallet | G18: Verify that the issuer can be selected in diff browser windows in diff browsers | H18: 1. Open browser 2. Browse inji home page 3. Open another browser window in diff browser 4. Browse inji home page 5. Click on Issuer in both pages | I18: Issuer can be selected and page navigated to "Credential Type selection" screen in the same tab | J18: PASS | K18: NA | L18: NA | M18: Diff browsers at the same time. so NA
A19: INJIWEB-37 | C19: INJIWEB-37_TC_05 | E19: Inji Home page and User wallet | G19: Verify that the issuer can be selected in incongnito window | H19: 1. Open browser 2. Browse inji home page 3. Open another window in incognito mode 4. Browse inji home page 5. Click on issuer in both normal and incongnito mode | I19: Issuer can be selected and page navigated to "Credential Type selection" screen in the same tab | J19: PASS | K19: Yes | L19: UI
A20: INJIWEB-37 | C20: INJIWEB-37_TC_06 | E20: Inji Home page and User wallet | G20: Verify that the issuer can be selected after search operation | H20: 1. Open browser 2. Browse inji home page 3. Search for an issuer with complete / partial name 4. Click on issuer | I20: Issuer can be selected and page navigated to "Credential Type selection" screen in the same tab | J20: PASS | K20: Yes | L20: UI
A21: INJIWEB-37 | C21: INJIWEB-37_TC_07 | E21: Inji Home page and User wallet | G21: Update mimoto issuers config and verify list updated as per config | H21: 1. Update mimito config file for the specified branch 2. Restart the required services 3. Open the inji home page 4. Verify the issuere list 5. Select the new and previously available issuer | I21: Updated and previously available issuers should be displayed. And all the issuers can be selected | J21: PASS | K21: NA | L21: NA | M21: Config change required
A22: INJIWEB-44 | B22: [UI] Inji Web - Select the Credential type in the “Download Credential” page | C22: INJIWEB-44_TC_01 | D22: UI | E22: Credential type | F22: 1. The “Download Credential” page should be updated with the list of credentials(from the chosen issuer) in a clickable tile. 2. The credential types should be taken from the well-known file published by the issuer/s. 3. The endpoint required to prove ownership of the data (i.e. to authenticate the holder (ARC type)) should be in the well-known file for a given certificate type. | G22: Verify the crednetials are listed only for the selected issuer | H22: 1. Open browser 2. Browse inji home page 3. Select the issuer | I22: Credentials should be displayed for the selected issuer only | J22: PASS | K22: Yes | L22: UI
A23: INJIWEB-44 | C23: INJIWEB-44_TC_02 | E23: Credential type | G23: Verify the "Credential download" diff browser windows | H23: 1. Open browser 2. Browse inji home page 3. Select Issuer 4. Select Credential 3. Repeat the steps in another browser window | I23: Credentials should be displayed for the selected issuers and Authentication Portal should be opened for authentication | J23: PASS | K23: NA | L23: NA | M23: Config change required
A24: INJIWEB-44 | C24: INJIWEB-44_TC_03 | E24: Credential type | G24: Verify the "Credential download" diff browser tabs | H24: 1. Open browser 2. Browse inji home page 3. Select Issuer 4. Select Credential 3. Repeat the steps in another tab | I24: Credentials should be displayed for the selected issuers and Authentication Portal should be opened for authentication | J24: PASS | K24: NA | L24: NA | M24: Diff browsers at the same time. so NA
A25: INJIWEB-44 | C25: INJIWEB-44_TC_04 | E25: Credential type | G25: Verify the "Credential download" in diff browser windows in diff browsers | H25: 1. Open browser 2. Browse inji home page 3. Select Issuer 4. Select Credential 3. Repeat the steps in diff browsers | I25: Credentials should be displayed for the selected issuers and Authentication Portal should be opened for authentication | J25: PASS | K25: NA | L25: NA | M25: Diff browsers at the same time. so NA
A26: INJIWEB-44 | C26: INJIWEB-44_TC_05 | E26: Credential type | G26: Verify the "Credential download" in incongnito window | H26: 1. Open browser 2. Browse inji home page 3. Select Issuer 4. Select Credential 3. Repeat the steps in incognito | I26: Credentials should be displayed for the selected issuers and Authentication Portal should be opened for authentication | J26: PASS | K26: Yes | L26: UI
A27: INJIWEB-44 | C27: INJIWEB-44_TC_06 | E27: Credential type | G27: Verify that the "Credential donwload" can be selected after search operation | H27: 1. Open browser 2. Browse inji home page 3. Select Issuer 4. Search for a Credential. 5. Click on credential | I27: Credentials should be displayed as per the search criteria Authentication Portal should be opened for authentication | J27: PASS | K27: Yes | L27: UI
A28: INJIWEB-44 | C28: INJIWEB-44_TC_08 | E28: Credential type | G28: Update Crednetials for an issuer in well known file and verify credential list | H28: 1. Update credentials in a well nown file for a particular issuer 2. Restart the necessary services 3. Launch inji home page 4. Select issuer 5. Select the credential 6. Verify the credential | I28: Credential should be apperered in the tile Crednetial can be downloaded and verified | J28: PASS | K28: NA | L28: NA | M28: Config change required
A29: INJIWEB-44 | C29: INJIWEB-44_TC_04 | E29: Credential type | G29: Verify the "Credential download" in chrome browser | H29: 1. Open chrome browser 2. Browse inji home page 3. Select Issuer 4. Select Credential 3. provide valid details Download the credential | I29: Credentials shold be downloaded | J29: PASS | K29: Yes | L29: UI
A30: INJIWEB-44 | C30: INJIWEB-44_TC_04 | E30: Credential type | G30: Verify the "Credential download" in diff browser windows in diff browsers | H30: 1. Open moziall browser 2. Browse inji home page 3. Select Issuer 4. Select Credential 3. provide valid details Download the credential | I30: Credentials shold be downloaded | J30: PASS | K30: Yes | L30: UI
A31: INJIWEB-44 | C31: INJIWEB-44_TC_04 | E31: Credential type | G31: Verify the "Credential download" in diff browser windows in diff browsers | H31: 1. Open edge browser 2. Browse inji home page 3. Select Issuer 4. Select Credential 3. provide valid details Download the credential | I31: Credentials shold be downloaded | J31: PASS | K31: Yes | L31: UI
A32: INJIWEB-44 | C32: INJIWEB-44_TC_04 | E32: Credential type | G32: Verify the "Credential download" in diff browser windows in diff browsers | H32: 1. Open safari browser 2. Browse inji home page 3. Select Issuer 4. Select Credential 3. provide valid details Download the credential | I32: Credentials shold be downloaded | J32: PASS | K32: Yes | L32: UI
A33: INJIWEB-45 | B33: [UI] Inji Web: Authentication Portal (eSignet) - Authenticate user credentials | C33: INJIWEB-45_TC_01 | E33: Authenticate user credentials | G33: Verify all the mandatory fields have * mark Note: if all the fields are mandatory, then * is not mandatory on all the fields | H33: 1. Update credentials in a well nown file for a particular issuer 2. Restart the necessary services 3. Launch inji home page 4. Select issuer 5. Select the credential | I33: All the mandatory fileds should have * symbol If all the fileds are mandatory * not required | J33: PASS | K33: NA | L33: NA | M33: there is no way to understand if all filds are manadatory or not
A34: INJIWEB-45 | C34: INJIWEB-45_TC_02 | E34: Authenticate user credentials | G34: Verify Login button enabled if all the mandatory fileds are not entered | H34: 3. provide valid details Download the credential | I34: Login button should not be enabled untill user enters all the mandatory fields | J34: PASS | K34: Yes | L34: UI
A35: INJIWEB-45 | C35: INJIWEB-45_TC_03 | E35: Authenticate user credentials | G35: Verify all the mandatory fields have * mark for KBI authentication Note: if all the fields are mandatory, then * is not mandatory on all the fields | H35: 1. Select credential to download 2. Select KBI based authentication 3. Verify all the mandatory fields have * | I35: All the mandatory fileds should have * symbol | J35: PASS | K35: NA | L35: NA | M35: there is no way to understand if all filds are manadatory or not
A36: INJIWEB-45 | C36: INJIWEB-45_TC_04 | E36: Authenticate user credentials | G36: Verify with all valid details | H36: 1. Select credential to download 2. Select KBI based authentication 3. Verify with valid data | I36: Authentication should be passed and Issuer’s “Authentication Portal” page should hold the metadata that will be utilised to generate the pdf certificate. | J36: PASS | K36: Yes | L36: UI
A37: INJIWEB-45 | C37: INJIWEB-45_TC_05 | E37: Authenticate user credentials | G37: Verify with invalid details | H37: 1. Select credential to download 2. Select KBI based authentication 3. Verify with invalid data | I37: Authentication should be failed with proper error message: "Login Failed. Wrong details entered. Please enter correct details and login" | J37: PASS | K37: Yes | L37: UI
A38: INJIWEB-45 | C38: INJIWEB-45_TC_06 | E38: Authenticate user credentials | G38: Verify with all mandatory fileds | H38: 1. Select credential to download 2. Select KBI based authentication | I38: Login button should be enabled | J38: PASS | K38: Yes | L38: UI
A39: INJIWEB-45 | C39: INJIWEB-45_TC_07 | E39: Authenticate user credentials | G39: Verify Login button without entering all the mandatory fileds | H39: 1. Select credential to download 2. Select KBI based authentication 3. Do not enter all mandatory fields | I39: Login button should not be enabled untill user enters all the mandatory fields | J39: PASS | K39: Yes | L39: UI
A40: INJIWEB-45 | C40: INJIWEB-45_TC_08 | E40: Authenticate user credentials | G40: Verify proper labels on data field | H40: 1. Select credential to download 2. Select KBI based authentication 3. Verify labels on the fields | I40: Labels should have proper info and with proper alignmnet | J40: PASS | K40: Yes | L40: UI
...

Sheet Known issues
A1: Issue ID | B1: Summary | C1: Severity
A2: INJIWEB-1680 | B2: Injiweb usability :No user notification when the user entering a second cycle of invalid passcode attempts. | C2: Minor
A3: INJIWEB-1677 | B3: Enhancement Injiweb: Appropriate warning should be displayed before the last attempt before a temporary lock. | C3: Minor
A4: INJIWEB-1676 | B4: Injiweb: Failed password attempts do not show any attempt count and remaining tries before temporary lock. | C4: Major
A5: INJIWEB-1755 | B5: INJI Web - Enhancement - the view passcode icon should be modified when enabled | C5: Minor
A6: INJIWEB-1674 | B6: Inji-web enhancement: The profile section name is not matching the displayed top header name | C6: Minor
A7: INJIWEB-1657 | B7: Injiweb : Inji wallet link in gmail login page is pointing to developer instead of redirecting homepage. | C7: Minor
A8: INJIWEB-1187 | B8: inji-web: even when there is no qr code in the downloaded PDF , we are getting the "Number of Times" credential can be verified message | C8: Major
A9: INJIWEB-1761 | B9: INJI Web - In Open id for vp flow there is no appropriate response to the verifier when user continues as guest | C9: Major
A10: INJIWEB-1802 | B10: INJI Web - The "coming soon" toaster message is not matching with the theme and the functionality in INJI Web | C10: Major
A11: INJIWEB-1834 | B11: Injiweb: Double scrollbars are displayed on the vc after clicking view card option. | C11: Minor
A12: INJIWEB-1694 | B12: Context Property Not Read Correctly from issuer wellknown | C12: Major
... A83: ES-1691 | B83: There is should back button to go back to the previous screen | C83: Major

Sheet NL Android test cases
A1: TestCase_No | B1: Feature | C1: Scenario | D1: Result

Sheet NL ios test cases
A1: TestCase_No | B1: Feature | C1: Scenario | D1: Result

Sheet Bug tracker - Android
B2: Bug tracker
B3: TICKET# | C3: Bug Title | D3: Status | E3: Severity | F3: Notes
B4: https://github.com/mosip/inji/issues/135 | C4: Unable to download credential displayed invalid input Parameter - mobileNumber | D4: OPEN | E4: Blocker
B5: https://github.com/mosip/inji/issues/134 | C5: Unable to download credential displayed UIN not available in Database | D5: OPEN | E5: Blocker
B6: https://github.com/mosip/inji/issues/137 | C6: mpartner-default-mobile partner details is missing in kernel default properties | D6: OPEN | E6: Blocker
B7: https://github.com/mosip/inji/issues/157 | C7: Get UIN/VID text box has a not working question mark | D7: closed
B8: https://github.com/mosip/inji/issues/137 | C8: mpartner-default-mobile partner details is missing in kernel default properties | D8: closed
B9: https://github.com/mosip/inji/issues/135 | C9: Unable to download credential displayed invalid input Parameter - mobileNumber | D9: closed
B10: https://github.com/mosip/inji/issues/178 | C10: Unable to download VC | D10: OPEN | E10: Blocker
B11: https://github.com/mosip/inji/issues/159 | C11: To turn on the bluetooth "Go to setting" button is not working | D11: OPEN
B12: https://github.com/mosip/inji/issues/158 | C12: Get UIN/VID text box has a question mark | D12: OPEN
B13: https://github.com/mosip/inji/issues/155 | C13: VC's border is not round edged properly | D13: OPEN
B14: https://github.com/mosip/inji/issues/153 | C14: Reason for sharing getting over layed out of the VC details | D14: OPEN
B15: https://github.com/mosip/inji/issues/148 | C15: Edit tag option making changes in UIN values in the home screen | D15: OPEN
B16: https://github.com/mosip/inji/issues/147 | C16: full name atribute taking the place of ID type in VC | D16: OPEN
B17: https://github.com/mosip/inji/issues/146 | C17: ID type feild is empty in the downloaded VC | D17: OPEN
B18: https://github.com/mosip/inji/issues/143 | C18: VC address values getting overlaped | D18: OPEN
B19: https://github.com/mosip/inji/issues/142 | C19: MOSIP logo trimed in VC card | D19: OPEN
B20: https://github.com/mosip/inji/issues/140 | C20: VC stuck at loading state in Mobile ID app | D20: OPEN
B21: https://github.com/mosip/inji/issues/196 | C21: Unable to download VC with arabic language UIN | D21: OPEN | E21: Blocker
B22: https://github.com/mosip/inji/issues/197 | C22: RTL is not handled in inji app | D22: OPEN
B23: https://github.com/mosip/inji/issues/199 | C23: The full name attribute is missing in the VC detailed view | D23: OPEN
B24: https://github.com/mosip/inji/issues/200 | C24: VC detailed layout is not ocupying the spaces properly | D24: OPEN
B25: https://github.com/mosip/inji/issues/201 | C25: The android app is not fully capable with diffrent language filters | D25: OPEN
B26: https://github.com/mosip/inji/issues/202 | C26: When the VC card is downloading it has two id type's attribute | D26: OPEN
B27: https://github.com/mosip/inji/issues/228 | C27: Mobile-id mail's where been looped | D27: Open

Sheet Bug tracker - ios
C3: Bug tracker
C4: JIRA # | D4: Bug Title | E4: Status | F4: Notes | H4: new apk
C5: https://github.com/mosip/inji/issues/191 | D5: Application ID text box has a question mark. | E5: Open
C6: https://github.com/mosip/inji/issues/193 | D6: VC's border is not round edged properly | E6: Open
C7: https://github.com/mosip/inji/issues/195 | D7: Renaming VC replacing UIN number in the home screen | E7: Open
C8: https://github.com/mosip/inji/issues/203 | D8: RTL is not handled in inji app | E8: Open
C9: https://github.com/mosip/inji/issues/206 | D9: MOSIP logo trimed in VC card | E9: Open
C10: https://github.com/mosip/inji/issues/208 | D10: Unable to download VC with the UIN which is created in Arabic language. | E10: Open
C11: https://github.com/mosip/inji/issues/209 | D11: Unable to download credential with infant's UIN. | E11: Open
C12: https://github.com/mosip/inji/issues/210 | D12: Message should be revised in sharing device while waiting for receiver to accept VC | E12: Open
C13: https://github.com/mosip/inji/issues/211 | D13: VC is not in card format in sharing device. | E13: Open
C14: https://github.com/mosip/inji/issues/212 | D14: Radio button should be removed if device contain single VC while sharing. | E14: Open
C15: https://github.com/mosip/inji/issues/213 | D15: While Downloading VC field Name is displayed as idtype instead of UIN. | E15: Open
C16: https://github.com/mosip/inji/issues/214 | D16: Message popup in sharing device is still retained even after successful VC share. | E16: Open
... C29: https://github.com/mosip/inji/issues/302 | D29: A successful face match is not displaying the message in sharing device. | E29: Open

Sheet Release-bugs
A1: Bug id | B1: Bug title | C1: ios | D1: android | E1: assignee | F1: status | G1: remarks
A2: 293 | B2: Camera is not launched in verifier's phone even after giving the consent from Resident's phone. | C2: yes | D2: yes | E2: anushree | F2: closed
A3: 291 | B3: otp generation is failing with the error "while generating otp error is occured" | C3: yes | D3: yes | E3: anushree/santhosh | F3: closed
A4: 276 | B4: Inji app crashing while sharing | C4: no | D4: yes | E4: santhosh | F4: closed | H4: closed
A5: 252 | B5: Change the static message on Sharing and Receiving device during sharing ID | C5: yes | D5: yes | E5: anushree/santhosh | F5: Verified and added comment | H5: closed , Android | I5: Added my comment waiting for reply.
A6: 231 | B6: Inji app is not prompting the user to grant location access | C6: yes | D6: no | E6: anushree | F6: closed
A7: 226 | B7: Name and Device reference number fields are missing in sharing device and also on requesting device | C7: no | D7: yes | E7: santhosh | F7: closed | H7: closed
A8: 225 | B8: Name and Device reference number fields are missing in sharing device and also on requesting device | C8: yes | D8: no | E8: anushree | F8: re-opened | H8: Added my comments
A9: 223 | B9: In inji app still labels and button remained in english even after language switch | C9: yes | D9: no | E9: anushree | F9: re-opened | H9: reopen
A10: 220 | B10: Even though requesting credential with VID still we see UIN detials in the app | C10: no | D10: yes | E10: santhosh | F10: Assigned for testing | G10: story not provided yet
A11: 219 | B11: Even though requesting credential with VID still we see UIN detials in the app | C11: yes | D11: no | E11: anushree | F11: VID support not available
A12: 217 | B12: The ADD ID button is getting stacked down by the VC card | C12: yes | D12: no | E12: anushree | F12: closed | H12: closed
A13: 216 | B13: The ADD ID getting stacked down by the VC card | C13: no | D13: yes | E13: santhosh | F13: closed
A14: 215 | B14: Mobile id API credentials are not moving to printing state | E14: santhosh | F14: closed
A15: 213 | B15: While Downloading VC field Name is displayed as idtype instead of UIN. | C15: yes | D15: no | E15: anushree | F15: closed
A16: 212 | B16: Radio button should be removed if device contain single VC while sharing. | C16: yes | D16: no | E16: anushree | F16: closed
A17: 209 | B17: Unable to download credential with infant's UIN | C17: yes | D17: no | E17: anushree | F17: Assigned for testing
A18: 205 | B18: Full name attribute is missing in detail view screen of VC | C18: yes | D18: no | E18: anushree | F18: closed
A19: 203 | B19: RTL is not handled in inji app | C19: yes | D19: no | E19: anushree | F19: re-opened | H19: reopen
A20: 199 | B20: The full name attribute is missing in the VC detailed view | C20: no | D20: yes | E20: santhosh | F20: closed
A21: 197 | B21: RTL is not handled in inji app | C21: no | D21: yes | E21: santhosh | F21: re-opened | G21: check in this build
A22: 196 | B22: Unable to download VC with arabic language UIN | C22: no | D22: yes | E22: santhosh | F22: re-opened
A23: 195 | B23: Renaming VC replacing UIN number in the home screen | C23: yes | D23: no | E23: anushree | F23: closed
A24: 191 | B24: Application ID text box has a question mark. | C24: yes | D24: no | E24: anushree | F24: re-opened
A25: 187 | B25: Unable to delete the numbers in the textbox in AID screen | C25: yes | D25: no | E25: anushree | F25: closed
A26: 158 | B26: Get UIN/VID text box has a question mark | C26: no | D26: yes | E26: santhosh | F26: re-opened
A27: 156 | B27: When a requesting device cancels a sharing request device details are still displayed in the sharing device | E27: santhosh | F27: closed
A28: 155 | B28: VC's border is not round edged properly | C28: no | D28: yes | E28: santhosh | F28: re-opened
A29: 154 | B29: Connection is not established even after scanning qr code | C29: yes | D29: no | E29: anushree | F29: closed
A30: 140 | B30: VC stuck at loading state in Mobile ID app | C30: no | D30: yes | E30: santhosh | F30: closed | H30: closed
A31: 114 | B31: Mobile id - can't change the field from uin to vid while generating id | C31: yes | D31: yes | E31: anushree/santhosh | F31: closed
A32: 112 | B32: App is continuously flickering when app is open but phone kept idle for some duration | C32: no | D32: yes | E32: santhosh | F32: re-opened | H32: Added my comments
A33: 111 | B33: mobile id - Template exceptionServiceError occurring while downloading VC | C33: no | D33: yes | E33: santhosh | F33: re-opened
A34: 110 | B34: mobile id - 2 buttons are displayed in APK home page | C34: no | D34: yes | E34: santhosh | F34: re-opened | H34: reopen
A35: 94 | B35: When Residents request VC with VID the UIN label should be changed to VID | C35: no | D35: yes | E35: santhosh | F35: story not provided yet
A36: 79 | B36: "network request failed" message is still showing after the network is connected when we try to add id and when otp is provided | C36: no | D36: yes | E36: santhosh | F36: closed
A37: 261 | B37: iOS: app should detect if the user’s biometrics changes in the device settings page | C37: yes | D37: no | E37: anushree | F37: Not assigned for testing
A38: 260 | B38: Error message should be revised when biometrics is not enrolled in device settings page but still resident use biometric unlock | C38: no | D38: yes | E38: santhosh | F38: closed
A39: 259 | B39: Error message should be revised when biometrics is not enrolled in device settings page but still resident use biometric unlock | C39: yes | D39: no | E39: anushree | F39: closed | H39: closed
A40: 210 | B40: Message should be revised in sharing device while waiting for receiver to accept VC | C40: yes | D40: no | E40: anushree | F40: re-opened
...

Sheet BLE testing-sharing flow
A1: Device names | B1: verifier | C1: wallet | D1: BLE sanity status | E1: Status with jan 30th build | F1: remarks | G1: Status with Feb 8th build | I1: app size after installation | J1: app size after 1 vc download | K1: app size after 4 vc download
A2: redmi 6A, redmi 7A | B2: Android 9 BLE 4.2 | C2: Android 10 BLE 4.2 | D2: normal sharing | E2: pass | G2: pass
A3: redmi 6A, redmi 7A | B3: Android 9 BLE 4.3 | C3: Android 10 BLE 4.3 | D3: face auth on resident's phone | E3: pass | G3: pass
A4: redmi 6A, redmi 7A | B4: Android 9 BLE 4.4 | C4: Android 10 BLE 4.4 | D4: face auth on receiver's phone | E4: Pass | G4: pass
A6: Redmi 6A, Redmi note 10 lite | B6: Android 9 BLE 4.2 | C6: Android 10 BLE 5.0 | D6: normal sharing | E6: fail | F6: second attempt not working | G6: pass
A7: Redmi 6A, Redmi note 10 lite | B7: Android 9 BLE 4.2 | C7: Android 10 BLE 5.0 | D7: face auth on resident's phone | E7: pass | G7: pass
A8: Redmi 6A, Redmi note 10 lite | B8: Android 9 BLE 4.2 | C8: Android 10 BLE 5.0 | D8: face auth on receiver's phone | E8: pass | G8: pass
A10: redmi 7A, redmi note 10 lite | B10: Android 10 BLE 4.2 | C10: Android 10 BLE 5.0 | D10: normal sharing | E10: pass | G10: pass
A11: redmi 7A, redmi note 10 lite | B11: Android 10 BLE 4.2 | C11: Android 10 BLE 5.0 | D11: face auth on resident's phone | E11: pass | G11: pass
A12: redmi 7A, redmi note 10 lite | B12: Android 10 BLE 4.2 | C12: Android 10 BLE 5.0 | D12: face auth on receiver's phone | E12: pass | G12: pass | P12: device name | Q12: verifier | R12: wallet
P13: redmi 6A, redmi 7A | Q13: Android 9 BLE 4.2 | R13: Android 10 BLE 4.2
A14: redmi 7A, Vivo Y73 | B14: Android 10 BLE 4.2 | C14: Android 12 BLE 5.0 | D14: normal sharing | E14: Pass | G14: pass | P14: Redmi 6A, Redmi note 10 lite | Q14: Android 9 BLE 4.2 | R14: Android 10 BLE 5.0
A15: redmi 7A, Vivo Y74 | B15: Android 10 BLE 4.2 | C15: Android 12 BLE 5.0 | D15: face auth on resident's phone | E15: pass | G15: pass | P15: redmi 7A, redmi note 10 lite | Q15: Android 10 BLE 4.2 | R15: Android 10 BLE 5.0
A16: redmi 7A, Vivo Y75 | B16: Android 10 BLE 4.2 | C16: Android 12 BLE 5.0 | D16: face auth on receiver's phone | E16: Pass | G16: pass | P16: redmi 7A, Vivo Y73 | Q16: Android 10 BLE 4.2 | R16: Android 12 BLE 5.0
P17: redmi note 10 lite, samsung galaxy A03 core | Q17: Android 10 BLE 5.0 | R17: Android 11 BLE 4.2
