Workbook

Sheet Verification - Summary
B2: Details | C2: Stories Tested | D2: UI Test Cases | L2: UI Stories | S2: API Stories | Z2: Browser Versions used for Desktop/Laptop testing | AB2: Tested on qa-core env with components
C3: Total | D3: Total | E3: With Stories | F3: w/o Stories | G3: Pass | H3: Fail | I3: Not tested | L3: Story | M3: Test Results | S3: Story | T3: Test Results | Z3: Chrome: Version 142.0.7444.59 | AB3: docker.io/mosipdev/alpine:latest
B4: Partner Management Revamp | C4: 158 | D4: =COUNTA('PMS-UI-Test Cases'!C2:C67405) -> 6564 | E4: =SUM(M4:M7000) -> 6560 | F4: =D4-E4 -> 4 | G4: =COUNTIF('PMS-UI-Test Cases'!I1:I6971, "Pass") -> 6499 | H4: =COUNTIF('PMS-UI-Test Cases'!I1:I6971, "Fail") -> 34 | I4: =COUNTIF('PMS-UI-Test Cases'!I1:I6971, "NA") -> 31 | L4: =IFERROR(__xludf.Q9("UNIQUE(FILTER('PMS-Test Cases'!A2:A2013, 'PMS-Test Cases'!A2:A2013<>""""))"),"MOSIP-32692") -> MOSIP-32692 | M4: 22 | N4: 22 | O4: =COUNTIFS('PMS-UI-Test Cases'!A2:A2212,L4,'PMS-UI-Test Cases'!C2:C2212,"<>"&"",'PMS-UI-Test Cases'!I2:I2212,"Fail") -> 0 | P4: =M4-N4-O4 -> 0 | S4: MOSIP_34935 | T4: 5 | U4: 5 | V4: =COUNTIFS('PMS-UI-Test Cases'!G2:G2212,S4,'PMS-UI-Test Cases'!I2:I2212,"<>"&"",'PMS-UI-Test Cases'!O2:O2212,"Fail") -> 0 | W4: =T4-U4-V4 -> 0 | Z4: Firefox: Version 144.0.2 | AB4: docker.io/mosipdev/apitest-pms:release-1.3.x
L5: =IFERROR(__xludf.DUMMYFUNCTION("""COMPUTED_VALUE"""),"MOSIP-32672") -> MOSIP-32672 | M5: =COUNTIFS('PMS-UI-Test Cases'!A2:A2879,L5,'PMS-UI-Test Cases'!C2:C2879,"<>"&"") -> 18 | N5: =COUNTIFS('PMS-UI-Test Cases'!A2:A2879,L5,'PMS-UI-Test Cases'!C2:C2879,"<>"&"",'PMS-UI-Test Cases'!I2:I2879,"PASS") -> 18 | O5: =COUNTIFS('PMS-UI-Test Cases'!A3:A2213,L5,'PMS-UI-Test Cases'!C3:C2213,"<>"&"",'PMS-UI-Test Cases'!I3:I2213,"Fail") -> 0 | P5: =M5-N5-O5 -> 0 | S5: MOSIP-33320 | T5: 10 | U5: 10 | V5: =COUNTIFS('PMS-UI-Test Cases'!G2:G2213,S5,'PMS-UI-Test Cases'!I2:I2213,"<>"&"",'PMS-UI-Test Cases'!O2:O2213,"Fail") -> 0 | W5: =T5-U5-V5 -> 0 | Z5: Edge: Version 142.0.3595.53 | AB5: docker.io/mosipdev/apitest-prereg:develop
B6: Total | C6: =SUM(C3:C5) -> 158 | D6: =SUM(D3:D5) -> 6564 | E6: =SUM(E3:E5) -> 6560 | F6: =SUM(F3:F5) -> 4 | G6: =SUM(G3:G5) -> 6499 | H6: =SUM(H3:H5) -> 34 | I6: =SUM(I3:I5) -> 31 | L6: =IFERROR(__xludf.DUMMYFUNCTION("""COMPUTED_VALUE"""),"MOSIP-32957") -> MOSIP-32957 | M6: =COUNTIFS('PMS-UI-Test Cases'!A2:A2880,L6,'PMS-UI-Test Cases'!C2:C2880,"<>"&"") -> 28 | N6: =COUNTIFS('PMS-UI-Test Cases'!A2:A2880,L6,'PMS-UI-Test Cases'!C2:C2880,"<>"&"",'PMS-UI-Test Cases'!I2:I2880,"PASS") -> 28 | O6: =COUNTIFS('PMS-UI-Test Cases'!A4:A2214,L6,'PMS-UI-Test Cases'!C4:C2214,"<>"&"",'PMS-UI-Test Cases'!I4:I2214,"Fail") -> 0 | P6: =M6-N6-O6 -> 0 | S6: MOSIP-33487 | T6: 12 | U6: 12 | V6: =COUNTIFS('PMS-UI-Test Cases'!G3:G2214,S6,'PMS-UI-Test Cases'!I3:I2214,"<>"&"",'PMS-UI-Test Cases'!O3:O2214,"Fail") -> 0 | W6: =T6-U6-V6 -> 0 | Z6: Safari: Version 18.6 (20621.3.11.11.3 | AB6: docker.io/mosipdev/auditsweeper:develop
L7: =IFERROR(__xludf.DUMMYFUNCTION("""COMPUTED_VALUE"""),"MOSIP-33227") -> MOSIP-33227 | M7: =COUNTIFS('PMS-UI-Test Cases'!A2:A2881,L7,'PMS-UI-Test Cases'!C2:C2881,"<>"&"") -> 41 | N7: =COUNTIFS('PMS-UI-Test Cases'!A3:A2881,L7,'PMS-UI-Test Cases'!C3:C2881,"<>"&"",'PMS-UI-Test Cases'!I3:I2881,"PASS") -> 41 | O7: =COUNTIFS('PMS-UI-Test Cases'!A5:A2215,L7,'PMS-UI-Test Cases'!C5:C2215,"<>"&"",'PMS-UI-Test Cases'!I5:I2215,"Fail") -> 0 | P7: =M7-N7-O7 -> 0 | S7: MOSIP-33499 | T7: 3 | U7: 3 | V7: =COUNTIFS('PMS-UI-Test Cases'!G4:G2215,S7,'PMS-UI-Test Cases'!I4:I2215,"<>"&"",'PMS-UI-Test Cases'!O4:O2215,"Fail") -> 0 | W7: =T7-U7-V7 -> 0 | AB7: docker.io/mosipdev/captcha-validation-service:develop
B8: Details | C8: Stories Tested | D8: API Test Cases | L8: =IFERROR(__xludf.DUMMYFUNCTION("""COMPUTED_VALUE"""),"MOSIP-33207") -> MOSIP-33207 | M8: =COUNTIFS('PMS-UI-Test Cases'!A3:A2882,L8,'PMS-UI-Test Cases'!C3:C2882,"<>"&"") -> 37 | N8: =COUNTIFS('PMS-UI-Test Cases'!A4:A2882,L8,'PMS-UI-Test Cases'!C4:C2882,"<>"&"",'PMS-UI-Test Cases'!I4:I2882,"PASS") -> 37 | O8: =COUNTIFS('PMS-UI-Test Cases'!A6:A2216,L8,'PMS-UI-Test Cases'!C6:C2216,"<>"&"",'PMS-UI-Test Cases'!I6:I2216,"Fail") -> 0 | P8: =M8-N8-O8 -> 0 | S8: MOSIP-33643 | T8: 12 | U8: 12 | V8: =COUNTIFS('PMS-UI-Test Cases'!G5:G2216,S8,'PMS-UI-Test Cases'!I5:I2216,"<>"&"",'PMS-UI-Test Cases'!O5:O2216,"Fail") -> 0 | W8: =T8-U8-V8 -> 0 | Z8: Browser Versions used for Tablet testing | AB8: docker.io/mosipdev/dsl-orchestrator:develop
C9: Total | D9: Total | E9: With Stories | F9: w/o Stories | G9: Pass | H9: Fail | I9: Not tested | L9: =IFERROR(__xludf.DUMMYFUNCTION("""COMPUTED_VALUE"""),"MOSIP-33217") -> MOSIP-33217 | M9: =COUNTIFS('PMS-UI-Test Cases'!A4:A2883,L9,'PMS-UI-Test Cases'!C4:C2883,"<>"&"") -> 35 | N9: =COUNTIFS('PMS-UI-Test Cases'!A5:A2883,L9,'PMS-UI-Test Cases'!C5:C2883,"<>"&"",'PMS-UI-Test Cases'!I5:I2883,"PASS") -> 35 | O9: =COUNTIFS('PMS-UI-Test Cases'!A7:A2217,L9,'PMS-UI-Test Cases'!C7:C2217,"<>"&"",'PMS-UI-Test Cases'!I7:I2217,"Fail") -> 0 | P9: =M9-N9-O9 -> 0 | S9: MOSIP-33722 | T9: 8 | U9: 8 | V9: =COUNTIFS('PMS-UI-Test Cases'!G6:G2217,S9,'PMS-UI-Test Cases'!I6:I2217,"<>"&"",'PMS-UI-Test Cases'!O6:O2217,"Fail") -> 0 | W9: =T9-U9-V9 -> 0 | Z9: Chrome: Version 141.0.7390.55 | AB9: docker.io/mosipdev/dsl-orchestrator:release-1.2.1.x
B10: Partner Management Revamp | C10: 54 | D10: 988 | E10: 988 | F10: 0 | G10: 982 | H10: 0 | I10: 6 | L10: =IFERROR(__xludf.DUMMYFUNCTION("""COMPUTED_VALUE"""),"MOSIP-32702") -> MOSIP-32702 | M10: 40 | N10: 40 | O10: =COUNTIFS('PMS-UI-Test Cases'!A8:A2218,L10,'PMS-UI-Test Cases'!C8:C2218,"<>"&"",'PMS-UI-Test Cases'!I8:I2218,"Fail") -> 0 | P10: 0 | S10: MOSIP-33941 | T10: 16 | U10: 16 | V10: =COUNTIFS('PMS-UI-Test Cases'!G7:G2218,S10,'PMS-UI-Test Cases'!I7:I2218,"<>"&"",'PMS-UI-Test Cases'!O7:O2218,"Fail") -> 0 | W10: 0 | Z10: Firefox: Version 144.0.2 | AB10: docker.io/mosipdev/dsl-orchestrator:release-1.3.x
L11: =IFERROR(__xludf.DUMMYFUNCTION("""COMPUTED_VALUE"""),"MOSIP-33237") -> MOSIP-33237 | M11: =COUNTIFS('PMS-UI-Test Cases'!A6:A2885,L11,'PMS-UI-Test Cases'!C6:C2885,"<>"&"") -> 17 | N11: =COUNTIFS('PMS-UI-Test Cases'!A7:A2885,L11,'PMS-UI-Test Cases'!C7:C2885,"<>"&"",'PMS-UI-Test Cases'!I7:I2885,"PASS") -> 17 | O11: =COUNTIFS('PMS-UI-Test Cases'!A9:A2219,L11,'PMS-UI-Test Cases'!C9:C2219,"<>"&"",'PMS-UI-Test Cases'!I9:I2219,"Fail") -> 0 | P11: =M11-N11-O11 -> 0 | S11: MOSIP-34236 | T11: 11 | U11: 11 | V11: =COUNTIFS('PMS-UI-Test Cases'!G8:G2219,S11,'PMS-UI-Test Cases'!I8:I2219,"<>"&"",'PMS-UI-Test Cases'!O8:O2219,"Fail") -> 0 | W11: 0 | Z11: Edge: Version 141.0.3537.99 | AB11: docker.io/mosipdev/dsl-packetcreator:develop
B12: Total | C12: =SUM(C9:C11) -> 54 | D12: =SUM(D9:D11) -> 988 | E12: =SUM(E9:E11) -> 988 | F12: =SUM(F9:F11) -> 0 | G12: =SUM(G9:G11) -> 982 | H12: =SUM(H9:H11) -> 0 | I12: =SUM(I9:I11) -> 6 | L12: =IFERROR(__xludf.DUMMYFUNCTION("""COMPUTED_VALUE"""),"MOSIP-32712") -> MOSIP-32712 | M12: 18 | N12: 18 | O12: =COUNTIFS('PMS-UI-Test Cases'!A10:A2220,L12,'PMS-UI-Test Cases'!C10:C2220,"<>"&"",'PMS-UI-Test Cases'!I10:I2220,"Fail") -> 0 | P12: =M12-N12-O12 -> 0 | S12: MOSIP-34238 | T12: 7 | U12: 7 | V12: =COUNTIFS('PMS-UI-Test Cases'!G9:G2220,S12,'PMS-UI-Test Cases'!I9:I2220,"<>"&"",'PMS-UI-Test Cases'!O9:O2220,"Fail") -> 0 | W12: =T12-U12-V12 -> 0 | AB12: docker.io/mosipdev/uitest-pmp-v2:release-1.3.x
L13: =IFERROR(__xludf.DUMMYFUNCTION("""COMPUTED_VALUE"""),"MOSIP-32662") -> MOSIP-32662 | M13: =COUNTIFS('PMS-UI-Test Cases'!A8:A2887,L13,'PMS-UI-Test Cases'!C8:C2887,"<>"&"") -> 40 | N13: =COUNTIFS('PMS-UI-Test Cases'!A9:A2887,L13,'PMS-UI-Test Cases'!C9:C2887,"<>"&"",'PMS-UI-Test Cases'!I9:I2887,"PASS") -> 37 | O13: =COUNTIFS('PMS-UI-Test Cases'!A11:A2221,L13,'PMS-UI-Test Cases'!C11:C2221,"<>"&"",'PMS-UI-Test Cases'!I11:I2221,"Fail") -> 2 | P13: 1 | S13: MOSIP-34239 | T13: 6 | U13: 6 | V13: =COUNTIFS('PMS-UI-Test Cases'!G10:G2221,S13,'PMS-UI-Test Cases'!I10:I2221,"<>"&"",'PMS-UI-Test Cases'!O10:O2221,"Fail") -> 0 | W13: =T13-U13-V13 -> 0 | Z13: Browser Versions used for Extra large screen testing | AB13: docker.io/mosipid/admin-service:1.2.1.1
L14: =IFERROR(__xludf.DUMMYFUNCTION("""COMPUTED_VALUE"""),"MOSIP-32652") -> MOSIP-32652 | M14: 11 | N14: 11 | O14: =COUNTIFS('PMS-UI-Test Cases'!A12:A2222,L14,'PMS-UI-Test Cases'!C12:C2222,"<>"&"",'PMS-UI-Test Cases'!I12:I2222,"Fail") -> 0 | P14: =M14-N14-O14 -> 0 | S14: MOSIP-34265 | T14: 17 | U14: 17 | V14: =COUNTIFS('PMS-UI-Test Cases'!G11:G2222,S14,'PMS-UI-Test Cases'!I11:I2222,"<>"&"",'PMS-UI-Test Cases'!O11:O2222,"Fail") -> 0 | W14: 0 | Z14: Chrome: Version 142.0.7444.59 | AB14: docker.io/mosipid/admin-ui:1.2.0.1
B15: ="Functional Testing - Stories Verified : " & C6 -> Functional Testing - Stories Verified : 158 | L15: =IFERROR(__xludf.DUMMYFUNCTION("""COMPUTED_VALUE"""),"MOSIP-32682") -> MOSIP-32682 | M15: =COUNTIFS('PMS-UI-Test Cases'!A10:A2889,L15,'PMS-UI-Test Cases'!C10:C2889,"<>"&"") -> 9 | N15: 7 | O15: 1 | P15: 0 | S15: MOSIP-34711 | T15: 14 | U15: 14 | V15: =COUNTIFS('PMS-UI-Test Cases'!G12:G2223,S15,'PMS-UI-Test Cases'!I12:I2223,"<>"&"",'PMS-UI-Test Cases'!O12:O2223,"Fail") -> 0 | W15: 0 | Z15: Firefox: Version 144.0.2 | AB15: docker.io/mosipid/apitest-auth:1.2.1.1-beta.1
B16: ="Test cases : " & D6 & " Passed : "& G6 & " Failed : " & H6 & " Skipped : " & I6 -> Test cases : 6564 Passed : 6499 Failed : 34 Skipped : 31 | L16: =IFERROR(__xludf.DUMMYFUNCTION("""COMPUTED_VALUE"""),"MOSIP-33197") -> MOSIP-33197 | M16: =COUNTIFS('PMS-UI-Test Cases'!A11:A2890,L16,'PMS-UI-Test Cases'!C11:C2890,"<>"&"") -> 58 | N16: =COUNTIFS('PMS-UI-Test Cases'!A12:A2890,L16,'PMS-UI-Test Cases'!C12:C2890,"<>"&"",'PMS-UI-Test Cases'!I12:I2890,"PASS") -> 58 | O16: =COUNTIFS('PMS-UI-Test Cases'!A14:A2224,L16,'PMS-UI-Test Cases'!C14:C2224,"<>"&"",'PMS-UI-Test Cases'!I14:I2224,"Fail") -> 0 | P16: =M16-N16-O16 -> 0 | S16: MOSIP-34823 | T16: 9 | U16: 9 | V16: =COUNTIFS('PMS-UI-Test Cases'!G13:G2224,S16,'PMS-UI-Test Cases'!I13:I2224,"<>"&"",'PMS-UI-Test Cases'!O13:O2224,"Fail") -> 0 | W16: 0 | Z16: Edge: Version 142.0.3595.53 | AB16: docker.io/mosipid/apitest-idrepo:1.2.2.2
B17: ="Test Rate : " & INT((((G6+H6)/D6)*100)) & "% With Pass Rate : " & INT((G6/(G6+H6))*100) & "%" -> Test Rate : 99% With Pass Rate : 99% | L17: =IFERROR(__xludf.DUMMYFUNCTION("""COMPUTED_VALUE"""),"MOSIP-33247") -> MOSIP-33247 | M17: 74 | N17: 73 | O17: =COUNTIFS('PMS-UI-Test Cases'!A15:A2225,L17,'PMS-UI-Test Cases'!C15:C2225,"<>"&"",'PMS-UI-Test Cases'!I15:I2225,"Fail") -> 1 | P17: =M17-N17-O17 -> 0 | S17: MOSIP-34944 | T17: 19 | U17: 19 | V17: =COUNTIFS('PMS-UI-Test Cases'!G14:G2225,S17,'PMS-UI-Test Cases'!I14:I2225,"<>"&"",'PMS-UI-Test Cases'!O14:O2225,"Fail") -> 0 | W17: 0 | Z17: Safari: Version 18.6 (20621.3.11.11.3 | AB17: docker.io/mosipid/apitest-masterdata:1.2.1.2
L18: =IFERROR(__xludf.DUMMYFUNCTION("""COMPUTED_VALUE"""),"MOSIP-33258") -> MOSIP-33258 | M18: =COUNTIFS('PMS-UI-Test Cases'!A13:A2892,L18,'PMS-UI-Test Cases'!C13:C2892,"<>"&"") -> 57 | N18: =COUNTIFS('PMS-UI-Test Cases'!A14:A2892,L18,'PMS-UI-Test Cases'!C14:C2892,"<>"&"",'PMS-UI-Test Cases'!I14:I2892,"PASS") -> 57 | O18: =COUNTIFS('PMS-UI-Test Cases'!A16:A2226,L18,'PMS-UI-Test Cases'!C16:C2226,"<>"&"",'PMS-UI-Test Cases'!I16:I2226,"Fail") -> 0 | P18: =M18-N18-O18 -> 0 | S18: MOSIP-35255 | T18: 42 | U18: 42 | V18: =COUNTIFS('PMS-UI-Test Cases'!G15:G2226,S18,'PMS-UI-Test Cases'!I15:I2226,"<>"&"",'PMS-UI-Test Cases'!O15:O2226,"Fail") -> 0 | W18: 0 | AB18: docker.io/mosipid/apitest-resident:1.2.1.2
B19: API Testing - Stories Verified : 54 | L19: =IFERROR(__xludf.DUMMYFUNCTION("""COMPUTED_VALUE"""),"MOSIP-33268") -> MOSIP-33268 | M19: =COUNTIFS('PMS-UI-Test Cases'!A14:A2893,L19,'PMS-UI-Test Cases'!C14:C2893,"<>"&"") -> 35 | N19: =COUNTIFS('PMS-UI-Test Cases'!A15:A2893,L19,'PMS-UI-Test Cases'!C15:C2893,"<>"&"",'PMS-UI-Test Cases'!I15:I2893,"PASS") -> 35 | O19: =COUNTIFS('PMS-UI-Test Cases'!A17:A2227,L19,'PMS-UI-Test Cases'!C17:C2227,"<>"&"",'PMS-UI-Test Cases'!I17:I2227,"Fail") -> 0 | P19: =M19-N19-O19 -> 0 | S19: MOSIP-35262 | T19: 15 | U19: 15 | V19: =COUNTIFS('PMS-UI-Test Cases'!G16:G2227,S19,'PMS-UI-Test Cases'!I16:I2227,"<>"&"",'PMS-UI-Test Cases'!O16:O2227,"Fail") -> 0 | W19: 0 | AB19: docker.io/mosipid/artifactory-server:1.2.0.2
B20: Test cases : 988 Passed: 982 Failed : 0 Skipped: 6 | L20: =IFERROR(__xludf.DUMMYFUNCTION("""COMPUTED_VALUE"""),"MOSIP-33288") -> MOSIP-33288 | M20: =COUNTIFS('PMS-UI-Test Cases'!A15:A2894,L20,'PMS-UI-Test Cases'!C15:C2894,"<>"&"") -> 31 | N20: =COUNTIFS('PMS-UI-Test Cases'!A15:A2894,L20,'PMS-UI-Test Cases'!C15:C2894,"<>"&"",'PMS-UI-Test Cases'!I15:I2894,"PASS") -> 31 | O20: =COUNTIFS('PMS-UI-Test Cases'!A18:A2228,L20,'PMS-UI-Test Cases'!C18:C2228,"<>"&"",'PMS-UI-Test Cases'!I18:I2228,"Fail") -> 0 | P20: =M20-N20-O20 -> 0 | S20: MOSIP-35264 | T20: 30 | U20: 30 | V20: =COUNTIFS('PMS-UI-Test Cases'!G17:G2228,S20,'PMS-UI-Test Cases'!I17:I2228,"<>"&"",'PMS-UI-Test Cases'!O17:O2228,"Fail") -> 0 | W20: 0 | AB20: docker.io/mosipid/artifactory-server:1.2.0.3
B21: Test Rate : 99% With Pass Rate : 99% | L21: =IFERROR(__xludf.DUMMYFUNCTION("""COMPUTED_VALUE"""),"MOSIP-32977") -> MOSIP-32977 | M21: =COUNTIFS('PMS-UI-Test Cases'!A15:A2895,L21,'PMS-UI-Test Cases'!C15:C2895,"<>"&"") -> 26 | N21: =COUNTIFS('PMS-UI-Test Cases'!A16:A2895,L21,'PMS-UI-Test Cases'!C16:C2895,"<>"&"",'PMS-UI-Test Cases'!I16:I2895,"PASS") -> 26 | O21: =COUNTIFS('PMS-UI-Test Cases'!A19:A2229,L21,'PMS-UI-Test Cases'!C19:C2229,"<>"&"",'PMS-UI-Test Cases'!I19:I2229,"Fail") -> 0 | P21: =M21-N21-O21 -> 0 | S21: MOSIP-35560 | T21: 10 | U21: 10 | V21: =COUNTIFS('PMS-UI-Test Cases'!G18:G2229,S21,'PMS-UI-Test Cases'!I18:I2229,"<>"&"",'PMS-UI-Test Cases'!O18:O2229,"Fail") -> 0 | W21: 0 | AB21: docker.io/mosipid/artifactory-server:1.3.0-beta.1
L22: =IFERROR(__xludf.DUMMYFUNCTION("""COMPUTED_VALUE"""),"MOSIP-33617") -> MOSIP-33617 | M22: =COUNTIFS('PMS-UI-Test Cases'!A16:A2896,L22,'PMS-UI-Test Cases'!C16:C2896,"<>"&"") -> 13 | N22: =COUNTIFS('PMS-UI-Test Cases'!A17:A2896,L22,'PMS-UI-Test Cases'!C17:C2896,"<>"&"",'PMS-UI-Test Cases'!I17:I2896,"PASS") -> 13 | O22: =COUNTIFS('PMS-UI-Test Cases'!A20:A2230,L22,'PMS-UI-Test Cases'!C20:C2230,"<>"&"",'PMS-UI-Test Cases'!I20:I2230,"Fail") -> 0 | P22: =M22-N22-O22 -> 0 | S22: MOSIP-35571 | T22: 15 | U22: 15 | V22: =COUNTIFS('PMS-UI-Test Cases'!G19:G2230,S22,'PMS-UI-Test Cases'!I19:I2230,"<>"&"",'PMS-UI-Test Cases'!O19:O2230,"Fail") -> 0 | W22: 0 | AB22: docker.io/mosipid/artifactory-server:1.4.1-ES
L23: =IFERROR(__xludf.DUMMYFUNCTION("""COMPUTED_VALUE"""),"MOSIP-33346") -> MOSIP-33346 | M23: =COUNTIFS('PMS-UI-Test Cases'!A17:A2897,L23,'PMS-UI-Test Cases'!C17:C2897,"<>"&"") -> 14 | N23: 12 | O23: =COUNTIFS('PMS-UI-Test Cases'!A21:A2231,L23,'PMS-UI-Test Cases'!C21:C2231,"<>"&"",'PMS-UI-Test Cases'!I21:I2231,"Fail") -> 0 | P23: 2 | S23: MOSIP-35581 | T23: 27 | U23: 27 | V23: =COUNTIFS('PMS-UI-Test Cases'!G20:G2231,S23,'PMS-UI-Test Cases'!I20:I2231,"<>"&"",'PMS-UI-Test Cases'!O20:O2231,"Fail") -> 0 | W23: 0 | AB23: docker.io/mosipid/authentication-internal-service:1.2.1.0
L24: =IFERROR(__xludf.DUMMYFUNCTION("""COMPUTED_VALUE"""),"MOSIP-32535") -> MOSIP-32535 | M24: =COUNTIFS('PMS-UI-Test Cases'!A17:A2898,L24,'PMS-UI-Test Cases'!C17:C2898,"<>"&"") -> 46 | N24: =COUNTIFS('PMS-UI-Test Cases'!A17:A2898,L24,'PMS-UI-Test Cases'!C17:C2898,"<>"&"",'PMS-UI-Test Cases'!I17:I2898,"PASS") -> 46 | O24: =COUNTIFS('PMS-UI-Test Cases'!A22:A2232,L24,'PMS-UI-Test Cases'!C22:C2232,"<>"&"",'PMS-UI-Test Cases'!I22:I2232,"Fail") -> 0 | P24: =M24-N24-O24 -> 0 | S24: MOSIP-35876 | T24: 13 | U24: 13 | V24: =COUNTIFS('PMS-UI-Test Cases'!G21:G2232,S24,'PMS-UI-Test Cases'!I21:I2232,"<>"&"",'PMS-UI-Test Cases'!O21:O2232,"Fail") -> 0 | W24: 0 | AB24: docker.io/mosipid/authentication-otp-service:1.2.1.0
L25: =IFERROR(__xludf.DUMMYFUNCTION("""COMPUTED_VALUE"""),"MOSIP-32130") -> MOSIP-32130 | M25: =COUNTIFS('PMS-UI-Test Cases'!A17:A2899,L25,'PMS-UI-Test Cases'!C17:C2899,"<>"&"") -> 14 | N25: 14 | O25: =COUNTIFS('PMS-UI-Test Cases'!A23:A2233,L25,'PMS-UI-Test Cases'!C23:C2233,"<>"&"",'PMS-UI-Test Cases'!I23:I2233,"Fail") -> 0 | P25: 1 | S25: MOSIP-36467 | T25: 26 | U25: 26 | V25: =COUNTIFS('PMS-UI-Test Cases'!G22:G2233,S25,'PMS-UI-Test Cases'!I22:I2233,"<>"&"",'PMS-UI-Test Cases'!O22:O2233,"Fail") -> 0 | W25: 0 | AB25: docker.io/mosipid/authentication-service:1.2.1.0
L26: =IFERROR(__xludf.DUMMYFUNCTION("""COMPUTED_VALUE"""),"MOSIP-32132") -> MOSIP-32132 | M26: =COUNTIFS('PMS-UI-Test Cases'!A18:A2900,L26,'PMS-UI-Test Cases'!C18:C2900,"<>"&"") -> 17 | N26: =COUNTIFS('PMS-UI-Test Cases'!A19:A2900,L26,'PMS-UI-Test Cases'!C19:C2900,"<>"&"",'PMS-UI-Test Cases'!I19:I2900,"PASS") -> 17 | O26: =COUNTIFS('PMS-UI-Test Cases'!A24:A2234,L26,'PMS-UI-Test Cases'!C24:C2234,"<>"&"",'PMS-UI-Test Cases'!I24:I2234,"Fail") -> 0 | P26: =M26-N26-O26 -> 0 | S26: MOSIP-36506 | T26: 8 | U26: 7 | V26: =COUNTIFS('PMS-UI-Test Cases'!G23:G2234,S26,'PMS-UI-Test Cases'!I23:I2234,"<>"&"",'PMS-UI-Test Cases'!O23:O2234,"Fail") -> 0 | W26: 1 | AB26: docker.io/mosipid/biosdk-server:1.2.0.1
L27: =IFERROR(__xludf.DUMMYFUNCTION("""COMPUTED_VALUE"""),"MOSIP-32407") -> MOSIP-32407 | M27: 40 | N27: 40 | O27: =COUNTIFS('PMS-UI-Test Cases'!A25:A2235,L27,'PMS-UI-Test Cases'!C25:C2235,"<>"&"",'PMS-UI-Test Cases'!I25:I2235,"Fail") -> 0 | P27: =M27-N27-O27 -> 0 | S27: MOSIP-37141 | T27: 23 | U27: 23 | V27: 0 | W27: 0 | AB27: docker.io/mosipid/commons-packet-service:1.2.0.1
L28: =IFERROR(__xludf.DUMMYFUNCTION("""COMPUTED_VALUE"""),"MOSIP-32133") -> MOSIP-32133 | M28: =COUNTIFS('PMS-UI-Test Cases'!A20:A2902,L28,'PMS-UI-Test Cases'!C20:C2902,"<>"&"") -> 78 | N28: =COUNTIFS('PMS-UI-Test Cases'!A21:A2902,L28,'PMS-UI-Test Cases'!C21:C2902,"<>"&"",'PMS-UI-Test Cases'!I21:I2902,"PASS") -> 78 | O28: =COUNTIFS('PMS-UI-Test Cases'!A26:A2236,L28,'PMS-UI-Test Cases'!C26:C2236,"<>"&"",'PMS-UI-Test Cases'!I26:I2236,"Fail") -> 0 | P28: =M28-N28-O28 -> 0 | S28: MOSIP-37273 | T28: 22 | U28: 22 | V28: =COUNTIFS('PMS-UI-Test Cases'!G25:G2236,S28,'PMS-UI-Test Cases'!I25:I2236,"<>"&"",'PMS-UI-Test Cases'!O25:O2236,"Fail") -> 0 | W28: 0 | AB28: docker.io/mosipid/config-server:1.1.2
L29: =IFERROR(__xludf.DUMMYFUNCTION("""COMPUTED_VALUE"""),"MOSIP-32150") -> MOSIP-32150 | M29: =COUNTIFS('PMS-UI-Test Cases'!A21:A2903,L29,'PMS-UI-Test Cases'!C21:C2903,"<>"&"") -> 29 | N29: =COUNTIFS('PMS-UI-Test Cases'!A22:A2903,L29,'PMS-UI-Test Cases'!C22:C2903,"<>"&"",'PMS-UI-Test Cases'!I22:I2903,"PASS") -> 29 | O29: =COUNTIFS('PMS-UI-Test Cases'!A27:A2237,L29,'PMS-UI-Test Cases'!C27:C2237,"<>"&"",'PMS-UI-Test Cases'!I27:I2237,"Fail") -> 0 | P29: =M29-N29-O29 -> 0 | S29: MOSIP-37434 | T29: 15 | U29: 15 | V29: =COUNTIFS('PMS-UI-Test Cases'!G26:G2237,S29,'PMS-UI-Test Cases'!I26:I2237,"<>"&"",'PMS-UI-Test Cases'!O26:O2237,"Fail") -> 0 | W29: 0 | AB29: docker.io/mosipid/consolidator-websub-service:1.2.0.1
L30: =IFERROR(__xludf.DUMMYFUNCTION("""COMPUTED_VALUE"""),"MOSIP-32947") -> MOSIP-32947 | M30: 43 | N30: 43 | O30: =COUNTIFS('PMS-UI-Test Cases'!A28:A2238,L30,'PMS-UI-Test Cases'!C28:C2238,"<>"&"",'PMS-UI-Test Cases'!I28:I2238,"Fail") -> 0 | P30: =M30-N30-O30 -> 0 | S30: MOSIP-37636 | T30: 19 | U30: 19 | V30: =COUNTIFS('PMS-UI-Test Cases'!G27:G2238,S30,'PMS-UI-Test Cases'!I27:I2238,"<>"&"",'PMS-UI-Test Cases'!O27:O2238,"Fail") -> 0 | W30: 0 | AB30: docker.io/mosipid/credential-request-generator:1.2.2.0
L31: =IFERROR(__xludf.DUMMYFUNCTION("""COMPUTED_VALUE"""),"MOSIP-34615") -> MOSIP-34615 | M31: =COUNTIFS('PMS-UI-Test Cases'!A23:A2904,L31,'PMS-UI-Test Cases'!C23:C2904,"<>"&"") -> 82 | N31: =COUNTIFS('PMS-UI-Test Cases'!A24:A2904,L31,'PMS-UI-Test Cases'!C24:C2904,"<>"&"",'PMS-UI-Test Cases'!I24:I2904,"PASS") -> 81 | O31: =COUNTIFS('PMS-UI-Test Cases'!A29:A2239,L31,'PMS-UI-Test Cases'!C29:C2239,"<>"&"",'PMS-UI-Test Cases'!I29:I2239,"Fail") -> 1 | P31: =M31-N31-O31 -> 0 | S31: MOSIP-37771 | T31: 17 | U31: 17 | V31: =COUNTIFS('PMS-UI-Test Cases'!G28:G2239,S31,'PMS-UI-Test Cases'!I28:I2239,"<>"&"",'PMS-UI-Test Cases'!O28:O2239,"Fail") -> 0 | W31: 0 | AB31: docker.io/mosipid/credential-service:1.2.2.0
L32: =IFERROR(__xludf.DUMMYFUNCTION("""COMPUTED_VALUE"""),"MOSIP-34645") -> MOSIP-34645 | M32: =COUNTIFS('PMS-UI-Test Cases'!A24:A2905,L32,'PMS-UI-Test Cases'!C24:C2905,"<>"&"") -> 44 | N32: 46 | O32: =COUNTIFS('PMS-UI-Test Cases'!A30:A2240,L32,'PMS-UI-Test Cases'!C30:C2240,"<>"&"",'PMS-UI-Test Cases'!I30:I2240,"Fail") -> 0 | P32: 0 | S32: MOSIP-37875 | T32: 21 | U32: 21 | V32: =COUNTIFS('PMS-UI-Test Cases'!G29:G2240,S32,'PMS-UI-Test Cases'!I29:I2240,"<>"&"",'PMS-UI-Test Cases'!O29:O2240,"Fail") -> 0 | W32: 0 | AB32: docker.io/mosipid/data-share-service:1.2.0.1
L33: =IFERROR(__xludf.DUMMYFUNCTION("""COMPUTED_VALUE"""),"MOSIP-34605") -> MOSIP-34605 | M33: =COUNTIFS('PMS-UI-Test Cases'!A25:A2906,L33,'PMS-UI-Test Cases'!C25:C2906,"<>"&"") -> 91 | N33: =COUNTIFS('PMS-UI-Test Cases'!A26:A2906,L33,'PMS-UI-Test Cases'!C26:C2906,"<>"&"",'PMS-UI-Test Cases'!I26:I2906,"PASS") -> 91 | O33: =COUNTIFS('PMS-UI-Test Cases'!A31:A2241,L33,'PMS-UI-Test Cases'!C31:C2241,"<>"&"",'PMS-UI-Test Cases'!I31:I2241,"Fail") -> 0 | P33: =M33-N33-O33 -> 0 | S33: MOSIP-38045 | T33: 19 | U33: 19 | V33: =COUNTIFS('PMS-UI-Test Cases'!G30:G2241,S33,'PMS-UI-Test Cases'!I30:I2241,"<>"&"",'PMS-UI-Test Cases'!O30:O2241,"Fail") -> 0 | W33: 0 | AB33: docker.io/mosipid/esignet:1.4.1
L34: =IFERROR(__xludf.DUMMYFUNCTION("""COMPUTED_VALUE"""),"MOSIP-34665") -> MOSIP-34665 | M34: =COUNTIFS('PMS-UI-Test Cases'!A26:A2907,L34,'PMS-UI-Test Cases'!C26:C2907,"<>"&"") -> 78 | N34: =COUNTIFS('PMS-UI-Test Cases'!A27:A2907,L34,'PMS-UI-Test Cases'!C27:C2907,"<>"&"",'PMS-UI-Test Cases'!I27:I2907,"PASS") -> 78 | O34: =COUNTIFS('PMS-UI-Test Cases'!A32:A2242,L34,'PMS-UI-Test Cases'!C32:C2242,"<>"&"",'PMS-UI-Test Cases'!I32:I2242,"Fail") -> 0 | P34: =M34-N34-O34 -> 0 | S34: MOSIP-38077 | T34: 20 | U34: 20 | V34: =COUNTIFS('PMS-UI-Test Cases'!G31:G2242,S34,'PMS-UI-Test Cases'!I31:I2242,"<>"&"",'PMS-UI-Test Cases'!O31:O2242,"Fail") -> 0 | W34: 0 | AB34: docker.io/mosipid/hotlist-service:1.2.1.1
L35: =IFERROR(__xludf.DUMMYFUNCTION("""COMPUTED_VALUE"""),"MOSIP-34625") -> MOSIP-34625 | M35: =COUNTIFS('PMS-UI-Test Cases'!A27:A2908,L35,'PMS-UI-Test Cases'!C27:C2908,"<>"&"") -> 72 | N35: =COUNTIFS('PMS-UI-Test Cases'!A28:A2908,L35,'PMS-UI-Test Cases'!C28:C2908,"<>"&"",'PMS-UI-Test Cases'!I28:I2908,"PASS") -> 72 | O35: =COUNTIFS('PMS-UI-Test Cases'!A33:A2243,L35,'PMS-UI-Test Cases'!C33:C2243,"<>"&"",'PMS-UI-Test Cases'!I33:I2243,"Fail") -> 0 | P35: =M35-N35-O35 -> 0 | S35: MOSIP-38092 | T35: 25 | U35: 25 | V35: 0 | W35: 0 | AB35: docker.io/mosipid/id-repository-identity-service:1.2.2.0
L36: =IFERROR(__xludf.DUMMYFUNCTION("""COMPUTED_VALUE"""),"MOSIP-34655") -> MOSIP-34655 | M36: =COUNTIFS('PMS-UI-Test Cases'!A28:A2909,L36,'PMS-UI-Test Cases'!C28:C2909,"<>"&"") -> 40 | N36: =COUNTIFS('PMS-UI-Test Cases'!A29:A2909,L36,'PMS-UI-Test Cases'!C29:C2909,"<>"&"",'PMS-UI-Test Cases'!I29:I2909,"PASS") -> 40 | O36: =COUNTIFS('PMS-UI-Test Cases'!A34:A2244,L36,'PMS-UI-Test Cases'!C34:C2244,"<>"&"",'PMS-UI-Test Cases'!I34:I2244,"Fail") -> 0 | P36: =M36-N36-O36 -> 0 | S36: MOSIP-38201 | T36: 21 | U36: 21 | V36: 0 | W36: 0 | AB36: docker.io/mosipid/id-repository-salt-generator:1.2.0.1
L37: =IFERROR(__xludf.DUMMYFUNCTION("""COMPUTED_VALUE"""),"MOSIP-34957") -> MOSIP-34957 | M37: =COUNTIFS('PMS-UI-Test Cases'!A29:A2910,L37,'PMS-UI-Test Cases'!C29:C2910,"<>"&"") -> 74 | N37: =COUNTIFS('PMS-UI-Test Cases'!A30:A2910,L37,'PMS-UI-Test Cases'!C30:C2910,"<>"&"",'PMS-UI-Test Cases'!I30:I2910,"PASS") -> 74 | O37: =COUNTIFS('PMS-UI-Test Cases'!A35:A2245,L37,'PMS-UI-Test Cases'!C35:C2245,"<>"&"",'PMS-UI-Test Cases'!I35:I2245,"Fail") -> 0 | P37: =M37-N37-O37 -> 0 | S37: MOSIP-38211 | T37: 4 | U37: 4 | V37: 0 | W37: 0 | AB37: docker.io/mosipid/id-repository-vid-service:1.2.2.0
L38: =IFERROR(__xludf.DUMMYFUNCTION("""COMPUTED_VALUE"""),"MOSIP-34967") -> MOSIP-34967 | M38: =COUNTIFS('PMS-UI-Test Cases'!A30:A2911,L38,'PMS-UI-Test Cases'!C30:C2911,"<>"&"") -> 45 | N38: 42 | O38: =COUNTIFS('PMS-UI-Test Cases'!A36:A2246,L38,'PMS-UI-Test Cases'!C36:C2246,"<>"&"",'PMS-UI-Test Cases'!I36:I2246,"Fail") -> 0 | P38: 0 | S38: MOSIP-39833 | T38: 29 | U38: 29 | V38: 0 | W38: 0 | AB38: docker.io/mosipid/kernel-auditmanager-service:1.2.0.1
L39: =IFERROR(__xludf.DUMMYFUNCTION("""COMPUTED_VALUE"""),"MOSIP-34998") -> MOSIP-34998 | M39: =COUNTIFS('PMS-UI-Test Cases'!A31:A2912,L39,'PMS-UI-Test Cases'!C31:C2912,"<>"&"") -> 49 | N39: =COUNTIFS('PMS-UI-Test Cases'!A32:A2912,L39,'PMS-UI-Test Cases'!C32:C2912,"<>"&"",'PMS-UI-Test Cases'!I32:I2912,"PASS") -> 49 | O39: =COUNTIFS('PMS-UI-Test Cases'!A37:A2247,L39,'PMS-UI-Test Cases'!C37:C2247,"<>"&"",'PMS-UI-Test Cases'!I37:I2247,"Fail") -> 0 | P39: =M39-N39-O39 -> 0 | S39: MOSIP-40304 | T39: 24 | U39: 24 | V39: 0 | W39: 0 | AB39: docker.io/mosipid/kernel-auth-service:1.2.0.1
L40: =IFERROR(__xludf.DUMMYFUNCTION("""COMPUTED_VALUE"""),"MOSIP-35028") -> MOSIP-35028 | M40: =COUNTIFS('PMS-UI-Test Cases'!A32:A2913,L40,'PMS-UI-Test Cases'!C32:C2913,"<>"&"") -> 34 | N40: =COUNTIFS('PMS-UI-Test Cases'!A33:A2913,L40,'PMS-UI-Test Cases'!C33:C2913,"<>"&"",'PMS-UI-Test Cases'!I33:I2913,"PASS") -> 34 | O40: =COUNTIFS('PMS-UI-Test Cases'!A38:A2248,L40,'PMS-UI-Test Cases'!C38:C2248,"<>"&"",'PMS-UI-Test Cases'!I38:I2248,"Fail") -> 0 | P40: =M40-N40-O40 -> 0 | S40: MOSIP-40618 | T40: 7 | U40: 7 | V40: 0 | W40: 0 | AB40: docker.io/mosipid/kernel-idgenerator-service:1.2.0.1
L41: =IFERROR(__xludf.DUMMYFUNCTION("""COMPUTED_VALUE"""),"MOSIP-35018") -> MOSIP-35018 | M41: =COUNTIFS('PMS-UI-Test Cases'!A33:A2914,L41,'PMS-UI-Test Cases'!C33:C2914,"<>"&"") -> 23 | N41: =COUNTIFS('PMS-UI-Test Cases'!A34:A2914,L41,'PMS-UI-Test Cases'!C34:C2914,"<>"&"",'PMS-UI-Test Cases'!I34:I2914,"PASS") -> 23 | O41: =COUNTIFS('PMS-UI-Test Cases'!A39:A2249,L41,'PMS-UI-Test Cases'!C39:C2249,"<>"&"",'PMS-UI-Test Cases'!I39:I2249,"Fail") -> 0 | P41: =M41-N41-O41 -> 0 | S41: MOSIP-40957 | T41: 20 | U41: 20 | V41: 0 | W41: 0 | AB41: docker.io/mosipid/kernel-keymanager-service:1.3.0-beta.3
...

Sheet PMS-UI-Test Cases
A1: Story ID | B1: Story Title | C1: TestCase_No | D1: pre requisite | E1: Feature | F1: Scenario | G1: Steps to reproduce | H1: Expected Result | I1: Result | J1: Bug ID | K1: Automated In | L1: Remarks
A2: MOSIP-32692 | B2: Policies : Tabular View of previously requested policies | C2: TC_32692_01 | D2: User uploaded partner certificate. | E2: Reuesting Policy | F2: First time user requesting for policy | G2: 1. Navigate to PMS portal. 2. Navigate "Left navigation" -> click "Policies". 3. Navigate "Policies" options in Home page. | H2: 1.User should be able to view the "Empty table to be displayed". | I2: Pass
A3: MOSIP-32692 | B3: Policies : Tabular View of previously requested policies | C3: TC_32692_02 | D3: Partner shouldn't uploaded the certificate. | E3: Reuesting Policy | F3: First time user requesting for policy | G3: 1. Navigate to PMS portal. 2. Navigate "Left navigation" -> click "Policies". 3. Navigate "Policies" options in Home page. | H3: User should not reuest policy without upload partner certificate. | I3: Pass
A4: MOSIP-32692 | B4: Policies : Tabular View of previously requested policies | C4: TC_32692_03 | D4: Partner shouldn't uploaded the certificate. | E4: Reqesting Policy | F4: Policy is submitted atleast once | G4: 1. Navigate to PMS portal. 2. Navigate "Left navigation" -> click "Policies". 3. Navigate "Policies" options in Home page. | H4: 1.User should be able to view the policies submitted 2."BACK" button enable the view the list of policies 3."Main Title "‘Policies’ to be dislayed 4.Request Policy button positioned towards the extreme right alongside the title. | I4: Pass
A5: MOSIP-32692 | B5: Policies : Tabular View of previously requested policies | C5: TC_32692_04 | D5: User uploaded partner certificate. | E5: Reuesting Policy | F5: Verify that user is able to "Request Policy". | G5: 1. Navigate to PMS portal. 2. Navigate "Left navigation" -> click "Policies". 3. Navigate "Policies" options in Home page. | H5: 1."Request Policy" should be Enabled | I5: Pass
A6: MOSIP-32692 | B6: Policies : Tabular View of previously requested policies | C6: TC_32692_05 | D6: Partner policy mapped | E6: Tabular View | F6: Verify Sub Title - ‘List of Policy Requests’ Feature | G6: 1. Navigate to PMS portal. 2. Navigate "Left navigation" -> click "Policies". 3. Navigate "Policies" options in Home page. | H6: 1.The number displayed in ( ) beside ‘List of policy requests’ denote the total number of records submitted by all users belonging to that respective organisation.(Future will be a multi user functionality. Currently we are testing as a single user) | I6: Pass
A7: MOSIP-32692 | B7: Policies : Tabular View of previously requested policies | C7: TC_32692_06 | D7: Multiple policies mapped | E7: Filter | F7: Check Filter values avliable. | G7: 1. Navigate to PMS portal. 2. Navigate "Left navigation" -> click "Policies". 3. Navigate "Policies" options in Home page. | H7: Filter values should be avliable in each column header. | I7: Pass
A8: MOSIP-32692 | B8: Policies : Tabular View of previously requested policies | C8: TC_32692_07 | D8: Multiple policies mapped | E8: Filter | F8: Try to enter values manulally in Filter values. | G8: 1. Navigate to PMS portal. 2. Navigate "Left navigation" -> click "Policies". 3. Navigate "Policies" options in Home page. | H8: Filter values shhould be dropdown, user should not allow to edit filter values. | I8: Pass
A9: MOSIP-32692 | B9: Policies : Tabular View of previously requested policies | C9: TC_32692_08 | D9: Multiple policies mapped | E9: Filter | F9: Check Filter Button | G9: 1. Navigate to PMS portal. 2. Navigate "Left navigation" -> click "Policies". 3. Navigate "Policies" options in Home page. | H9: 1.Should be expandable and collapsible filter section on consecutive clicks. 2.The expandable section displays filters for the column headers: Partner ID, Partner type, policy group, policy name and status. 3.Each filter box should be a textbox+dropdown and the results should dynamically update based on the inputs provided at the time of typing. 4. Once filtered results are out, user should be able to sort on all the fields .ex.Partner id,Partner type etc | I9: Pass
A10: MOSIP-32693 | B10: Policies : Tabular View of previously requested policies | C10: TC_32692_09 | D10: Multiple policies mapped | E10: Filter | F10: Sort after filtered policies | G10: 1. Navigate to PMS portal. 2. Navigate "Left navigation" -> click "Policies". 3. Navigate "Policies" options in Home page. | H10: sort should work on filtered result. | I10: Pass
A11: MOSIP-32692 | B11: Policies : Tabular View of previously requested policies | C11: TC_32692_10 | D11: Multiple policies mapped | E11: Filter | F11: Check Multi filter search feature | G11: 1. Navigate to PMS portal. 2. Navigate "Left navigation" -> click "Policies". 3. Navigate "Policies" options in Home page. | H11: User should be able to filetrize data by multi filtering. | I11: Pass
A12: MOSIP-32692 | B12: Policies : Tabular View of previously requested policies | C12: TC_32692_11 | D12: Multiple policies mapped | E12: Tabular View | F12: Check the view of the colums displayed | G12: 1. Navigate to PMS portal. 2. Navigate "Left navigation" -> click "Policies". 3. Navigate "Policies" options in Home page. | H12: View to display the following fields 1.Partner ID; Partner Type;Policy Group;Policy Name; Created Date;Status;Action 2.Sort icon is provided across all column headers for sorting in ascending or descending alphabetic order. | I12: Pass
A13: MOSIP-32692 | B13: Policies : Tabular View of previously requested policies | C13: TC_32692_12 | D13: Multiple policies mapped | E13: Status | F13: Check "Action" field | G13: 1. Navigate to PMS portal. 2. Navigate "Left navigation" -> click "Policies". 3. Navigate "Policies" options in Home page. | H13: 1.Action menu has only view option for all statuses. 2. Validate the action status based on the filter applied. | I13: Pass
... A99: MOSIP-33227 | B99: Authentication Services: Edit OIDC Client details | C99: 33227_30 | D99: The OIDC Client in the tabular view should be in Activated status for edit option to be enabled | E99: As a user (partner), on clicking Edit option of OIDC Client in the tabular view screen- I should be able to edit the previously submitted OIDC Client details such as LogoURI and RedirectURI so that the new changes are applied. | F99: Verify the Data validation for the Client Name | G99: 1.Login to PMS portal 2.Navigate to Authentication Services. 3.Navigate to create OIDC client Home page 4.Click on the edit option in the Action Menu for client Name | H99: 1.Data Length should accept only 1-256 characters 2.Should accept only Alphanumeric characters symbols for- space, dot, comma, - , _ , &, ( , ) | I99: Pass
A100: MOSIP-33227 | B100: Authentication Services: Edit OIDC Client details | C100: 33227_31 | D100: The OIDC Client in the tabular view should be in Activated status for edit option to be enabled | E100: As a user (partner), on clicking Edit option of OIDC Client in the tabular view screen- I should be able to edit the previously submitted OIDC Client details such as LogoURI and RedirectURI so that the new changes are applied. | F100: Verify the Data validation for the Client Name on adding only special characters apart from - space, dot, comma, - , _ , &, ( , ) | G100: 1.Login to PMS portal 2.Navigate to Authentication Services. 3.Navigate to create OIDC client Home page 4.Click on the edit option in the Action Menu for client Name adding characters apart from - space, dot, comma, - , _ , &, ( , ) | H100: It should accept alphanumeric characters and symbols- space, dot, comma, - , _ , &, ( , ) and digits | I100: Pass | M100: f
A101: MOSIP-33227 | B101: Authentication Services: Edit OIDC Client details | C101: 33227_32 | D101: The OIDC Client in the tabular view should be in Activated status for edit option to be enabled | E101: As a user (partner), on clicking Edit option of OIDC Client in the tabular view screen- I should be able to edit the previously submitted OIDC Client details such as LogoURI and RedirectURI so that the new changes are applied. | F101: Verify the Data validation for the Client Name with combination of special charcacters - space, dot, comma, - , _ , &, ( , ) and digits | G101: 1.Login to PMS portal 2.Navigate to Authentication Services. 3.Navigate to create OIDC client Home page 4.Click on the edit option in the Action Menu for client Name adding characters - space, dot, comma, - , _ , &, ( , ) and digits | H101: It should accept alphanumeric characters and symbols- space, dot, comma, - , _ , &, ( , ) and digits | I101: Pass
A102: MOSIP-33227 | B102: Authentication Services: Edit OIDC Client details | C102: 33227_33 | D102: The OIDC Client in the tabular view should be in Activated status for edit option to be enabled | E102: As a user (partner), on clicking Edit option of OIDC Client in the tabular view screen- I should be able to edit the previously submitted OIDC Client details such as LogoURI and RedirectURI so that the new changes are applied. | F102: Verify the Data validation for the Client Name with combination of special charcacters other than - space, dot, comma, - , _ , &, ( , ) and digits | G102: 1.Login to PMS portal 2.Navigate to Authentication Services. 3.Navigate to create OIDC client Home page 4.Click on the edit option in the Action Menu for client Name adding characters apart from - space, dot, comma, - , _ , &, ( , ) and digits | H102: It should accept alphanumeric characters and symbols- space, dot, comma, - , _ , &, ( , ) and digits | I102: Pass
A103: MOSIP-33227 | B103: Authentication Services: Edit OIDC Client details | C103: 33227_34 | D103: The OIDC Client in the tabular view should be in Activated status for edit option to be enabled | E103: As a user (partner), on clicking Edit option of OIDC Client in the tabular view screen- I should be able to edit the previously submitted OIDC Client details such as LogoURI and RedirectURI so that the new changes are applied. | F103: Verify the Data validation for the Client Name if exceeds the limit | G103: 1.Login to PMS portal 2.Navigate to Authentication Services. 3.Navigate to create OIDC client Home page 4.Click on the edit option in the Action Menu 5.Edit the client name with more than 256 characters 6.Click on submit | H103: Partner should not be allowed to enter more data beyond the maximum limit | I103: Pass
A104: MOSIP-33227 | B104: Authentication Services: Edit OIDC Client details | C104: 33227_35 | D104: The OIDC Client in the tabular view should be in Activated status for edit option to be enabled | E104: As a user (partner), on clicking Edit option of OIDC Client in the tabular view screen- I should be able to edit the previously submitted OIDC Client details such as LogoURI and RedirectURI so that the new changes are applied. | F104: Verify the Data validation for the Client Name if it is within the given limit | G104: 1.Login to PMS portal 2.Navigate to Authentication Services. 3.Navigate to create OIDC client Home page 4.Click on the edit option in the Action Menu 5.Edit the client name with less than 256 characters 6.Click on submit | H104: User should be able to edit the clients name successfully | I104: Pass
A105: MOSIP-33227 | B105: Authentication Services: Edit OIDC Client details | C105: 33227_36 | D105: The OIDC Client in the tabular view should be in Activated status for edit option to be enabled | E105: As a user (partner), on clicking Edit option of OIDC Client in the tabular view screen- I should be able to edit the previously submitted OIDC Client details such as LogoURI and RedirectURI so that the new changes are applied. | F105: Verify the Data validation for Logo URI | G105: 1.Login to PMS portal 2.Navigate to Authentication Services. 3.Navigate to create OIDC client Home page 4.Click on the edit option in the Action Menu 5.Edit the LogoURI and submit 6.Click on submit | H105: 1.Must be a valid URI format. 2.Should be able to edit the fields appropriately | I105: Pass
A106: MOSIP-33227 | B106: Authentication Services: Edit OIDC Client details | C106: 33227_37 | D106: The OIDC Client in the tabular view should be in Activated status for edit option to be enabled | E106: As a user (partner), on clicking Edit option of OIDC Client in the tabular view screen- I should be able to edit the previously submitted OIDC Client details such as LogoURI and RedirectURI so that the new changes are applied. | F106: Verify the Data validation for Logo URI if it is within the given limit | G106: 1.Login to PMS portal 2.Navigate to Authentication Services. 3.Navigate to create OIDC client Home page 4.Click on the edit option in the Action Menu 5.Edit the LogoURI within 2048 characters and submit 6.Click on submit | H106: Should be able to edit the fields successfully | I106: Pass
A107: MOSIP-33227 | B107: Authentication Services: Edit OIDC Client details | C107: 33227_38 | D107: The OIDC Client in the tabular view should be in Activated status for edit option to be enabled | E107: As a user (partner), on clicking Edit option of OIDC Client in the tabular view screen- I should be able to edit the previously submitted OIDC Client details such as LogoURI and RedirectURI so that the new changes are applied. | F107: Verify the Data validation for Logo URI for the if it is exceeding the given limit | G107: 1.Login to PMS portal 2.Navigate to Authentication Services. 3.Navigate to create OIDC client Home page 4.Click on the edit option in the Action Menu 5.Edit the LogoURI with more than 2048 characters and submit 6.Click on submit | H107: Should throw appropriate error message on tab "should not allow more than 2048 characters" | I107: Pass
A108: MOSIP-33227 | B108: Authentication Services: Edit OIDC Client details | C108: 33227_39 | D108: The OIDC Client in the tabular view should be in Activated status for edit option to be enabled | E108: As a user (partner), on clicking Edit option of OIDC Client in the tabular view screen- I should be able to edit the previously submitted OIDC Client details such as LogoURI and RedirectURI so that the new changes are applied. | F108: Verify the Data validation for Redirect URI | G108: 1.Login to PMS portal 2.Navigate to Authentication Services. 3.Navigate to create OIDC client Home page 4.Click on the edit option in the Action Menu 5.Edit the RedirectURI within 2048 characters and submit 6.Click on submit | H108: Should be able to edit the fields successfully | I108: Pass
A109: MOSIP-33227 | B109: Authentication Services: Edit OIDC Client details | C109: 33227_40 | D109: The OIDC Client in the tabular view should be in Activated status for edit option to be enabled | E109: As a user (partner), on clicking Edit option of OIDC Client in the tabular view screen- I should be able to edit the previously submitted OIDC Client details such as LogoURI and RedirectURI so that the new changes are applied. | F109: Verify the Data validation for Redirect URI if it is exceeding the given limit | G109: 1.Login to PMS portal 2.Navigate to Authentication Services. 3.Navigate to create OIDC client Home page 4.Click on the edit option in the Action Menu 5.Edit the RedirectURI with more than 2048 characters and submit 6.Click on submit | H109: Should throw appropriate error message on tab "should not allow more than 2048 characters" | I109: Pass
A110: MOSIP-33227 | B110: Authentication Services: Edit OIDC Client details | C110: 33227_41 | D110: The OIDC Client in the tabular view should be in Activated status for edit option to be enabled | E110: As a user (partner), on clicking Edit option of OIDC Client in the tabular view screen- I should be able to edit the previously submitted OIDC Client details such as LogoURI and RedirectURI so that the new changes are applied. | F110: Verify Sort Icon for list of OIDC client request | G110: 1.Login to PMS portal 2.Navigate to Authentication Services. 3.Navigate to create OIDC client Home page | H110: Action and OIDC Client ID shouldn't have sort icon | I110: Pass
A111: MOSIP-33207 | B111: Authentication Services: Tabular View of previous submitted OIDC Clients | C111: 33207_01 | D111: 1. User has logged in to PMS portal as Auth partner 2.User had uploaded certificate. 3.User has Requested Policy 4.Policy is approved by admin 5. OIDC request should have been submittted atleast once. | E111: As a user (partner), I should be able to view the tabular list of submitted OIDC Clients along with its details and status so that I can view the OIDC Clients created by my organisation in a sequential order and view the OIDC Client IDs for active records in same screen. | F111: Verify a New User wanting to create OIDC Client for the first time | G111: 1.Login to PMS portal 2.Navigate to Authentication Services. 3.Navigate to create OIDC client Home page | H111: The screen should have the following options under OIDC Client tab: 1. Create OIDC Client button should be placed on the centre of the screen. 2. Columns headers should have : Partner ID,partner type,Policy Group, Policy Name, OIDC Client Name, Created Date, Status, OIDC Client ID, Action | I111: Pass
A112: MOSIP-33207 | B112: Authentication Services: Tabular View of previous submitted OIDC Clients | C112: 33207_02 | D112: 1.User has logged in as Auth partner 2.User has not uploaded certificates | E112: As a user (partner), I should be able to view the tabular list of submitted OIDC Clients along with its details and status so that I can view the OIDC Clients created by my organisation in a sequential order and view the OIDC Client IDs for active records in same screen. | F112: Verify user is able to view the list of OIDC client without uploading partner certificate | G112: 1.Login to PMS portal 2.Navigate to Authentication Services without uploading partner certificate. 3.Navigate to create OIDC client Home page | H112: 1.Partner Id should not display in the dropdown 2.Partner type should not get changed 3.Policy name should not be available either on search or in the dropdown 4.Partner should not be able to create OIDC client 5.Hence should not avail in the list | I112: Pass
... A197: MOSIP-32702 | B197: Request a policy to be assigned to partner ID | C197: TC_32702_15 | D197: 1. Partner certificate should be uploaded before for particular partner. 2. Policy group should be created by admin and mapped to Partner. 3. Policy Names should be created and mapped to Policy group by admin. | E197: As a user (partner), on clicking Request Policy button in Policies screen- I should be able to request for a policy that is applicable to my organisation so that on approval from admin, the policy is assigned to the respective partner ID in order to proceed with authentication services. | F197: Verify the comments text area. | G197: 1. Navigate to PMS portal. 2. Click "Policies" options in Home page. 3. "Request a Policy page" gets displayed. 4. Navigate to "Partner ID" dropdown and select any Partner ID. 5. "Policy Group" gets auto populated based on Partner ID selected by user. 6. Navigate and select "Policy Name" dropdown. 7. Navigate to "Comments" edit box. | H197: 1. Comments text area should be editable. 2. Proper placeholder should be defined for comments edit box - "Mention the purpose of requesting the policy" | I197: Pass
A198: MOSIP-32702 | B198: Request a policy to be assigned to partner ID | C198: TC_32702_16 | E198: As a user (partner), on clicking Request Policy button in Policies screen- I should be able to request for a policy that is applicable to my organisation so that on approval from admin, the policy is assigned to the respective partner ID in order to proceed with authentication services. | F198: Verify "Submit" button is disabled by default. | G198: 1. Navigate to PMS portal. 2. Click "Policies" options in Home page. 3. "Request a Policy page" gets displayed. 4. Navigate to "Submit" button. | H198: Submit button should be disabled by default. | I198: Pass
A199: MOSIP-32702 | B199: Request a policy to be assigned to partner ID | C199: TC_32702_17 | D199: 1. Partner certificate should be uploaded before for particular partner. 2. Policy group should be created by admin and mapped to Partner. 3. Policy Names should be created and mapped to Policy group by admin. | E199: As a user (partner), on clicking Request Policy button in Policies screen- I should be able to request for a policy that is applicable to my organisation so that on approval from admin, the policy is assigned to the respective partner ID in order to proceed with authentication services. | F199: Verify by not selecting all mandatory fields and submitting the request. | G199: 1. Navigate to PMS portal. 2. Click "Policies" options in Home page. 3. "Request a Policy page" gets displayed. 4. Do not select any mandatory field. 5. Navigate and click "Submit" button. | H199: 1. "Submit" button should be disabled. | I199: Pass
A200: MOSIP-32702 | B200: Request a policy to be assigned to partner ID | C200: TC_32702_18 | D200: 1. Partner certificate should be uploaded before for particular partner. 2. Policy group should be created by admin and mapped to Partner. 3. Policy Names should be created and mapped to Policy group by admin. | E200: As a user (partner), on clicking Request Policy button in Policies screen- I should be able to request for a policy that is applicable to my organisation so that on approval from admin, the policy is assigned to the respective partner ID in order to proceed with authentication services. | F200: Verify by selecting all the mandatory fields to request policy. | G200: 1. Navigate to PMS portal. 2. Click "Policies" options in Home page. 3. "Request a Policy page" gets displayed. 4. Navigate to "Partner ID" dropdown and select any Partner ID. 5. "Partner Type" & "Policy Group" gets auto populated based on Partner ID selected by user. 6. Navigate and select "Policy Name" dropdown. 7. Provide comments "Comments". 8. Click on Submit button. | H200: 1. Submit button should be enabled. 2. User should be able to "Request Policy". 3. Success message should be displayed. | I200: Pass
A201: MOSIP-32702 | B201: Request a policy to be assigned to partner ID | C201: TC_32702_19 | D201: 1. Partner certificate should be uploaded before for particular partner. 2. Policy group should be created by admin and mapped to Partner. 3. Policy Names should be created and mapped to Policy group by admin. | E201: As a user (partner), on clicking Request Policy button in Policies screen- I should be able to request for a policy that is applicable to my organisation so that on approval from admin, the policy is assigned to the respective partner ID in order to proceed with authentication services. | F201: Verify the success message after submitting the request. | G201: 1. Navigate to PMS portal. 2. Click "Policies" options in Home page. 3. "Request a Policy page" gets displayed. 4. Navigate to "Partner ID" dropdown and select any Partner ID. 5. "Partner Type" & "Policy Group" gets auto populated based on Partner ID selected by user. 6. Navigate and select "Policy Name" dropdown. 7. Provide comments "Comments". 8. Click on Submit button. | H201: Below content should be displayed for user upon submitting the request, 1. Success Green Color Tick Icon 2. Title of success message: 'Policy Submitted Successfully! 3. Description of success message: Policy request has been successfully submitted. Approval is pending with admin. 4. Go Back button. 5. Home Button. | I201: Pass
A202: MOSIP-32702 | B202: Request a policy to be assigned to partner ID | C202: TC_32702_20 | D202: 1. Partner certificate should be uploaded before for particular partner. 2. Policy group should be created by admin and mapped to Partner. 3. Policy Names should be created and mapped to Policy group by admin. | E202: As a user (partner), on clicking Request Policy button in Policies screen- I should be able to request for a policy that is applicable to my organisation so that on approval from admin, the policy is assigned to the respective partner ID in order to proceed with authentication services. | F202: Verify by not entering comments into the comments edit field. | G202: 1. Navigate to PMS portal. 2. Click "Policies" options in Home page. 3. "Request a Policy page" gets displayed. 4. Navigate to "Partner ID" dropdown and select any Partner ID. 5. "Partner Type" & "Policy Group" gets auto populated based on Partner ID selected by user. 6. Navigate and select "Policy Name" dropdown. 7. Do not provide comments in "Comments" edit field. 8. Click on Submit button. | H202: Submit button should be disabled. | I202: Pass
A203: MOSIP-32702 | B203: Request a policy to be assigned to partner ID | C203: TC_32702_21 | D203: 1. Partner certificate should be uploaded before for particular partner. 2. Policy group should be created by admin and mapped to Partner. 3. Policy Names should be created and mapped to Policy group by admin. | E203: As a user (partner), on clicking Request Policy button in Policies screen- I should be able to request for a policy that is applicable to my organisation so that on approval from admin, the policy is assigned to the respective partner ID in order to proceed with authentication services. | F203: Verify clear button functionality | G203: 1. Navigate to PMS portal. 2. Click "Policies" options in Home page. 3. "Request a Policy page" gets displayed. 4. Navigate to "Partner ID" dropdown and select any Partner ID. 5. "Partner Type" & "Policy Group" gets auto populated based on Partner ID selected by user. 6. Navigate and select "Policy Name" dropdown. 7. Provide comments in "Comments" edit field. 8. Click on clear button. | H203: All the data selected/entered into request policy form should get cleared after invoking "Clear" button. | I203: Pass
A204: MOSIP-32702 | B204: Request a policy to be assigned to partner ID | C204: TC_32702_22 | D204: 1. Partner certificate should be uploaded before for particular partner. 2. Policy group should be created by admin and mapped to Partner. 3. Policy Names should be created and mapped to Policy group by admin. | E204: As a user (partner), on clicking Request Policy button in Policies screen- I should be able to request for a policy that is applicable to my organisation so that on approval from admin, the policy is assigned to the respective partner ID in order to proceed with authentication services. | F204: Verify cancel button functionality | G204: 1. Navigate to PMS portal. 2. Click "Policies" options in Home page. 3. "Request a Policy page" gets displayed. 4. Navigate to "Partner ID" dropdown and select any Partner ID. 5. "Partner Type" & "Policy Group" gets auto populated based on Partner ID selected by user. 6. Navigate and select "Policy Name" dropdown. 7. Provide comments in "Comments" edit field. 8. Click on cancel button. | H204: User should be navigate to tabular view screen after invoking cancel button. | I204: Pass
A205: MOSIP-32702 | B205: Request a policy to be assigned to partner ID | C205: TC_32702_23 | D205: 1. Partner certificate should be uploaded before for particular partner. 2. Policy group should be created by admin and mapped to Partner. 3. Policy Names should be created and mapped to Policy group by admin. | E205: As a user (partner), on clicking Request Policy button in Policies screen- I should be able to request for a policy that is applicable to my organisation so that on approval from admin, the policy is assigned to the respective partner ID in order to proceed with authentication services. | F205: Verify the status is "Pending for approval" after submitting policy request. | G205: 1. Navigate to PMS portal. 2. Click "Policies" options in Home page. 3. "Request a Policy page" gets displayed. 4. Navigate to "Partner ID" dropdown and select any Partner ID. 5. "Partner Type" & "Policy Group" gets auto populated based on Partner ID selected by user. 6. Navigate and select "Policy Name" dropdown. 7. Provide comments in "Comments" edit field. 8. Click on submit button. 9. Navigate to tabular view. | H205: 1. User should be able to submit the request. 2. User should be able to click on "Go back" button. 3. In list of tabular view status should be "Pending for approval" for particular partner ID. | I205: Pass
A206: MOSIP-32702 | B206: Request a policy to be assigned to partner ID | C206: TC_32702_24 | E206: As a user (partner), on clicking Request Policy button in Policies screen- I should be able to request for a policy that is applicable to my organisation so that on approval from admin, the policy is assigned to the respective partner ID in order to proceed with authentication services. | F206: Verify all the mandatory fields are marked with * symbol | G206: 1. Navigate to PMS portal. 2. Click "Policies" options in Home page. 3. "Request a Policy page" gets displayed. | H206: All the mandatory fields should be marked with * symbol | I206: Pass
A207: MOSIP-32702 | B207: Request a policy to be assigned to partner ID | C207: TC_32702_25 | D207: 1. Partner certificate should be uploaded before for particular partner. 2. Policy group should be created by admin and mapped to Partner. 3. Policy Names should be created and mapped to Policy group by admin. | E207: As a user (partner), on clicking Request Policy button in Policies screen- I should be able to request for a policy that is applicable to my organisation so that on approval from admin, the policy is assigned to the respective partner ID in order to proceed with authentication services. | F207: Verify by selecting multiple "Policy Name" at a time from dropdown. | G207: 1. Navigate to PMS portal. 2. Click "Policies" options in Home page. 3. "Request a Policy page" gets displayed. 4. Navigate to "Partner ID" dropdown and select any Partner ID. 5. "Partner Type" & "Policy Group" gets auto populated based on Partner ID selected by user. 6. Navigate and select "Policy Name" dropdown and select multiple items from dropdown. 7. Provide comments in "Comments" edit field. 8. Click on submit button. | H207: 1. User should not be able to select multiple items from dropdown at a time. 2. Submit button should be disabled. | I207: Pass
A208: MOSIP-32702 | B208: Request a policy to be assigned to partner ID | C208: TC_32702_26 | D208: 1. Partner certificate should be uploaded before for particular partner. 2. Policy group should be created by admin and mapped to Partner. 3. Policy Names should be created and mapped to Policy group by admin. | E208: As a user (partner), on clicking Request Policy button in Policies screen- I should be able to request for a policy that is applicable to my organisation so that on approval from admin, the policy is assigned to the respective partner ID in order to proceed with authentication services. | F208: Verify user is able to submit another Policy request | G208: 1. Navigate to PMS portal. 2. Click "Policies" options in Home page. 3. "Request a Policy page" gets displayed. 4. Navigate to "Partner ID" dropdown and select any Partner ID. 5. "Partner Type" & "Policy Group" gets auto populated based on Partner ID selected by user. 6. Navigate and select "Policy Name" dropdown. 7. Provide comments in "Comments" edit field. 8. Click on submit button. 9. Repeat step 4,5,6,7,8 | H208: 1. User should be able to submit another "Policy Request" 2. Success message be displayed. | I208: Pass
A209: MOSIP-32702 | B209: Request a policy to be assigned to partner ID | C209: TC_32702_27 | D209: 1. Partner certificate should be uploaded before for particular partner. 2. Policy group should be created by admin and mapped to Partner. 3. Policy Names should be created and mapped to Policy group by admin. | E209: As a user (partner), on clicking Request Policy button in Policies screen- I should be able to request for a policy that is applicable to my organisation so that on approval from admin, the policy is assigned to the respective partner ID in order to proceed with authentication services. | F209: Verify by submitting (mapping) multiple Policy request for same partner ID | G209: 1. Navigate to PMS portal. 2. Click "Policies" options in Home page. 3. "Request a Policy page" gets displayed. 4. Navigate to "Partner ID" dropdown and select any Partner ID. 5. "Partner Type" & "Policy Group" gets auto populated based on Partner ID selected by user. 6. Navigate and select "Policy Name" dropdown. 7. Provide comments in "Comments" edit field. 8. Click on submit button. 9. Repeat step 4,5,6,7,8 multiple times. | H209: 1. User should be able to submit multiple "Policy Request" for same Partner ID. 2. Success message be displayed. 3. User should be able to view all the Policies in tabular view of policies. | I209: Pass
...

Sheet PMS-API-Test Cases
A1: Story id | B1: Story Title | C1: TestCase_No | D1: pre requisite | E1: Feature | F1: Scenario | G1: Test case step | H1: Expected Result | I1: Test Result | J1: Bug Id | K1: Remarks | L1: Automation | M1: Automation IN
A2: MOSIP-33487 | B2: Get all approved partner ID's which have policy group | C2: TC_01 | E2: Get all approved partner ID's which have policy group | F2: Verify the response without authorization token | G2: 1. Go to parter management swagger 2. Navigate to "Get all approved partner id's with Policy Groups" API 3. Click on Execute | H2: Valid error message should be displayed, { "errorCode": "KER-ATH-401", "message": "Authentication Failed" } | I2: Pass
A3: MOSIP-33487 | B3: Get all approved partner ID's which have policy group | C3: TC_02 | E3: Get all approved partner ID's which have policy group | F3: Verify the response with authorization token | G3: 1. Go to parter management swagger 2. Navigate to "Get all approved partner id's with Policy Groups" API 3. Click on Execute | H3: User should get valid response with status code "OK" | I3: Pass
