Workbook

Sheet Verification - Summary
B2: Details | C2: Stories Tested | D2: Test Cases | K2: API Based Testing | P2: UI Based Testing | V2: Devices Used For Testing | X2: Tested with Components on esqa2 env | Y2: Tested with Components on qa-base env
C3: Total | D3: Total | E3: With Stories | F3: w/o Stories | G3: Pass | H3: Fail | I3: Skip | K3: Story | L3: Test Results | P3: Story | Q3: Test Results | V3: Redmi 6A with Android 9 BLE 4.2 | X3: docker.io/mosipid/captcha-validation-service:0.1.0-beta.1 | Y3: docker.io/mosipid/admin-ui:1.2.0.1
B4: =K2 -> API Based Testing | C4: {=COUNTA(_xludf.UNIQUE(_xlws.FILTER('eSignet API - Test Cases'!A2:A2489, 'eSignet API - Test Cases'!A2:A2489 <> "")))} -> 1 | D4: =COUNTA('eSignet API - Test Cases'!C2:C4506) -> 2192 | E4: =SUM(L4:L19) -> 1537 | F4: =D4-E4 -> 655 | G4: =COUNTIF('eSignet API - Test Cases'!I2:I4506, "Pass") -> 2129 | H4: =COUNTIF('eSignet API - Test Cases'!I2:I4472, "Fail") -> 28 | I4: =D4-G4-H4 -> 35 | K4: =IFERROR(__xludf.DUMMYFUNCTION("UNIQUE(FILTER('eSignet API - Test Cases'!A2:A4491, ('eSignet API - Test Cases'!A2:A4491 <> """")))"),"MOSIP-22715") -> MOSIP-22715 | L4: =COUNTIFS('eSignet API - Test Cases'!A2:A4474,K4,'eSignet API - Test Cases'!C2:C4474,"<>"&"") -> 70 | M4: =COUNTIFS('eSignet API - Test Cases'!A2:A4474,K4,'eSignet API - Test Cases'!C2:C4474,"<>"&"",'eSignet API - Test Cases'!I2:I4474,"Pass") -> 70 | N4: =COUNTIFS('eSignet API - Test Cases'!A2:A4474,K4,'eSignet API - Test Cases'!C2:C4474,"<>"&"",'eSignet API - Test Cases'!I2:I4474,"Fail") -> 0 | O4: =L4-M4-N4 -> 0 | P4: =IFERROR(__xludf.DUMMYFUNCTION("UNIQUE(FILTER('eSignet UI - Test Cases'!A2:A4889, ('eSignet UI - Test Cases'!A2:A4889 <> """")))"),"ES-391") -> ES-391 | Q4: =COUNTIFS('eSignet UI - Test Cases'!A2:A4882,P4,'eSignet UI - Test Cases'!C2:C4882,"<>"&"") -> 144 | R4: =COUNTIFS('eSignet UI - Test Cases'!A2:A4882,P4,'eSignet UI - Test Cases'!C2:C4882,"<>"&"",'eSignet UI - Test Cases'!I2:I4882,"Pass") -> 144 | S4: =COUNTIFS('eSignet UI - Test Cases'!A2:A4882,P4,'eSignet UI - Test Cases'!C2:C4882,"<>"&"",'eSignet UI - Test Cases'!I2:I4882,"Fail") -> 0 | T4: =Q4-R4-S4 -> 0 | V4: redmi 7A with Android BLE 4.2 | X4: docker.io/mosipid/kafka:3.2.1-debian-11-r9 | Y4: docker.io/mosipid/apitest-auth:1.2.1.1-beta.1
B5: =P2 -> UI Based Testing | C5: {=COUNTA(_xludf.UNIQUE(_xlws.FILTER('eSignet UI - Test Cases'!A2:A3880, 'eSignet UI - Test Cases'!A2:A3880 <> "")))} -> 1 | D5: =COUNTA('eSignet UI - Test Cases'!C2:C2882) -> 1251 | E5: =SUM(Q4:Q24) -> 595 | F5: =D5-E5 -> 656 | G5: =COUNTIF('eSignet UI - Test Cases'!I2:I2883, "Pass") -> 1228 | H5: =COUNTIF('eSignet UI - Test Cases'!I2:I2883, "Fail") -> 23 | I5: =D5-G5-H5 -> 0 | K5: =IFERROR(__xludf.DUMMYFUNCTION("""COMPUTED_VALUE"""),"MOSIP-22717") -> MOSIP-22717 | L5: =COUNTIFS('eSignet API - Test Cases'!A3:A4475,K5,'eSignet API - Test Cases'!C3:C4475,"<>"&"") -> 186 | M5: =COUNTIFS('eSignet API - Test Cases'!A3:A4475,K5,'eSignet API - Test Cases'!C3:C4475,"<>"&"",'eSignet API - Test Cases'!I3:I4475,"Pass") -> 186 | N5: =COUNTIFS('eSignet API - Test Cases'!A3:A4475,K5,'eSignet API - Test Cases'!C3:C4475,"<>"&"",'eSignet API - Test Cases'!I3:I4475,"Fail") -> 0 | O5: =L5-M5-N5 -> 0 | P5: =IFERROR(__xludf.DUMMYFUNCTION("""COMPUTED_VALUE"""),"ES-393") -> ES-393 | Q5: =COUNTIFS('eSignet UI - Test Cases'!A3:A4883,P5,'eSignet UI - Test Cases'!C3:C4883,"<>"&"") -> 98 | R5: =COUNTIFS('eSignet UI - Test Cases'!A3:A4883,P5,'eSignet UI - Test Cases'!C3:C4883,"<>"&"",'eSignet UI - Test Cases'!I3:I4883,"Pass") -> 97 | S5: =COUNTIFS('eSignet UI - Test Cases'!A3:A4883,P5,'eSignet UI - Test Cases'!C3:C4883,"<>"&"",'eSignet UI - Test Cases'!I3:I4883,"Fail") -> 1 | T5: =Q5-R5-S5 -> 0 | V5: Redmi note lite with Android BLE 5.0 | X5: docker.io/mosipid/keycloak-init:1.2.0.1 | Y5: docker.io/mosipid/apitest-idrepo:1.2.2.2
K6: =IFERROR(__xludf.DUMMYFUNCTION("""COMPUTED_VALUE"""),"MOSIP-24753") -> MOSIP-24753 | L6: =COUNTIFS('eSignet API - Test Cases'!A4:A4476,K6,'eSignet API - Test Cases'!C4:C4476,"<>"&"") -> 10 | M6: =COUNTIFS('eSignet API - Test Cases'!A4:A4476,K6,'eSignet API - Test Cases'!C4:C4476,"<>"&"",'eSignet API - Test Cases'!I4:I4476,"Pass") -> 10 | N6: =COUNTIFS('eSignet API - Test Cases'!A4:A4476,K6,'eSignet API - Test Cases'!C4:C4476,"<>"&"",'eSignet API - Test Cases'!I4:I4476,"Fail") -> 0 | O6: =L6-M6-N6 -> 0 | P6: =IFERROR(__xludf.DUMMYFUNCTION("""COMPUTED_VALUE"""),"ES-414") -> ES-414 | Q6: =COUNTIFS('eSignet UI - Test Cases'!A4:A4884,P6,'eSignet UI - Test Cases'!C4:C4884,"<>"&"") -> 104 | R6: =COUNTIFS('eSignet UI - Test Cases'!A4:A4884,P6,'eSignet UI - Test Cases'!C4:C4884,"<>"&"",'eSignet UI - Test Cases'!I4:I4884,"Pass") -> 104 | S6: =COUNTIFS('eSignet UI - Test Cases'!A4:A4884,P6,'eSignet UI - Test Cases'!C4:C4884,"<>"&"",'eSignet UI - Test Cases'!I4:I4884,"Fail") -> 0 | T6: =Q6-R6-S6 -> 0 | V6: Vivo Y73 with Android 1BLE 5.0 | X6: docker.io/mosipid/kibana:7.17.2-debian-10-r0 | Y6: docker.io/mosipid/apitest-masterdata:1.2.1.2
B7: Total: | C7: =SUM(C4:C6) -> 2 | D7: =SUM(D4:D6) -> 3443 | E7: =SUM(E4:E6) -> 2132 | F7: =SUM(F4:F6) -> 1311 | G7: =SUM(G4:G6) -> 3357 | H7: =SUM(H4:H6) -> 51 | I7: =SUM(I4:I6) -> 35 | K7: =IFERROR(__xludf.DUMMYFUNCTION("""COMPUTED_VALUE"""),"MOSIP-24923") -> MOSIP-24923 | L7: =COUNTIFS('eSignet API - Test Cases'!A5:A4477,K7,'eSignet API - Test Cases'!C5:C4477,"<>"&"") -> 100 | M7: =COUNTIFS('eSignet API - Test Cases'!A5:A4477,K7,'eSignet API - Test Cases'!C5:C4477,"<>"&"",'eSignet API - Test Cases'!I5:I4477,"Pass") -> 100 | N7: =COUNTIFS('eSignet API - Test Cases'!A5:A4477,K7,'eSignet API - Test Cases'!C5:C4477,"<>"&"",'eSignet API - Test Cases'!I5:I4477,"Fail") -> 0 | O7: =L7-M7-N7 -> 0 | P7: =IFERROR(__xludf.DUMMYFUNCTION("""COMPUTED_VALUE"""),"MOSIP-22717") -> MOSIP-22717 | Q7: =COUNTIFS('eSignet UI - Test Cases'!A5:A4885,P7,'eSignet UI - Test Cases'!C5:C4885,"<>"&"") -> 44 | R7: =COUNTIFS('eSignet UI - Test Cases'!A5:A4885,P7,'eSignet UI - Test Cases'!C5:C4885,"<>"&"",'eSignet UI - Test Cases'!I5:I4885,"Pass") -> 44 | S7: =COUNTIFS('eSignet UI - Test Cases'!A5:A4885,P7,'eSignet UI - Test Cases'!C5:C4885,"<>"&"",'eSignet UI - Test Cases'!I5:I4885,"Fail") -> 0 | T7: =Q7-R7-S7 -> 0 | V7: SS Galaxy A03 core with Android 1BLE 4.2 | X7: docker.io/mosipid/mosip-artemis-keycloak:1.2.0.1 | Y7: docker.io/mosipid/apitest-pms:1.2.2.2
K8: =IFERROR(__xludf.DUMMYFUNCTION("""COMPUTED_VALUE"""),"MOSIP-22705") -> MOSIP-22705 | L8: =COUNTIFS('eSignet API - Test Cases'!A6:A4478,K8,'eSignet API - Test Cases'!C6:C4478,"<>"&"") -> 55 | M8: =COUNTIFS('eSignet API - Test Cases'!A6:A4478,K8,'eSignet API - Test Cases'!C6:C4478,"<>"&"",'eSignet API - Test Cases'!I6:I4478,"Pass") -> 53 | N8: =COUNTIFS('eSignet API - Test Cases'!A6:A4478,K8,'eSignet API - Test Cases'!C6:C4478,"<>"&"",'eSignet API - Test Cases'!I6:I4478,"Fail") -> 2 | P8: =IFERROR(__xludf.DUMMYFUNCTION("""COMPUTED_VALUE"""),"MOSIP-22715") -> MOSIP-22715 | Q8: =COUNTIFS('eSignet UI - Test Cases'!A6:A4886,P8,'eSignet UI - Test Cases'!C6:C4886,"<>"&"") -> 1 | R8: =COUNTIFS('eSignet UI - Test Cases'!A6:A4886,P8,'eSignet UI - Test Cases'!C6:C4886,"<>"&"",'eSignet UI - Test Cases'!I6:I4886,"Pass") -> 1 | S8: =COUNTIFS('eSignet UI - Test Cases'!A6:A4886,P8,'eSignet UI - Test Cases'!C6:C4886,"<>"&"",'eSignet UI - Test Cases'!I6:I4886,"Fail") -> 0 | T8: =Q8-R8-S8 -> 0 | V8: Redmi K20 pro with Android 1BLE 5.0 | X8: docker.io/mosipid/os-shell:12-debian-12-r46 | Y8: docker.io/mosipid/apitest-prereg:1.2.0.2
K9: =IFERROR(__xludf.DUMMYFUNCTION("""COMPUTED_VALUE"""),"MOSIP-22709") -> MOSIP-22709 | L9: =COUNTIFS('eSignet API - Test Cases'!A7:A4479,K9,'eSignet API - Test Cases'!C7:C4479,"<>"&"") -> 18 | M9: =COUNTIFS('eSignet API - Test Cases'!A7:A4479,K9,'eSignet API - Test Cases'!C7:C4479,"<>"&"",'eSignet API - Test Cases'!I7:I4479,"Pass") -> 14 | N9: =COUNTIFS('eSignet API - Test Cases'!A7:A4479,K9,'eSignet API - Test Cases'!C7:C4479,"<>"&"",'eSignet API - Test Cases'!I7:I4479,"Fail") -> 4 | O9: =L9-M9-N9 -> 0 | P9: =IFERROR(__xludf.DUMMYFUNCTION("""COMPUTED_VALUE"""),"MOSIP-24002") -> MOSIP-24002 | Q9: =COUNTIFS('eSignet UI - Test Cases'!A7:A4887,P9,'eSignet UI - Test Cases'!C7:C4887,"<>"&"") -> 14 | R9: =COUNTIFS('eSignet UI - Test Cases'!A7:A4887,P9,'eSignet UI - Test Cases'!C7:C4887,"<>"&"",'eSignet UI - Test Cases'!I7:I4887,"Pass") -> 14 | S9: =COUNTIFS('eSignet UI - Test Cases'!A7:A4887,P9,'eSignet UI - Test Cases'!C7:C4887,"<>"&"",'eSignet UI - Test Cases'!I7:I4887,"Fail") -> 0 | T9: =Q9-R9-S9 -> 0 | V9: iPhone 1with iPhone 1BLE 5.0 | X9: docker.io/mosipid/partner-management-service:1.2.2.2 | Y9: docker.io/mosipid/apitest-resident:1.2.1.2
B10: ="Functional Testing - Stories Verified : " & C7 -> Functional Testing - Stories Verified : 2 | K10: =IFERROR(__xludf.DUMMYFUNCTION("""COMPUTED_VALUE"""),"MOSIP-22731") -> MOSIP-22731 | L10: =COUNTIFS('eSignet API - Test Cases'!A8:A4480,K10,'eSignet API - Test Cases'!C8:C4480,"<>"&"") -> 66 | M10: =COUNTIFS('eSignet API - Test Cases'!A8:A4480,K10,'eSignet API - Test Cases'!C8:C4480,"<>"&"",'eSignet API - Test Cases'!I8:I4480,"Pass") -> 66 | N10: =COUNTIFS('eSignet API - Test Cases'!A8:A4480,K10,'eSignet API - Test Cases'!C8:C4480,"<>"&"",'eSignet API - Test Cases'!I8:I4480,"Fail") -> 0 | O10: =L10-M10-N10 -> 0 | P10: =IFERROR(__xludf.DUMMYFUNCTION("""COMPUTED_VALUE"""),"MOSIP-22719") -> MOSIP-22719 | Q10: =COUNTIFS('eSignet UI - Test Cases'!A8:A4888,P10,'eSignet UI - Test Cases'!C8:C4888,"<>"&"") -> 11 | R10: =COUNTIFS('eSignet UI - Test Cases'!A8:A4888,P10,'eSignet UI - Test Cases'!C8:C4888,"<>"&"",'eSignet UI - Test Cases'!I8:I4888,"Pass") -> 11 | S10: =COUNTIFS('eSignet UI - Test Cases'!A8:A4888,P10,'eSignet UI - Test Cases'!C8:C4888,"<>"&"",'eSignet UI - Test Cases'!I8:I4888,"Fail") -> 0 | T10: =Q10-R10-S10 -> 0 | V10: iPhone with iphone 1BLE 5.0 | X10: docker.io/mosipid/policy-management-service:1.2.2.2 | Y10: docker.io/mosipid/artifactory-server:1.2.0.2
B11: ="Test cases : " & D7 & " Passed : "& G7 & " Failed : " & H7 & " Skipped : " & I7 -> Test cases : 3443 Passed : 3357 Failed : 51 Skipped : 35 | K11: =IFERROR(__xludf.DUMMYFUNCTION("""COMPUTED_VALUE"""),"MOSIP-24755") -> MOSIP-24755 | L11: =COUNTIFS('eSignet API - Test Cases'!A9:A4481,K11,'eSignet API - Test Cases'!C9:C4481,"<>"&"") -> 157 | M11: =COUNTIFS('eSignet API - Test Cases'!A9:A4481,K11,'eSignet API - Test Cases'!C9:C4481,"<>"&"",'eSignet API - Test Cases'!I9:I4481,"Pass") -> 157 | N11: =COUNTIFS('eSignet API - Test Cases'!A9:A4481,K11,'eSignet API - Test Cases'!C9:C4481,"<>"&"",'eSignet API - Test Cases'!I9:I4481,"Fail") -> 0 | O11: =L11-M11-N11 -> 0 | P11: =IFERROR(__xludf.DUMMYFUNCTION("""COMPUTED_VALUE"""),"MOSIP-22718") -> MOSIP-22718 | Q11: =COUNTIFS('eSignet UI - Test Cases'!A9:A4889,P11,'eSignet UI - Test Cases'!C9:C4889,"<>"&"") -> 29 | R11: =COUNTIFS('eSignet UI - Test Cases'!A9:A4889,P11,'eSignet UI - Test Cases'!C9:C4889,"<>"&"",'eSignet UI - Test Cases'!I9:I4889,"Pass") -> 29 | S11: =COUNTIFS('eSignet UI - Test Cases'!A9:A4889,P11,'eSignet UI - Test Cases'!C9:C4889,"<>"&"",'eSignet UI - Test Cases'!I9:I4889,"Fail") -> 0 | T11: =Q11-R11-S11 -> 0 | V11: iPhone with iphone 15.BLE 4.2 | X11: docker.io/mosipid/postgresql:14.2.0-debian-10-r70 | Y11: docker.io/mosipid/artifactory-server:1.3.0-beta.1
B12: ="Test Rate : " & INT((((G7+H7)/D7)*100)) & "% With Pass Rate : " & INT((G7/(G7+H7))*100) & "%" -> Test Rate : 98% With Pass Rate : 98% | K12: =IFERROR(__xludf.DUMMYFUNCTION("""COMPUTED_VALUE"""),"ES-3") -> ES-3 | L12: =COUNTIFS('eSignet API - Test Cases'!A10:A4482,K12,'eSignet API - Test Cases'!C10:C4482,"<>"&"") -> 32 | M12: =COUNTIFS('eSignet API - Test Cases'!A10:A4482,K12,'eSignet API - Test Cases'!C10:C4482,"<>"&"",'eSignet API - Test Cases'!I10:I4482,"Pass") -> 32 | N12: =COUNTIFS('eSignet API - Test Cases'!A10:A4482,K12,'eSignet API - Test Cases'!C10:C4482,"<>"&"",'eSignet API - Test Cases'!I10:I4482,"Fail") -> 0 | O12: =L12-M12-N12 -> 0 | P12: =IFERROR(__xludf.DUMMYFUNCTION("""COMPUTED_VALUE"""),"Multiple IDP Instance") -> Multiple IDP Instance | Q12: =COUNTIFS('eSignet UI - Test Cases'!A10:A4890,P12,'eSignet UI - Test Cases'!C10:C4890,"<>"&"") -> 16 | R12: =COUNTIFS('eSignet UI - Test Cases'!A10:A4890,P12,'eSignet UI - Test Cases'!C10:C4890,"<>"&"",'eSignet UI - Test Cases'!I10:I4890,"Pass") -> 16 | S12: =COUNTIFS('eSignet UI - Test Cases'!A10:A4890,P12,'eSignet UI - Test Cases'!C10:C4890,"<>"&"",'eSignet UI - Test Cases'!I10:I4890,"Fail") -> 0 | T12: =Q12-R12-S12 -> 0 | X12: docker.io/mosipid/postgresql:16.0.0-debian-11-r13 | Y12: docker.io/mosipid/artifactory-server:1.4.1-ES
K13: =IFERROR(__xludf.DUMMYFUNCTION("""COMPUTED_VALUE"""),"ES-34") -> ES-34 | L13: =COUNTIFS('eSignet API - Test Cases'!A11:A4483,K13,'eSignet API - Test Cases'!C11:C4483,"<>"&"") -> 28 | M13: =COUNTIFS('eSignet API - Test Cases'!A11:A4483,K13,'eSignet API - Test Cases'!C11:C4483,"<>"&"",'eSignet API - Test Cases'!I11:I4483,"Pass") -> 28 | N13: =COUNTIFS('eSignet API - Test Cases'!A11:A4483,K13,'eSignet API - Test Cases'!C11:C4483,"<>"&"",'eSignet API - Test Cases'!I11:I4483,"Fail") -> 0 | O13: =L13-M13-N13 -> 0 | P13: =IFERROR(__xludf.DUMMYFUNCTION("""COMPUTED_VALUE"""),"IDP Cross browser Testing") -> IDP Cross browser Testing | Q13: =COUNTIFS('eSignet UI - Test Cases'!A11:A4891,P13,'eSignet UI - Test Cases'!C11:C4891,"<>"&"") -> 1 | R13: =COUNTIFS('eSignet UI - Test Cases'!A11:A4891,P13,'eSignet UI - Test Cases'!C11:C4891,"<>"&"",'eSignet UI - Test Cases'!I11:I4891,"Pass") -> 1 | S13: =COUNTIFS('eSignet UI - Test Cases'!A11:A4891,P13,'eSignet UI - Test Cases'!C11:C4891,"<>"&"",'eSignet UI - Test Cases'!I11:I4891,"Fail") -> 0 | T13: =Q13-R13-S13 -> 0 | X13: docker.io/mosipid/redis:7.0.5-debian-11-r25 | Y13: docker.io/mosipid/biosdk-server:1.2.0.1
K14: =IFERROR(__xludf.DUMMYFUNCTION("""COMPUTED_VALUE"""),"ES-35") -> ES-35 | L14: =COUNTIFS('eSignet API - Test Cases'!A12:A4484,K14,'eSignet API - Test Cases'!C12:C4484,"<>"&"") -> 15 | M14: =COUNTIFS('eSignet API - Test Cases'!A12:A4484,K14,'eSignet API - Test Cases'!C12:C4484,"<>"&"",'eSignet API - Test Cases'!I12:I4484,"Pass") -> 15 | N14: =COUNTIFS('eSignet API - Test Cases'!A12:A4484,K14,'eSignet API - Test Cases'!C12:C4484,"<>"&"",'eSignet API - Test Cases'!I12:I4484,"Fail") -> 0 | O14: =L14-M14-N14 -> 0 | P14: =IFERROR(__xludf.DUMMYFUNCTION("""COMPUTED_VALUE"""),"MOSIP-24755") -> MOSIP-24755 | Q14: =COUNTIFS('eSignet UI - Test Cases'!A12:A4892,P14,'eSignet UI - Test Cases'!C12:C4892,"<>"&"") -> 26 | R14: =COUNTIFS('eSignet UI - Test Cases'!A12:A4892,P14,'eSignet UI - Test Cases'!C12:C4892,"<>"&"",'eSignet UI - Test Cases'!I12:I4892,"Pass") -> 26 | S14: =COUNTIFS('eSignet UI - Test Cases'!A12:A4892,P14,'eSignet UI - Test Cases'!C12:C4892,"<>"&"",'eSignet UI - Test Cases'!I12:I4892,"Fail") -> 0 | T14: =Q14-R14-S14 -> 0 | X14: docker.io/mosipid/softhsm:v2 | Y14: docker.io/mosipid/commons-packet-service:1.2.0.3
K15: =IFERROR(__xludf.DUMMYFUNCTION("""COMPUTED_VALUE"""),"ES-491") -> ES-491 | L15: =COUNTIFS('eSignet API - Test Cases'!A13:A4485,K15,'eSignet API - Test Cases'!C13:C4485,"<>"&"") -> 558 | M15: =COUNTIFS('eSignet API - Test Cases'!A13:A4485,K15,'eSignet API - Test Cases'!C13:C4485,"<>"&"",'eSignet API - Test Cases'!I13:I4485,"Pass") -> 551 | N15: =COUNTIFS('eSignet API - Test Cases'!A13:A4485,K15,'eSignet API - Test Cases'!C13:C4485,"<>"&"",'eSignet API - Test Cases'!I13:I4485,"Fail") -> 7 | O15: =L15-M15-N15 -> 0 | P15: =IFERROR(__xludf.DUMMYFUNCTION("""COMPUTED_VALUE"""),"MOSIP-25869") -> MOSIP-25869 | Q15: =COUNTIFS('eSignet UI - Test Cases'!A13:A4893,P15,'eSignet UI - Test Cases'!C13:C4893,"<>"&"") -> 10 | R15: =COUNTIFS('eSignet UI - Test Cases'!A13:A4893,P15,'eSignet UI - Test Cases'!C13:C4893,"<>"&"",'eSignet UI - Test Cases'!I13:I4893,"Pass") -> 10 | S15: =COUNTIFS('eSignet UI - Test Cases'!A13:A4893,P15,'eSignet UI - Test Cases'!C13:C4893,"<>"&"",'eSignet UI - Test Cases'!I13:I4893,"Fail") -> 0 | T15: =Q15-R15-S15 -> 0 | X15: docker.io/mosipid/zookeeper:3.8.0-debian-11-r30 | Y15: docker.io/mosipid/config-server:1.1.2
K16: =IFERROR(__xludf.DUMMYFUNCTION("""COMPUTED_VALUE"""),"ES-496") -> ES-496 | L16: =COUNTIFS('eSignet API - Test Cases'!A14:A4486,K16,'eSignet API - Test Cases'!C14:C4486,"<>"&"") -> 112 | M16: =COUNTIFS('eSignet API - Test Cases'!A14:A4486,K16,'eSignet API - Test Cases'!C14:C4486,"<>"&"",'eSignet API - Test Cases'!I14:I4486,"Pass") -> 112 | N16: =COUNTIFS('eSignet API - Test Cases'!A14:A4486,K16,'eSignet API - Test Cases'!C14:C4486,"<>"&"",'eSignet API - Test Cases'!I14:I4486,"Fail") -> 0 | O16: =L16-M16-N16 -> 0 | P16: =IFERROR(__xludf.DUMMYFUNCTION("""COMPUTED_VALUE"""),"MOSIP-24813") -> MOSIP-24813 | Q16: =COUNTIFS('eSignet UI - Test Cases'!A14:A4894,P16,'eSignet UI - Test Cases'!C14:C4894,"<>"&"") -> 20 | R16: =COUNTIFS('eSignet UI - Test Cases'!A14:A4894,P16,'eSignet UI - Test Cases'!C14:C4894,"<>"&"",'eSignet UI - Test Cases'!I14:I4894,"Pass") -> 20 | S16: =COUNTIFS('eSignet UI - Test Cases'!A14:A4894,P16,'eSignet UI - Test Cases'!C14:C4894,"<>"&"",'eSignet UI - Test Cases'!I14:I4894,"Fail") -> 0 | T16: =Q16-R16-S16 -> 0 | X16: docker.io/mosipint/elasticsearch:7.17.2-debian-10-r4 | Y16: docker.io/mosipid/consolidator-websub-service:1.2.0.1
K17: =IFERROR(__xludf.DUMMYFUNCTION("""COMPUTED_VALUE"""),"MOSIP-22732") -> MOSIP-22732 | L17: =COUNTIFS('eSignet API - Test Cases'!A15:A4487,K17,'eSignet API - Test Cases'!C15:C4487,"<>"&"") -> 26 | M17: =COUNTIFS('eSignet API - Test Cases'!A15:A4487,K17,'eSignet API - Test Cases'!C15:C4487,"<>"&"",'eSignet API - Test Cases'!I15:I4487,"Pass") -> 26 | N17: =COUNTIFS('eSignet API - Test Cases'!A15:A4487,K17,'eSignet API - Test Cases'!C15:C4487,"<>"&"",'eSignet API - Test Cases'!I15:I4487,"Fail") -> 0 | O17: =L17-M17-N17 -> 0 | P17: =IFERROR(__xludf.DUMMYFUNCTION("""COMPUTED_VALUE"""),"MOSIP-25868") -> MOSIP-25868 | Q17: =COUNTIFS('eSignet UI - Test Cases'!A15:A4895,P17,'eSignet UI - Test Cases'!C15:C4895,"<>"&"") -> 6 | R17: =COUNTIFS('eSignet UI - Test Cases'!A15:A4895,P17,'eSignet UI - Test Cases'!C15:C4895,"<>"&"",'eSignet UI - Test Cases'!I15:I4895,"Pass") -> 6 | S17: =COUNTIFS('eSignet UI - Test Cases'!A15:A4895,P17,'eSignet UI - Test Cases'!C15:C4895,"<>"&"",'eSignet UI - Test Cases'!I15:I4895,"Fail") -> 0 | T17: =Q17-R17-S17 -> 0 | X17: docker.io/mosipqa/apitest-esignet-signup:1.3.x | Y17: docker.io/mosipid/data-share-service:1.2.0.1
K18: =IFERROR(__xludf.DUMMYFUNCTION("""COMPUTED_VALUE"""),"ES-186") -> ES-186 | L18: =COUNTIFS('eSignet API - Test Cases'!A16:A4488,K18,'eSignet API - Test Cases'!C16:C4488,"<>"&"") -> 66 | M18: =COUNTIFS('eSignet API - Test Cases'!A16:A4488,K18,'eSignet API - Test Cases'!C16:C4488,"<>"&"",'eSignet API - Test Cases'!I16:I4488,"Pass") -> 66 | N18: =COUNTIFS('eSignet API - Test Cases'!A16:A4488,K18,'eSignet API - Test Cases'!C16:C4488,"<>"&"",'eSignet API - Test Cases'!I16:I4488,"Fail") -> 0 | O18: =L18-M18-N18 -> 0 | P18: =IFERROR(__xludf.DUMMYFUNCTION("""COMPUTED_VALUE"""),"ES-3") -> ES-3 | Q18: =COUNTIFS('eSignet UI - Test Cases'!A16:A4896,P18,'eSignet UI - Test Cases'!C16:C4896,"<>"&"") -> 12 | R18: =COUNTIFS('eSignet UI - Test Cases'!A16:A4896,P18,'eSignet UI - Test Cases'!C16:C4896,"<>"&"",'eSignet UI - Test Cases'!I16:I4896,"Pass") -> 12 | S18: =COUNTIFS('eSignet UI - Test Cases'!A16:A4896,P18,'eSignet UI - Test Cases'!C16:C4896,"<>"&"",'eSignet UI - Test Cases'!I16:I4896,"Fail") -> 0 | T18: =Q18-R18-S18 -> 0 | X18: docker.io/mosipqa/apitest-esignet:1.7.x | Y18: docker.io/mosipid/data-share-service:1.3.0-beta.2
K19: =IFERROR(__xludf.DUMMYFUNCTION("""COMPUTED_VALUE"""),"ES-1053") -> ES-1053 | L19: =COUNTIFS('eSignet API - Test Cases'!A17:A4489,K19,'eSignet API - Test Cases'!C17:C4489,"<>"&"") -> 38 | M19: =COUNTIFS('eSignet API - Test Cases'!A17:A4489,K19,'eSignet API - Test Cases'!C17:C4489,"<>"&"",'eSignet API - Test Cases'!I17:I4489,"Pass") -> 38 | N19: =COUNTIFS('eSignet API - Test Cases'!A17:A4489,K19,'eSignet API - Test Cases'!C17:C4489,"<>"&"",'eSignet API - Test Cases'!I17:I4489,"Fail") -> 0 | O19: =L19-M19-N19 -> 0 | P19: =IFERROR(__xludf.DUMMYFUNCTION("""COMPUTED_VALUE"""),"ES-92") -> ES-92 | Q19: =COUNTIFS('eSignet UI - Test Cases'!A17:A4897,P19,'eSignet UI - Test Cases'!C17:C4897,"<>"&"") -> 22 | R19: =COUNTIFS('eSignet UI - Test Cases'!A17:A4897,P19,'eSignet UI - Test Cases'!C17:C4897,"<>"&"",'eSignet UI - Test Cases'!I17:I4897,"Pass") -> 22 | S19: =COUNTIFS('eSignet UI - Test Cases'!A17:A4897,P19,'eSignet UI - Test Cases'!C17:C4897,"<>"&"",'eSignet UI - Test Cases'!I17:I4897,"Fail") -> 0 | T19: =Q19-R19-S19 -> 0 | X19: docker.io/mosipqa/config-server:1.1.2 | Y19: docker.io/mosipid/digital-card-service:1.2.0.1
K20: =IFERROR(__xludf.DUMMYFUNCTION("""COMPUTED_VALUE"""),"ES-1043") -> ES-1043 | L20: =COUNTIFS('eSignet API - Test Cases'!A18:A4490,K20,'eSignet API - Test Cases'!C18:C4490,"<>"&"") -> 41 | M20: =COUNTIFS('eSignet API - Test Cases'!A18:A4490,K20,'eSignet API - Test Cases'!C18:C4490,"<>"&"",'eSignet API - Test Cases'!I18:I4490,"Pass") -> 41 | N20: =COUNTIFS('eSignet API - Test Cases'!A18:A4490,K20,'eSignet API - Test Cases'!C18:C4490,"<>"&"",'eSignet API - Test Cases'!I18:I4490,"Fail") -> 0 | O20: =L20-M20-N20 -> 0 | P20: =IFERROR(__xludf.DUMMYFUNCTION("""COMPUTED_VALUE"""),"ES-36") -> ES-36 | Q20: =COUNTIFS('eSignet UI - Test Cases'!A18:A4898,P20,'eSignet UI - Test Cases'!C18:C4898,"<>"&"") -> 4 | R20: =COUNTIFS('eSignet UI - Test Cases'!A18:A4898,P20,'eSignet UI - Test Cases'!C18:C4898,"<>"&"",'eSignet UI - Test Cases'!I18:I4898,"Pass") -> 4 | S20: =COUNTIFS('eSignet UI - Test Cases'!A18:A4898,P20,'eSignet UI - Test Cases'!C18:C4898,"<>"&"",'eSignet UI - Test Cases'!I18:I4898,"Fail") -> 0 | T20: =Q20-R20-S20 -> 0 | X20: docker.io/mosipqa/esignet-with-plugins:1.7.x | Y20: docker.io/mosipid/dsl-orchestrator:1.2.1.0
K21: =IFERROR(__xludf.DUMMYFUNCTION("""COMPUTED_VALUE"""),"ES-1066") -> ES-1066 | L21: =COUNTIFS('eSignet API - Test Cases'!A19:A4491,K21,'eSignet API - Test Cases'!C19:C4491,"<>"&"") -> 82 | M21: =COUNTIFS('eSignet API - Test Cases'!A19:A4491,K21,'eSignet API - Test Cases'!C19:C4491,"<>"&"",'eSignet API - Test Cases'!I19:I4491,"Pass") -> 59 | N21: =COUNTIFS('eSignet API - Test Cases'!A19:A4491,K21,'eSignet API - Test Cases'!C19:C4491,"<>"&"",'eSignet API - Test Cases'!I19:I4491,"Fail") -> 1 | O21: =L21-M21-N21 -> 22 | P21: =IFERROR(__xludf.DUMMYFUNCTION("""COMPUTED_VALUE"""),"ES-97") -> ES-97 | Q21: =COUNTIFS('eSignet UI - Test Cases'!A19:A4899,P21,'eSignet UI - Test Cases'!C19:C4899,"<>"&"") -> 19 | R21: =COUNTIFS('eSignet UI - Test Cases'!A19:A4899,P21,'eSignet UI - Test Cases'!C19:C4899,"<>"&"",'eSignet UI - Test Cases'!I19:I4899,"Pass") -> 19 | S21: =COUNTIFS('eSignet UI - Test Cases'!A19:A4899,P21,'eSignet UI - Test Cases'!C19:C4899,"<>"&"",'eSignet UI - Test Cases'!I19:I4899,"Fail") -> 0 | T21: =Q21-R21-S21 -> 0 | X21: docker.io/mosipqa/keycloak-init:develop | Y21: docker.io/mosipid/dsl-packetcreator:1.2.0.1
K22: =IFERROR(__xludf.DUMMYFUNCTION("""COMPUTED_VALUE"""),"ES-1373") -> ES-1373 | L22: =COUNTIFS('eSignet API - Test Cases'!A20:A4492,K22,'eSignet API - Test Cases'!C20:C4492,"<>"&"") -> 25 | M22: =COUNTIFS('eSignet API - Test Cases'!A20:A4492,K22,'eSignet API - Test Cases'!C20:C4492,"<>"&"",'eSignet API - Test Cases'!I20:I4492,"Pass") -> 23 | N22: =COUNTIFS('eSignet API - Test Cases'!A20:A4492,K22,'eSignet API - Test Cases'!C20:C4492,"<>"&"",'eSignet API - Test Cases'!I20:I4492,"Fail") -> 1 | O22: =L22-M22-N22 -> 1 | P22: =IFERROR(__xludf.DUMMYFUNCTION("""COMPUTED_VALUE"""),"ES-124") -> ES-124 | Q22: =COUNTIFS('eSignet UI - Test Cases'!A20:A4900,P22,'eSignet UI - Test Cases'!C20:C4900,"<>"&"") -> 6 | R22: =COUNTIFS('eSignet UI - Test Cases'!A20:A4900,P22,'eSignet UI - Test Cases'!C20:C4900,"<>"&"",'eSignet UI - Test Cases'!I20:I4900,"Pass") -> 6 | S22: =COUNTIFS('eSignet UI - Test Cases'!A20:A4900,P22,'eSignet UI - Test Cases'!C20:C4900,"<>"&"",'eSignet UI - Test Cases'!I20:I4900,"Fail") -> 0 | T22: =Q22-R22-S22 -> 0 | X22: docker.io/mosipqa/mock-identity-system:0.12.x | Y22: docker.io/mosipid/dsl-packetcreator:1.2.1.0
K23: =IFERROR(__xludf.DUMMYFUNCTION("""COMPUTED_VALUE"""),"ES-1065") -> ES-1065 | L23: =COUNTIFS('eSignet API - Test Cases'!A21:A4493,K23,'eSignet API - Test Cases'!C21:C4493,"<>"&"") -> 61 | M23: =COUNTIFS('eSignet API - Test Cases'!A21:A4493,K23,'eSignet API - Test Cases'!C21:C4493,"<>"&"",'eSignet API - Test Cases'!I21:I4493,"Pass") -> 59 | N23: =COUNTIFS('eSignet API - Test Cases'!A21:A4493,K23,'eSignet API - Test Cases'!C21:C4493,"<>"&"",'eSignet API - Test Cases'!I21:I4493,"Fail") -> 0 | O23: =L23-M23-N23 -> 2 | P23: =IFERROR(__xludf.DUMMYFUNCTION("""COMPUTED_VALUE"""),"MOSIP-26238") -> MOSIP-26238 | Q23: =COUNTIFS('eSignet UI - Test Cases'!A21:A4901,P23,'eSignet UI - Test Cases'!C21:C4901,"<>"&"") -> 5 | R23: =COUNTIFS('eSignet UI - Test Cases'!A21:A4901,P23,'eSignet UI - Test Cases'!C21:C4901,"<>"&"",'eSignet UI - Test Cases'!I21:I4901,"Pass") -> 5 | S23: =COUNTIFS('eSignet UI - Test Cases'!A21:A4901,P23,'eSignet UI - Test Cases'!C21:C4901,"<>"&"",'eSignet UI - Test Cases'!I21:I4901,"Fail") -> 0 | T23: =Q23-R23-S23 -> 0 | X23: docker.io/mosipqa/mock-relying-party-service:0.12.x | Y23: docker.io/mosipid/esignet:1.4.1
K24: =IFERROR(__xludf.DUMMYFUNCTION("""COMPUTED_VALUE"""),"ES-1784") -> ES-1784 | L24: =COUNTIFS('eSignet API - Test Cases'!A22:A4494,K24,'eSignet API - Test Cases'!C22:C4494,"<>"&"") -> 67 | M24: =COUNTIFS('eSignet API - Test Cases'!A22:A4494,K24,'eSignet API - Test Cases'!C22:C4494,"<>"&"",'eSignet API - Test Cases'!I22:I4494,"Pass") -> 67 | N24: =COUNTIFS('eSignet API - Test Cases'!A22:A4494,K24,'eSignet API - Test Cases'!C22:C4494,"<>"&"",'eSignet API - Test Cases'!I22:I4494,"Fail") -> 0 | O24: =L24-M24-N24 -> 0 | P24: =IFERROR(__xludf.DUMMYFUNCTION("""COMPUTED_VALUE"""),"ES-35") -> ES-35 | Q24: =COUNTIFS('eSignet UI - Test Cases'!A22:A4902,P24,'eSignet UI - Test Cases'!C22:C4902,"<>"&"") -> 3 | R24: =COUNTIFS('eSignet UI - Test Cases'!A22:A4902,P24,'eSignet UI - Test Cases'!C22:C4902,"<>"&"",'eSignet UI - Test Cases'!I22:I4902,"Pass") -> 3 | S24: =COUNTIFS('eSignet UI - Test Cases'!A22:A4902,P24,'eSignet UI - Test Cases'!C22:C4902,"<>"&"",'eSignet UI - Test Cases'!I22:I4902,"Fail") -> 0 | T24: =Q24-R24-S24 -> 0 | X24: docker.io/mosipqa/mock-relying-party-ui:0.12.x | Y24: docker.io/mosipid/kernel-auditmanager-service:1.2.0.1
K25: =IFERROR(__xludf.DUMMYFUNCTION("""COMPUTED_VALUE"""),"ES-1794") -> ES-1794 | L25: =COUNTIFS('eSignet API - Test Cases'!A23:A4495,K25,'eSignet API - Test Cases'!C23:C4495,"<>"&"") -> 16 | M25: =COUNTIFS('eSignet API - Test Cases'!A23:A4495,K25,'eSignet API - Test Cases'!C23:C4495,"<>"&"",'eSignet API - Test Cases'!I23:I4495,"Pass") -> 15 | N25: =COUNTIFS('eSignet API - Test Cases'!A23:A4495,K25,'eSignet API - Test Cases'!C23:C4495,"<>"&"",'eSignet API - Test Cases'!I23:I4495,"Fail") -> 0 | O25: =L25-M25-N25 -> 1 | P25: =IFERROR(__xludf.DUMMYFUNCTION("""COMPUTED_VALUE"""),"ES-206") -> ES-206 | Q25: =COUNTIFS('eSignet UI - Test Cases'!A23:A4903,P25,'eSignet UI - Test Cases'!C23:C4903,"<>"&"") -> 16 | R25: =COUNTIFS('eSignet UI - Test Cases'!A23:A4903,P25,'eSignet UI - Test Cases'!C23:C4903,"<>"&"",'eSignet UI - Test Cases'!I23:I4903,"Pass") -> 16 | S25: =COUNTIFS('eSignet UI - Test Cases'!A23:A4903,P25,'eSignet UI - Test Cases'!C23:C4903,"<>"&"",'eSignet UI - Test Cases'!I23:I4903,"Fail") -> 0 | T25: =Q25-R25-S25 -> 0 | X25: docker.io/mosipqa/oidc-ui:1.7.x | Y25: docker.io/mosipid/kernel-auth-service:1.2.0.1
K26: =IFERROR(__xludf.DUMMYFUNCTION("""COMPUTED_VALUE"""),"ES-1064") -> ES-1064 | L26: =COUNTIFS('eSignet API - Test Cases'!A24:A4496,K26,'eSignet API - Test Cases'!C24:C4496,"<>"&"") -> 51 | M26: =COUNTIFS('eSignet API - Test Cases'!A24:A4496,K26,'eSignet API - Test Cases'!C24:C4496,"<>"&"",'eSignet API - Test Cases'!I24:I4496,"Pass") -> 51 | N26: =COUNTIFS('eSignet API - Test Cases'!A24:A4496,K26,'eSignet API - Test Cases'!C24:C4496,"<>"&"",'eSignet API - Test Cases'!I24:I4496,"Fail") -> 0 | P26: =IFERROR(__xludf.DUMMYFUNCTION("""COMPUTED_VALUE"""),"ES-21") -> ES-21 | Q26: =COUNTIFS('eSignet UI - Test Cases'!A24:A4904,P26,'eSignet UI - Test Cases'!C24:C4904,"<>"&"") -> 4 | R26: =COUNTIFS('eSignet UI - Test Cases'!A24:A4904,P26,'eSignet UI - Test Cases'!C24:C4904,"<>"&"",'eSignet UI - Test Cases'!I24:I4904,"Pass") -> 4 | S26: =COUNTIFS('eSignet UI - Test Cases'!A24:A4904,P26,'eSignet UI - Test Cases'!C24:C4904,"<>"&"",'eSignet UI - Test Cases'!I24:I4904,"Fail") -> 0 | T26: =Q26-R26-S26 -> 0 | X26: docker.io/mosipqa/postgres-init:develop | Y26: docker.io/mosipid/kernel-idgenerator-service:1.2.0.1
K27: =IFERROR(__xludf.DUMMYFUNCTION("""COMPUTED_VALUE"""),"ES-1033") -> ES-1033 | L27: =COUNTIFS('eSignet API - Test Cases'!A25:A4497,K27,'eSignet API - Test Cases'!C25:C4497,"<>"&"") -> 53 | M27: =COUNTIFS('eSignet API - Test Cases'!A25:A4497,K27,'eSignet API - Test Cases'!C25:C4497,"<>"&"",'eSignet API - Test Cases'!I25:I4497,"Pass") -> 52 | N27: =COUNTIFS('eSignet API - Test Cases'!A25:A4497,K27,'eSignet API - Test Cases'!C25:C4497,"<>"&"",'eSignet API - Test Cases'!I25:I4497,"Fail") -> 1 | O27: =L27-M27-N27 -> 0 | P27: =IFERROR(__xludf.DUMMYFUNCTION("""COMPUTED_VALUE"""),"ES-254") -> ES-254 | Q27: =COUNTIFS('eSignet UI - Test Cases'!A25:A4905,P27,'eSignet UI - Test Cases'!C25:C4905,"<>"&"") -> 7 | R27: =COUNTIFS('eSignet UI - Test Cases'!A25:A4905,P27,'eSignet UI - Test Cases'!C25:C4905,"<>"&"",'eSignet UI - Test Cases'!I25:I4905,"Pass") -> 7 | S27: =COUNTIFS('eSignet UI - Test Cases'!A25:A4905,P27,'eSignet UI - Test Cases'!C25:C4905,"<>"&"",'eSignet UI - Test Cases'!I25:I4905,"Fail") -> 0 | T27: =Q27-R27-S27 -> 0 | X27: docker.io/mosipqa/signup-ui:1.3.x | Y27: docker.io/mosipid/kernel-keymanager-service:1.2.1.0
K28: =IFERROR(__xludf.DUMMYFUNCTION("""COMPUTED_VALUE"""),"ES-2280") -> ES-2280 | L28: =COUNTIFS('eSignet API - Test Cases'!A26:A4498,K28,'eSignet API - Test Cases'!C26:C4498,"<>"&"") -> 9 | M28: =COUNTIFS('eSignet API - Test Cases'!A26:A4498,K28,'eSignet API - Test Cases'!C26:C4498,"<>"&"",'eSignet API - Test Cases'!I26:I4498,"Pass") -> 0 | N28: =COUNTIFS('eSignet API - Test Cases'!A26:A4498,K28,'eSignet API - Test Cases'!C26:C4498,"<>"&"",'eSignet API - Test Cases'!I26:I4498,"Fail") -> 0 | O28: =L28-M28-N28 -> 9 | P28: =IFERROR(__xludf.DUMMYFUNCTION("""COMPUTED_VALUE"""),"ES-501") -> ES-501 | Q28: =COUNTIFS('eSignet UI - Test Cases'!A26:A4906,P28,'eSignet UI - Test Cases'!C26:C4906,"<>"&"") -> 34 | R28: =COUNTIFS('eSignet UI - Test Cases'!A26:A4906,P28,'eSignet UI - Test Cases'!C26:C4906,"<>"&"",'eSignet UI - Test Cases'!I26:I4906,"Pass") -> 34 | S28: =COUNTIFS('eSignet UI - Test Cases'!A26:A4906,P28,'eSignet UI - Test Cases'!C26:C4906,"<>"&"",'eSignet UI - Test Cases'!I26:I4906,"Fail") -> 0 | T28: =Q28-R28-S28 -> 0 | X28: docker.io/mosipqa/signup-with-plugins:1.3.x | Y28: docker.io/mosipid/kernel-notification-service:1.2.0.1
K29: =IFERROR(__xludf.DUMMYFUNCTION("""COMPUTED_VALUE"""),"ES-1655") -> ES-1655 | L29: =COUNTIFS('eSignet API - Test Cases'!A27:A4499,K29,'eSignet API - Test Cases'!C27:C4499,"<>"&"") -> 72 | M29: =COUNTIFS('eSignet API - Test Cases'!A27:A4499,K29,'eSignet API - Test Cases'!C27:C4499,"<>"&"",'eSignet API - Test Cases'!I27:I4499,"Pass") -> 71 | N29: =COUNTIFS('eSignet API - Test Cases'!A27:A4499,K29,'eSignet API - Test Cases'!C27:C4499,"<>"&"",'eSignet API - Test Cases'!I27:I4499,"Fail") -> 1 | O29: =L29-M29-N29 -> 0 | P29: =IFERROR(__xludf.DUMMYFUNCTION("""COMPUTED_VALUE"""),"ES-1115") -> ES-1115 | Q29: =COUNTIFS('eSignet UI - Test Cases'!A27:A4907,P29,'eSignet UI - Test Cases'!C27:C4907,"<>"&"") -> 34 | R29: =COUNTIFS('eSignet UI - Test Cases'!A27:A4907,P29,'eSignet UI - Test Cases'!C27:C4907,"<>"&"",'eSignet UI - Test Cases'!I27:I4907,"Pass") -> 32 | S29: =COUNTIFS('eSignet UI - Test Cases'!A27:A4907,P29,'eSignet UI - Test Cases'!C27:C4907,"<>"&"",'eSignet UI - Test Cases'!I27:I4907,"Fail") -> 2 | T29: =Q29-R29-S29 -> 0 | X29: mosipqa/apitest-esignet:1.7.x | Y29: docker.io/mosipid/kernel-otpmanager-service:1.2.0.1
K30: =IFERROR(__xludf.DUMMYFUNCTION("""COMPUTED_VALUE"""),"ES-2379") -> ES-2379 | L30: =COUNTIFS('eSignet API - Test Cases'!A28:A4500,K30,'eSignet API - Test Cases'!C28:C4500,"<>"&"") -> 2 | M30: =COUNTIFS('eSignet API - Test Cases'!A28:A4500,K30,'eSignet API - Test Cases'!C28:C4500,"<>"&"",'eSignet API - Test Cases'!I28:I4500,"Pass") -> 2 | N30: =COUNTIFS('eSignet API - Test Cases'!A28:A4500,K30,'eSignet API - Test Cases'!C28:C4500,"<>"&"",'eSignet API - Test Cases'!I28:I4500,"Fail") -> 0 | O30: =L30-M30-N30 -> 0 | P30: =IFERROR(__xludf.DUMMYFUNCTION("""COMPUTED_VALUE"""),"ES-808") -> ES-808 | Q30: =COUNTIFS('eSignet UI - Test Cases'!A28:A4908,P30,'eSignet UI - Test Cases'!C28:C4908,"<>"&"") -> 18 | R30: =COUNTIFS('eSignet UI - Test Cases'!A28:A4908,P30,'eSignet UI - Test Cases'!C28:C4908,"<>"&"",'eSignet UI - Test Cases'!I28:I4908,"Pass") -> 18 | S30: =COUNTIFS('eSignet UI - Test Cases'!A28:A4908,P30,'eSignet UI - Test Cases'!C28:C4908,"<>"&"",'eSignet UI - Test Cases'!I28:I4908,"Fail") -> 0 | T30: =Q30-R30-S30 -> 0 | X30: mosipqa/apitest-esignet-signup:1.3.x | Y30: docker.io/mosipid/kernel-pridgenerator-service:1.2.0.1
K31: =IFERROR(__xludf.DUMMYFUNCTION("""COMPUTED_VALUE"""),"ES-2297") -> ES-2297 | L31: =COUNTIFS('eSignet API - Test Cases'!A29:A4501,K31,'eSignet API - Test Cases'!C29:C4501,"<>"&"") -> 58 | M31: =COUNTIFS('eSignet API - Test Cases'!A29:A4501,K31,'eSignet API - Test Cases'!C29:C4501,"<>"&"",'eSignet API - Test Cases'!I29:I4501,"Pass") -> 52 | N31: =COUNTIFS('eSignet API - Test Cases'!A29:A4501,K31,'eSignet API - Test Cases'!C29:C4501,"<>"&"",'eSignet API - Test Cases'!I29:I4501,"Fail") -> 6 | O31: =L31-M31-N31 -> 0 | P31: =IFERROR(__xludf.DUMMYFUNCTION("""COMPUTED_VALUE"""),"ES-993") -> ES-993 | Q31: =COUNTIFS('eSignet UI - Test Cases'!A29:A4909,P31,'eSignet UI - Test Cases'!C29:C4909,"<>"&"") -> 36 | R31: =COUNTIFS('eSignet UI - Test Cases'!A29:A4909,P31,'eSignet UI - Test Cases'!C29:C4909,"<>"&"",'eSignet UI - Test Cases'!I29:I4909,"Pass") -> 36 | S31: =COUNTIFS('eSignet UI - Test Cases'!A29:A4909,P31,'eSignet UI - Test Cases'!C29:C4909,"<>"&"",'eSignet UI - Test Cases'!I29:I4909,"Fail") -> 0 | T31: =Q31-R31-S31 -> 0 | X31: mosipid/keycloak-init:1.2.0.1 | Y31: docker.io/mosipid/kernel-ridgenerator-service:1.2.0.1
K32: =IFERROR(__xludf.DUMMYFUNCTION("""COMPUTED_VALUE"""),"ES-2333") -> ES-2333 | L32: =COUNTIFS('eSignet API - Test Cases'!A30:A4502,K32,'eSignet API - Test Cases'!C30:C4502,"<>"&"") -> 24 | M32: =COUNTIFS('eSignet API - Test Cases'!A30:A4502,K32,'eSignet API - Test Cases'!C30:C4502,"<>"&"",'eSignet API - Test Cases'!I30:I4502,"Pass") -> 22 | N32: =COUNTIFS('eSignet API - Test Cases'!A30:A4502,K32,'eSignet API - Test Cases'!C30:C4502,"<>"&"",'eSignet API - Test Cases'!I30:I4502,"Fail") -> 2 | O32: =L32-M32-N32 -> 0 | P32: =IFERROR(__xludf.DUMMYFUNCTION("""COMPUTED_VALUE"""),"ES-958") -> ES-958 | Q32: =COUNTIFS('eSignet UI - Test Cases'!A30:A4910,P32,'eSignet UI - Test Cases'!C30:C4910,"<>"&"") -> 35 | R32: =COUNTIFS('eSignet UI - Test Cases'!A30:A4910,P32,'eSignet UI - Test Cases'!C30:C4910,"<>"&"",'eSignet UI - Test Cases'!I30:I4910,"Pass") -> 35 | S32: =COUNTIFS('eSignet UI - Test Cases'!A30:A4910,P32,'eSignet UI - Test Cases'!C30:C4910,"<>"&"",'eSignet UI - Test Cases'!I30:I4910,"Fail") -> 0 | T32: =Q32-R32-S32 -> 0 | X32: mosipid/softhsm:v2 | Y32: docker.io/mosipid/keycloak-init:1.2.0.1
K33: =IFERROR(__xludf.DUMMYFUNCTION("""COMPUTED_VALUE"""),"ES-2589") -> ES-2589 | L33: =COUNTIFS('eSignet API - Test Cases'!A31:A4503,K33,'eSignet API - Test Cases'!C31:C4503,"<>"&"") -> 38 | M33: =COUNTIFS('eSignet API - Test Cases'!A31:A4503,K33,'eSignet API - Test Cases'!C31:C4503,"<>"&"",'eSignet API - Test Cases'!I31:I4503,"Pass") -> 35 | N33: =COUNTIFS('eSignet API - Test Cases'!A31:A4503,K33,'eSignet API - Test Cases'!C31:C4503,"<>"&"",'eSignet API - Test Cases'!I31:I4503,"Fail") -> 3 | O33: =L33-M33-N33 -> 0 | P33: =IFERROR(__xludf.DUMMYFUNCTION("""COMPUTED_VALUE"""),"ES-983") -> ES-983 | Q33: =COUNTIFS('eSignet UI - Test Cases'!A31:A4911,P33,'eSignet UI - Test Cases'!C31:C4911,"<>"&"") -> 29 | R33: =COUNTIFS('eSignet UI - Test Cases'!A31:A4911,P33,'eSignet UI - Test Cases'!C31:C4911,"<>"&"",'eSignet UI - Test Cases'!I31:I4911,"Pass") -> 29 | S33: =COUNTIFS('eSignet UI - Test Cases'!A31:A4911,P33,'eSignet UI - Test Cases'!C31:C4911,"<>"&"",'eSignet UI - Test Cases'!I31:I4911,"Fail") -> 0 | T33: =Q33-R33-S33 -> 0 | X33: mosipqa/apitest-esignet-signup:1.3.x | Y33: docker.io/mosipid/keys-generator:1.3.0-beta.2
K34: =IFERROR(__xludf.DUMMYFUNCTION("""COMPUTED_VALUE"""),"ES-2296") -> ES-2296 | L34: =COUNTIFS('eSignet API - Test Cases'!A32:A4504,K34,'eSignet API - Test Cases'!C32:C4504,"<>"&"") -> 53 | M34: =COUNTIFS('eSignet API - Test Cases'!A32:A4504,K34,'eSignet API - Test Cases'!C32:C4504,"<>"&"",'eSignet API - Test Cases'!I32:I4504,"Pass") -> 53 | N34: =COUNTIFS('eSignet API - Test Cases'!A32:A4504,K34,'eSignet API - Test Cases'!C32:C4504,"<>"&"",'eSignet API - Test Cases'!I32:I4504,"Fail") -> 0 | O34: =L34-M34-N34 -> 0 | P34: =IFERROR(__xludf.DUMMYFUNCTION("""COMPUTED_VALUE"""),"ES-675") -> ES-675 | Q34: =COUNTIFS('eSignet UI - Test Cases'!A32:A4912,P34,'eSignet UI - Test Cases'!C32:C4912,"<>"&"") -> 37 | R34: =COUNTIFS('eSignet UI - Test Cases'!A32:A4912,P34,'eSignet UI - Test Cases'!C32:C4912,"<>"&"",'eSignet UI - Test Cases'!I32:I4912,"Pass") -> 37 | S34: =COUNTIFS('eSignet UI - Test Cases'!A32:A4912,P34,'eSignet UI - Test Cases'!C32:C4912,"<>"&"",'eSignet UI - Test Cases'!I32:I4912,"Fail") -> 0 | T34: =Q34-R34-S34 -> 0 | X34: mosipqa/apitest-esignet:1.7.x | Y34: docker.io/mosipid/mimoto:0.13.0
M35: =COUNTIFS('eSignet API - Test Cases'!A48:A1520,K35,'eSignet API - Test Cases'!C48:C1520,"<>"&"",'eSignet API - Test Cases'!I48:I1520,"Pass") -> 0 | N35: =COUNTIFS('eSignet API - Test Cases'!A33:A4505,K35,'eSignet API - Test Cases'!C33:C4505,"<>"&"",'eSignet API - Test Cases'!I33:I4505,"Fail") -> 0 | O35: =L35-M35-N35 -> 0 | P35: =IFERROR(__xludf.DUMMYFUNCTION("""COMPUTED_VALUE"""),"ES-676") -> ES-676 | Q35: =COUNTIFS('eSignet UI - Test Cases'!A33:A4913,P35,'eSignet UI - Test Cases'!C33:C4913,"<>"&"") -> 2 | R35: =COUNTIFS('eSignet UI - Test Cases'!A33:A4913,P35,'eSignet UI - Test Cases'!C33:C4913,"<>"&"",'eSignet UI - Test Cases'!I33:I4913,"Pass") -> 2 | S35: =COUNTIFS('eSignet UI - Test Cases'!A33:A4913,P35,'eSignet UI - Test Cases'!C33:C4913,"<>"&"",'eSignet UI - Test Cases'!I33:I4913,"Fail") -> 0 | T35: =Q35-R35-S35 -> 0 | X35: mosipqa/config-server:1.1.2 | Y35: docker.io/mosipid/mimoto:0.19.2
M36: =COUNTIFS('eSignet API - Test Cases'!A50:A1522,K36,'eSignet API - Test Cases'!C50:C1522,"<>"&"",'eSignet API - Test Cases'!I50:I1522,"Pass") -> 0 | N36: =COUNTIFS('eSignet API - Test Cases'!A34:A4506,K36,'eSignet API - Test Cases'!C34:C4506,"<>"&"",'eSignet API - Test Cases'!I34:I4506,"Fail") -> 0 | O36: =L36-M36-N36 -> 0 | P36: =IFERROR(__xludf.DUMMYFUNCTION("""COMPUTED_VALUE"""),"ES-1013") -> ES-1013 | Q36: =COUNTIFS('eSignet UI - Test Cases'!A34:A4914,P36,'eSignet UI - Test Cases'!C34:C4914,"<>"&"") -> 33 | R36: =COUNTIFS('eSignet UI - Test Cases'!A34:A4914,P36,'eSignet UI - Test Cases'!C34:C4914,"<>"&"",'eSignet UI - Test Cases'!I34:I4914,"Pass") -> 33 | S36: =COUNTIFS('eSignet UI - Test Cases'!A34:A4914,P36,'eSignet UI - Test Cases'!C34:C4914,"<>"&"",'eSignet UI - Test Cases'!I34:I4914,"Fail") -> 0 | T36: =Q36-R36-S36 -> 0 | X36: mosipqa/keycloak-init:develop | Y36: docker.io/mosipid/mock-abis:1.2.0.1
N37: =COUNTIFS('eSignet API - Test Cases'!A35:A4507,K37,'eSignet API - Test Cases'!C35:C4507,"<>"&"",'eSignet API - Test Cases'!I35:I4507,"Fail") -> 0 | P37: =IFERROR(__xludf.DUMMYFUNCTION("""COMPUTED_VALUE"""),"ES-1260") -> ES-1260 | Q37: =COUNTIFS('eSignet UI - Test Cases'!A35:A4915,P37,'eSignet UI - Test Cases'!C35:C4915,"<>"&"") -> 27 | R37: =COUNTIFS('eSignet UI - Test Cases'!A35:A4915,P37,'eSignet UI - Test Cases'!C35:C4915,"<>"&"",'eSignet UI - Test Cases'!I35:I4915,"Pass") -> 27 | S37: =COUNTIFS('eSignet UI - Test Cases'!A35:A4915,P37,'eSignet UI - Test Cases'!C35:C4915,"<>"&"",'eSignet UI - Test Cases'!I35:I4915,"Fail") -> 0 | T37: =Q37-R37-S37 -> 0 | X37: mosipqa/postgres-init:develop | Y37: docker.io/mosipid/mock-identity-system:0.9.3
N38: =COUNTIFS('eSignet API - Test Cases'!A36:A4508,K38,'eSignet API - Test Cases'!C36:C4508,"<>"&"",'eSignet API - Test Cases'!I36:I4508,"Fail") -> 0 | P38: =IFERROR(__xludf.DUMMYFUNCTION("""COMPUTED_VALUE"""),"ES-973") -> ES-973 | Q38: =COUNTIFS('eSignet UI - Test Cases'!A36:A4916,P38,'eSignet UI - Test Cases'!C36:C4916,"<>"&"") -> 37 | R38: =COUNTIFS('eSignet UI - Test Cases'!A36:A4916,P38,'eSignet UI - Test Cases'!C36:C4916,"<>"&"",'eSignet UI - Test Cases'!I36:I4916,"Pass") -> 37 | S38: =COUNTIFS('eSignet UI - Test Cases'!A36:A4916,P38,'eSignet UI - Test Cases'!C36:C4916,"<>"&"",'eSignet UI - Test Cases'!I36:I4916,"Fail") -> 0 | T38: =Q38-R38-S38 -> 0 | Y38: docker.io/mosipid/mock-mv:1.2.0.1
N39: =COUNTIFS('eSignet API - Test Cases'!A37:A4509,K39,'eSignet API - Test Cases'!C37:C4509,"<>"&"",'eSignet API - Test Cases'!I37:I4509,"Fail") -> 0 | P39: =IFERROR(__xludf.DUMMYFUNCTION("""COMPUTED_VALUE"""),"ES-1003") -> ES-1003 | Q39: =COUNTIFS('eSignet UI - Test Cases'!A37:A4917,P39,'eSignet UI - Test Cases'!C37:C4917,"<>"&"") -> 23 | R39: =COUNTIFS('eSignet UI - Test Cases'!A37:A4917,P39,'eSignet UI - Test Cases'!C37:C4917,"<>"&"",'eSignet UI - Test Cases'!I37:I4917,"Pass") -> 15 | S39: =COUNTIFS('eSignet UI - Test Cases'!A37:A4917,P39,'eSignet UI - Test Cases'!C37:C4917,"<>"&"",'eSignet UI - Test Cases'!I37:I4917,"Fail") -> 8 | T39: =Q39-R39-S39 -> 0 | Y39: docker.io/mosipid/mock-relying-party-service:0.9.3
N40: =COUNTIFS('eSignet API - Test Cases'!A38:A4510,K40,'eSignet API - Test Cases'!C38:C4510,"<>"&"",'eSignet API - Test Cases'!I38:I4510,"Fail") -> 0 | P40: =IFERROR(__xludf.DUMMYFUNCTION("""COMPUTED_VALUE"""),"ES-1665") -> ES-1665 | Q40: =COUNTIFS('eSignet UI - Test Cases'!A38:A4918,P40,'eSignet UI - Test Cases'!C38:C4918,"<>"&"") -> 72 | R40: =COUNTIFS('eSignet UI - Test Cases'!A38:A4918,P40,'eSignet UI - Test Cases'!C38:C4918,"<>"&"",'eSignet UI - Test Cases'!I38:I4918,"Pass") -> 65 | S40: =COUNTIFS('eSignet UI - Test Cases'!A38:A4918,P40,'eSignet UI - Test Cases'!C38:C4918,"<>"&"",'eSignet UI - Test Cases'!I38:I4918,"Fail") -> 7 | T40: =Q40-R40-S40 -> 0 | Y40: docker.io/mosipid/mock-relying-party-ui:0.9.3
N41: =COUNTIFS('eSignet API - Test Cases'!A39:A4511,K41,'eSignet API - Test Cases'!C39:C4511,"<>"&"",'eSignet API - Test Cases'!I39:I4511,"Fail") -> 0 | P41: =IFERROR(__xludf.DUMMYFUNCTION("""COMPUTED_VALUE"""),"ES-1601") -> ES-1601 | Q41: =COUNTIFS('eSignet UI - Test Cases'!A39:A4919,P41,'eSignet UI - Test Cases'!C39:C4919,"<>"&"") -> 5 | R41: =COUNTIFS('eSignet UI - Test Cases'!A39:A4919,P41,'eSignet UI - Test Cases'!C39:C4919,"<>"&"",'eSignet UI - Test Cases'!I39:I4919,"Pass") -> 5 | S41: =COUNTIFS('eSignet UI - Test Cases'!A39:A4919,P41,'eSignet UI - Test Cases'!C39:C4919,"<>"&"",'eSignet UI - Test Cases'!I39:I4919,"Fail") -> 0 | T41: =Q41-R41-S41 -> 0 | Y41: docker.io/mosipid/mock-smtp:1.0.0
...

Sheet eSignet - API Testing
C2: MOSIP-CRE Env | D2: # Test Cases
D3: Total | E3: Failed | F3: Passed | G3: Skipped | H3: Ignored | I3: Known Issues
C4: eSignet | D4: 1273 | E4: 8 | F4: 1091 | G4: 8 | H4: 166 | I4: 0
C5: signup | D5: 665 | E5: 53 | F5: 405 | G5: 190 | H5: 17 | I5: 0
C7: Total | D7: =SUM(D4:D6) -> 1938 | E7: =SUM(E4:E6) -> 61 | F7: =SUM(F4:F6) -> 1496 | G7: =SUM(G4:G6) -> 198 | H7: =SUM(H4:H6) -> 183 | I7: 0
C10: MOSIP qa-base Env | D10: # Test Cases
D11: Total | E11: Failed | F11: Passed | G11: Skipped | H11: Ignored | I11: Known Issues
C12: eSignet | D12: 1273 | E12: 0 | F12: 1107 | G12: 0 | H12: 166 | I12: 0
C13: signup | D13: 665 | E13: 0 | F13: 648 | G13: 0 | H13: 17 | I13: 0
C15: Total | D15: =SUM(D12:D14) -> 1938 | E15: =SUM(E12:E14) -> 0 | F15: =SUM(F12:F14) -> 1755 | G15: =SUM(G12:G14) -> 0 | H15: =SUM(H12:H14) -> 183 | I15: 0
C18: Mock ID | D18: # Test Cases
D19: Total | E19: Failed | F19: Passed | G19: Skipped | H19: Ignored | I19: Known Issues
C20: eSignet | D20: 1273 | E20: 0 | F20: 729 | G20: 0 | H20: 544 | I20: 0
C21: signup | D21: 665 | E21: 0 | F21: 635 | G21: 0 | H21: 30 | I21: 0
C23: Total | D23: =SUM(D20:D22) -> 1938 | E23: =SUM(E20:E22) -> 0 | F23: =SUM(F20:F22) -> 1364 | G23: =SUM(G20:G22) -> 0 | H23: =SUM(H20:H22) -> 574 | I23: 0
C26: Sunbird | D26: # Test Cases
D27: Total | E27: Failed | F27: Passed | G27: Skipped | H27: Ignored | I27: Known Issues
C28: eSignet | D28: 1273 | E28: 0 | F28: 93 | G28: 0 | H28: 1180 | I28: 0
C30: Total | D30: 1273 | E30: =SUM(E28) -> 0 | F30: 93 | G30: =SUM(G28) -> 0 | H30: 1180 | I30: 0

Sheet eSignet API - Test Cases
A1: Story id | B1: Story Title | C1: TestCase_No | D1: pre requisite | E1: Feature | F1: Scenario | G1: Test case step | H1: Expected Result | I1: Mosipid_Test Result | J1: MockId_test results | K1: Remarks | L1: Automated | M1: status
A2: MOSIP-22715 | B2: IdP: Build new internal API for OIDC client creation and update | C2: TC_22715_01 | D2: Step 1: The resource owner wants the client to use the identity from the authorization server. Step 2: Client redirects the browser to the authorization server. Step 3: The authorization server redirects back to the client. Step 4: Client Accesses Protected data on Resource Server. | E2: Create OIDC Client | F2: Verify Relying party able to create OIDC client for itself from PMP | G2: 1.hit http://localhost:3000 /client-mgmt/oidc-client API. 2. Enter | H2: IDP should accept client registration request from PMP and client creation should happen in IDP | I2: Pass | L2: Yes
A3: MOSIP-22715 | B3: IdP: Build new internal API for OIDC client creation and update | C3: TC_22715_02 | F3: Verify One Relying party able to create multiple clients from PMP | G3: 1.hit http://localhost:3000 /client-mgmt/oidc-client API. 2. Enter Valid data in the client registration form and execute. | H3: IDP should accept client registration request and client creation should happen in IDP | I3: Pass | L3: Yes
A4: MOSIP-22715 | B4: IdP: Build new internal API for OIDC client creation and update | C4: TC_22715_03 | F4: Verify IDP should accept client registartion request from PMP only with valid authorization token i,e in the scope token should be "add_oidc_client". | G4: 1.hit http://localhost:3000 /client-mgmt/oidc-client API. 2. Enter Valid data in the client registration form and execute. | H4: IDP should accept client registration request from PMP and client creation should happen in IDP with ACTIVE status with valid authorization token. Note: Expected scope in the token is add_oidc_client. | I4: Pass | L4: Yes
A5: MOSIP-22715 | B5: IdP: Build new internal API for OIDC client creation and update | C5: TC_22715_04 | F5: Verify IDP shouldnot accept client registartion request from PMP with invalid authorization token i,e in the scope mention invalid token like"xyz". | G5: 1.hit http://localhost:3000 /client-mgmt/oidc-client API. 2. Enter Valid data in the client registration form and execute. | H5: IDP should not accept client registartion request from PMP and should throw 40Unauthorized error | I5: Pass | L5: Yes
A6: MOSIP-22715 | B6: IdP: Build new internal API for OIDC client creation and update | C6: TC_22715_05 | E6: Create OIDC Client request body validation | F6: check with valid OIDC client id (Case-Sensitive) as an input of clientId in the request body. Example: client id like "e-health-service" / it should be UID | G6: 1.hit http://localhost:3000 /client-mgmt/oidc-client API | H6: client id we have to get as UID | I6: Pass | L6: Yes
A7: MOSIP-22715 | B7: IdP: Build new internal API for OIDC client creation and update | C7: TC_22715_06 | F7: check with invalid OIDC client id as an input of clientId in the request body. Example: client id like "???><::}:" | G7: 1.hit http://localhost:3000 /client-mgmt/oidc-client API | H7: ErrorCodes we should get when we pass client id "invalid_client_id" | I7: Pass | L7: Yes
A8: MOSIP-22715 | B8: IdP: Build new internal API for OIDC client creation and update | C8: TC_22715_07 | F8: check with existing OIDC client id as an input of clientId in the request body. If duplicates found, request will be rejected. | G8: 1.hit http://localhost:3000 /client-mgmt/oidc-client API | H8: ErrorCodes we should get duplicate_client_id | I8: Pass | L8: Yes
A9: MOSIP-22715 | B9: IdP: Build new internal API for OIDC client creation and update | C9: TC_22715_08 | F9: check client id field value with the mentioned range (i,e >= characters <= 50 characters) | G9: 1.hit http://localhost:3000 /client-mgmt/oidc-client API | H9: client id should create with ACTIVE status | I9: Pass | L9: Yes
A10: MOSIP-22715 | B10: IdP: Build new internal API for OIDC client creation and update | C10: TC_22715_09 | F10: check with crossing the maximum characters in client id field(i,e >= characters <= 50 characters) | G10: 1.hit http://localhost:3000 /client-mgmt/oidc-client API | H10: it should give error as invalid_client_id | I10: Pass | L10: Yes
A11: MOSIP-22715 | B11: IdP: Build new internal API for OIDC client creation and update | C11: TC_22715_10 | F11: check Name of OIDC client comes in the below range >= characters <= 25character as an input of clientName in the request body. Example: Health Service | G11: 1.hit http://localhost:3000 /client-mgmt/oidc-client API | H11: client id should create with ACTIVE status | I11: Pass | L11: Yes
A12: MOSIP-22715 | B12: IdP: Build new internal API for OIDC client creation and update | C12: TC_22715_11 | F12: check Name of OIDC client exceed the below range >= characters <= 25character as an input of clientName in the request body. Example: Health Service | G12: 1.hit http://localhost:3000 /client-mgmt/oidc-client API | H12: it shouuld give error as invalid_client_name | I12: Pass | L12: Yes
A13: MOSIP-22715 | B13: IdP: Build new internal API for OIDC client creation and update | C13: TC_22715_12 | F13: check Name of OIDC client in case sensitive format as an input of clientName in the request body. | G13: 1.hit http://localhost:3000 /client-mgmt/oidc-client API | H13: client id should create with ACTIVE status | I13: Pass | L13: Yes
A14: MOSIP-22715 | B14: IdP: Build new internal API for OIDC client creation and update | C14: TC_22715_14 | F14: check once relying party is registed from PMS use the same id as relyingPartyId in Create OIDC Client request body. Note: This we can use further to fetch KYC from IDA servers. Example: bharathi-inc | G14: 1.hit http://localhost:3000 /client-mgmt/oidc-client API | H14: client id should create with ACTIVE status | I14: Pass | L14: Yes
A15: MOSIP-22715 | B15: IdP: Build new internal API for OIDC client creation and update | C15: TC_22715_15 | F15: check relying partyid should be in the below mentioned range >= characters <= 50 characters as an input of relyingpartyid in the request body. : Example:bharathi-inc | G15: 1.hit http://localhost:3000 /client-mgmt/oidc-client API | H15: client id should create with ACTIVE status | I15: Pass | L15: Yes
A16: MOSIP-22715 | B16: IdP: Build new internal API for OIDC client creation and update | C16: TC_22715_16 | F16: check relying partyid accepts alphanumeric as an input of relyingpartyid in the request body. | G16: 1.hit http://localhost:3000 /client-mgmt/oidc-client API | H16: it should accepts Alphanumeric for relying party | I16: Pass | L16: Yes
A17: MOSIP-22715 | B17: IdP: Build new internal API for OIDC client creation and update | C17: TC_22715_17 | F17: check with crossing the maximum characters of relying partyid should throw an error. | G17: 1.hit http://localhost:3000 /client-mgmt/oidc-client API | H17: it should give error as invalid_rp_id | I17: Pass | L17: Yes
A18: MOSIP-22715 | B18: IdP: Build new internal API for OIDC client creation and update | C18: TC_22715_18 | F18: check with invalid relying partyid which is not registered in the IDP server. | G18: 1.hit http://localhost:3000 /client-mgmt/oidc-client API | H18: it should give error as invalid_rp_id | I18: Pass | L18: N/A
... A42: MOSIP-22715 | B42: IdP: Build new internal API for OIDC client creation and update | C42: TC_22715_44 | F42: verify with invalid data passing in clientAuthMethods as an input provided in the request body | G42: 1.hit http://localhost:3000 /client-mgmt/oidc-client API | H42: error we should get like invalid_client_auth | I42: Pass | L42: Yes
A43: MOSIP-22715 | B43: IdP: Build new internal API for OIDC client creation and update | C43: TC_22715_45 | E43: Status of Client ID in the response body | F43: Creation of OIDC client is successfull , the status should get like ACTIVE in the response body | G43: 1.hit http://localhost:3000 /client-mgmt/oidc-client API | H43: status should be ACTIVE in the response | I43: Pass | L43: Yes
A44: MOSIP-22715 | B44: IdP: Build new internal API for OIDC client creation and update | C44: TC_22715_46 | E44: Update OIDC Client Endpoint | F44: Verify IDP should accept OIDC-Client update from PMP only with valid authorization token i,e in the scope token should be "update_oidc_client". Authentication & Authorization: Scope based. | G44: 1.Hit http://localhost:3000 /client-mgmt/oidc-client/{client_id} | H44: IDP should accept client registration request from PMP and client creation should happen in IDP | I44: Pass | L44: Yes
A45: MOSIP-22715 | B45: IdP: Build new internal API for OIDC client creation and update | C45: TC_22715_47 | F45: verify with invalid OIDC-Client id passing in the Update OIDC Client Endpoint | G45: 1.Hit http://localhost:3000 /client-mgmt/oidc-client/{client_id} | H45: Error we should get invalid_client_id | I45: Pass | L45: Yes
A46: MOSIP-22715 | B46: IdP: Build new internal API for OIDC client creation and update | C46: TC_22715_48 | F46: check with Authentication & Authorization: Scope based. | G46: 1.Hit http://localhost:3000 /client-mgmt/oidc-client/{client_id} | H46: IDP should accept client registration request from PMP and client creation should happen in IDP | I46: Pass | L46: Yes
A47: MOSIP-22715 | B47: IdP: Build new internal API for OIDC client creation and update | C47: TC_22715_50 | E47: Update OIDC Client request body validation | F47: check Name of OIDC client comes in the below range >= characters <= 25character as an input of clientName in the request body. Example: Health Service | G47: 1.Hit http://localhost:3000 /client-mgmt/oidc-client/{client_id} | H47: client id has to update with ACTIVE status | I47: Pass | L47: Yes
A48: MOSIP-22715 | B48: IdP: Build new internal API for OIDC client creation and update | C48: TC_22715_51 | F48: check Name of OIDC client exceed the below range >= characters <= 25character as an input of clientName in the request body. Example: Health Service | G48: 1.Hit http://localhost:3000 /client-mgmt/oidc-client/{client_id} | H48: error we should get invalid client name | I48: Pass | L48: Yes
A49: MOSIP-22715 | B49: IdP: Build new internal API for OIDC client creation and update | C49: TC_22715_52 | F49: Check Name of OIDC client in case sensitive format as an input of clientName in the request body. | G49: 1.Hit http://localhost:3000 /client-mgmt/oidc-client/{client_id} | H49: client id should create with ACTIVE status | I49: Pass | L49: Yes
A50: MOSIP-22715 | B50: IdP: Build new internal API for OIDC client creation and update | C50: TC_22715_54 | F50: The status allowed types like ACTIVE or INACTIVE as an input of status in the Update OIDC client request | G50: 1.Hit http://localhost:3000 /client-mgmt/oidc-client/{client_id} | H50: Status of the OIDC Client should update in IdP servers. | I50: Pass | L50: Yes
A51: MOSIP-22715 | B51: IdP: Build new internal API for OIDC client creation and update | C51: TC_22715_55 | F51: The status other than allowed types like ACTIVE or INACTIVE as an input of status in the Update OIDC client request | G51: 1.Hit http://localhost:3000 /client-mgmt/oidc-client/{client_id} | H51: error we should get and it should not update in the IDP server. | I51: Pass | L51: Yes
A52: MOSIP-22715 | B52: IdP: Build new internal API for OIDC client creation and update | C52: TC_22715_57 | F52: check Relying party logo URI which will used to display logo in OIDC login and consent pages as an input of logoUri in the request body. | G52: 1.Hit http://localhost:3000 /client-mgmt/oidc-client/{client_id} | H52: client id should create with ACTIVE status | I52: Pass | L52: Yes
A53: MOSIP-22715 | B53: IdP: Build new internal API for OIDC client creation and update | C53: TC_22715_58 | F53: check logoUri should be in the below mentioned >= characters <= 102characters as an input of logoUri in the request body. | G53: 1.Hit http://localhost:3000 /client-mgmt/oidc-client/{client_id} | H53: client id should create with ACTIVE status | I53: Pass | L53: Yes
A54: MOSIP-22715 | B54: IdP: Build new internal API for OIDC client creation and update | C54: TC_22715_59 | F54: check with crossing the maximum characters as an input of logoUri in the request body. | G54: 1.Hit http://localhost:3000 /client-mgmt/oidc-client/{client_id} | H54: error we should get invalid URI | I54: Pass | L54: Yes
A55: MOSIP-22715 | B55: IdP: Build new internal API for OIDC client creation and update | C55: TC_22715_60 | F55: Check by providing valid redirectUris in the request body. Note:Uri to where the response with authorization_code to be redirected. This will be cross verified with the redirect_uri query parameter sent in the authorize request. | G55: 1.Hit http://localhost:3000 /client-mgmt/oidc-client/{client_id} | H55: Client redirects the browser to the authorization server | I55: Pass | L55: Yes
A56: MOSIP-22715 | B56: IdP: Build new internal API for OIDC client creation and update | C56: TC_22715_61 | F56: chech by providing invalid redirectUris in the request body | G56: 1.Hit http://localhost:3000 /client-mgmt/oidc-client/{client_id} | H56: Error we should get invalid_redirect_uri | I56: Pass | L56: Yes
A57: MOSIP-22715 | B57: IdP: Build new internal API for OIDC client creation and update | C57: TC_22715_62 | F57: check only allowed user details can we provide as an input for userClaims Allowed values like below: "userClaims": [ "name", "given_name", "email", "gender", "birthdate", "phone_number", "profile_photo", "address", "locale", "individual_id" ] | G57: 1.Hit http://localhost:3000 /client-mgmt/oidc-client/{client_id} | H57: client id should create with ACTIVE status | I57: Pass | L57: Yes
A58: MOSIP-22715 | B58: IdP: Build new internal API for OIDC client creation and update | C58: TC_22715_63 | F58: check Allowed user info claims should be >= items | G58: 1.Hit http://localhost:3000 /client-mgmt/oidc-client/{client_id} | H58: client id should create with ACTIVE status | I58: Pass | L58: Yes
A59: MOSIP-22715 | B59: IdP: Build new internal API for OIDC client creation and update | C59: TC_22715_64 | F59: check with invalid allowed user details as an input of userClaims | G59: 1.Hit http://localhost:3000 /client-mgmt/oidc-client/{client_id} | H59: error we should get invalid_claim | I59: Pass | L59: Yes
... A71: MOSIP-22715 | B71: IdP: Build new internal API for OIDC client creation and update | C71: TC_22715_76 | F71: verify with invalid data passing in clientAuthMethods as an input provided in the request body | G71: 1.Hit http://localhost:3000 /client-mgmt/oidc-client/{client_id} | H71: error we should get like invalid_client_auth | I71: Pass | L71: Yes
